Workbook

Sheet Run_1
A1: puzzle_size | B1: nAnts_alg0 | C1: nAnts_alg3 | D1: nAnts_alg4 | E1: threads_alg0 | F1: threads_alg3 | G1: threads_alg4 | H1: numcolonies_alg0 | I1: numcolonies_alg3 | J1: numcolonies_alg4 | K1: numacs_alg0 | L1: numacs_alg3 | M1: numacs_alg4 | N1: q0_alg0 | O1: q0_alg3 | P1: q0_alg4 | Q1: rho_alg0 | R1: rho_alg3 | S1: rho_alg4 | T1: bve_alg0 | U1: bve_alg3 | V1: bve_alg4 | W1: timeout_alg0 | X1: timeout_alg3 | Y1: timeout_alg4 | Z1: success_rate_alg0 | AA1: success_rate_alg3 | AB1: success_rate_alg4 | AC1: time_mean_alg0 | AD1: time_mean_alg3 | AE1: time_mean_alg4 | AF1: time_std_alg0 | AG1: time_std_alg3 | AH1: time_std_alg4 | AI1: iter_mean_alg0 | AJ1: iter_mean_alg3 | AK1: iter_mean_alg4 | AL1: with_comm_alg0 | AM1: with_comm_alg3 | AN1: with_comm_alg4 | AO1: without_comm_alg0 | AP1: without_comm_alg3 | AQ1: without_comm_alg4 | AR1: cp_initial_mean_alg0 | AS1: cp_initial_mean_alg3 | AT1: cp_initial_mean_alg4 | AU1: cp_ant_mean_alg0 | AV1: cp_ant_mean_alg3 | AW1: cp_ant_mean_alg4 | AX1: cp_total_mean_alg0 | AY1: cp_total_mean_alg3 | AZ1: cp_total_mean_alg4 | BA1: acs_time_mean_alg0 | BB1: acs_time_mean_alg3 | BC1: acs_time_mean_alg4 | BD1: dcm_aco_time_mean_alg0 | BE1: dcm_aco_time_mean_alg3 | BF1: dcm_aco_time_mean_alg4 | BG1: coop_game_mean_alg0 | BH1: coop_game_mean_alg3 | BI1: coop_game_mean_alg4 | BJ1: pheromone_fusion_mean_alg0 | BK1: pheromone_fusion_mean_alg3 | BL1: pheromone_fusion_mean_alg4 | BM1: public_path_mean_alg0 | BN1: public_path_mean_alg3 | BO1: public_path_mean_alg4 | BP1: communication_time_mean_alg0 | BQ1: communication_time_mean_alg3 | BR1: communication_time_mean_alg4 | BS1: cp_percentage_alg0 | BT1: cp_percentage_alg3 | BU1: cp_percentage_alg4 | BV1: acs_time_percentage_alg0 | BW1: acs_time_percentage_alg3 | BX1: acs_time_percentage_alg4 | BY1: dcm_aco_time_percentage_alg0 | BZ1: dcm_aco_time_percentage_alg3 | CA1: dcm_aco_time_percentage_alg4 | CB1: coop_game_percentage_alg0 | CC1: coop_game_percentage_alg3 | CD1: coop_game_percentage_alg4 | CE1: pheromone_fusion_percentage_alg0 | CF1: pheromone_fusion_percentage_alg3 | CG1: pheromone_fusion_percentage_alg4 | CH1: public_path_percentage_alg0 | CI1: public_path_percentage_alg3 | CJ1: public_path_percentage_alg4 | CK1: communication_time_percentage_alg0 | CL1: communication_time_percentage_alg3 | CM1: communication_time_percentage_alg4
A2: 2020_00004 | B2: 10 | C2: 3 | D2: 3 | G2: 3 | I2: 3 | J2: 3 | L2: 2 | M2: 2 | N2: 0.9 | O2: 0.9 | P2: 0.9 | Q2: 0.9 | R2: 0.9 | S2: 0.9 | T2: 0.005 | U2: 0.005 | V2: 0.005 | W2: 5 | X2: 5 | Y2: 5 | Z2: 100 | AA2: 100 | AB2: 100 | AC2: 0.115697 | AD2: 0.042068 | AE2: 0.023715 | AF2: 0.373438 | AG2: 0.034897 | AH2: 0.021654 | AI2: 114.62 | AJ2: 42.28 | AK2: 19.65 | AN2: 0 | AQ2: 100 | AR2: 0.000102 | AS2: 0.000102 | AT2: 0.000104 | AU2: 0.070165 | AV2: 0.025328 | AW2: 0.012625 | AX2: 0.070266 | AY2: 0.02543 | AZ2: 0.01273 | BA2: 0.04543 | BE2: 0.016638 | BF2: 0.010986 | BH2: 0.000521 | BI2: 0.000263 | BK2: 4.1e-05 | BL2: 4.2e-05 | BN2: 0.000107 | BO2: 4.4e-05 | BR2: 0 | BS2: 60.73 | BT2: 60.45 | BU2: 53.68 | BV2: 39.27 | BZ2: 39.55 | CA2: 46.32 | CC2: 1.24 | CD2: 1.11 | CF2: 0.1 | CG2: 0.18 | CI2: 0.25 | CJ2: 0.19 | CM2: 0
A3: 2020_00021 | B3: 10 | C3: 3 | D3: 3 | G3: 3 | I3: 3 | J3: 3 | L3: 2 | M3: 2 | N3: 0.9 | O3: 0.9 | P3: 0.9 | Q3: 0.9 | R3: 0.9 | S3: 0.9 | T3: 0.005 | U3: 0.005 | V3: 0.005 | W3: 5 | X3: 5 | Y3: 5 | Z3: 100 | AA3: 100 | AB3: 100 | AC3: 0.092731 | AD3: 0.055187 | AE3: 0.029928 | AF3: 0.076717 | AG3: 0.04589 | AH3: 0.02491 | AI3: 93.49 | AJ3: 60.28 | AK3: 25.82 | AN3: 0 | AQ3: 100 | AR3: 9.4e-05 | AS3: 9.3e-05 | AT3: 0.000107 | AU3: 0.056965 | AV3: 0.032947 | AW3: 0.01608 | AX3: 0.057059 | AY3: 0.03304 | AZ3: 0.016186 | BA3: 0.035672 | BE3: 0.022147 | BF3: 0.013741 | BH3: 0.000706 | BI3: 0.000396 | BK3: 3.9e-05 | BL3: 4.2e-05 | BN3: 0.000141 | BO3: 5.6e-05 | BR3: 0 | BS3: 61.53 | BT3: 59.87 | BU3: 54.08 | BV3: 38.47 | BZ3: 40.13 | CA3: 45.92 | CC3: 1.28 | CD3: 1.32 | CF3: 0.07 | CG3: 0.14 | CI3: 0.26 | CJ3: 0.19 | CM3: 0
A4: 2020_00041 | B4: 10 | C4: 3 | D4: 3 | G4: 3 | I4: 3 | J4: 3 | L4: 2 | M4: 2 | N4: 0.9 | O4: 0.9 | P4: 0.9 | Q4: 0.9 | R4: 0.9 | S4: 0.9 | T4: 0.005 | U4: 0.005 | V4: 0.005 | W4: 5 | X4: 5 | Y4: 5 | Z4: 100 | AA4: 100 | AB4: 100 | AC4: 0.103602 | AD4: 0.066643 | AE4: 0.019465 | AF4: 0.111561 | AG4: 0.06524 | AH4: 0.027974 | AI4: 102.77 | AJ4: 68.92 | AK4: 17 | AN4: 2 | AQ4: 98 | AR4: 0.000103 | AS4: 0.000106 | AT4: 0.00011 | AU4: 0.063915 | AV4: 0.040109 | AW4: 0.01067 | AX4: 0.064018 | AY4: 0.040215 | AZ4: 0.010781 | BA4: 0.039584 | BE4: 0.026428 | BF4: 0.008684 | BH4: 0.000864 | BI4: 0.000229 | BK4: 4.1e-05 | BL4: 3.9e-05 | BN4: 0.00018 | BO4: 3.9e-05 | BR4: 0 | BS4: 61.79 | BT4: 60.34 | BU4: 55.39 | BV4: 38.21 | BZ4: 39.66 | CA4: 44.61 | CC4: 1.3 | CD4: 1.18 | CF4: 0.06 | CG4: 0.2 | CI4: 0.27 | CJ4: 0.2 | CM4: 0
A5: 2020_00049 | B5: 10 | C5: 3 | D5: 3 | G5: 3 | I5: 3 | J5: 3 | L5: 2 | M5: 2 | N5: 0.9 | O5: 0.9 | P5: 0.9 | Q5: 0.9 | R5: 0.9 | S5: 0.9 | T5: 0.005 | U5: 0.005 | V5: 0.005 | W5: 5 | X5: 5 | Y5: 5 | Z5: 100 | AA5: 100 | AB5: 100 | AC5: 0.132642 | AD5: 0.150849 | AE5: 0.052507 | AF5: 0.113773 | AG5: 0.168474 | AH5: 0.050259 | AI5: 119.37 | AJ5: 152.72 | AK5: 45.9 | AN5: 10 | AQ5: 90 | AR5: 0.000103 | AS5: 0.000101 | AT5: 0.000103 | AU5: 0.082337 | AV5: 0.090944 | AW5: 0.030085 | AX5: 0.08244 | AY5: 0.091045 | AZ5: 0.030188 | BA5: 0.050202 | BE5: 0.059804 | BF5: 0.021942 | BH5: 0.001848 | BI5: 0.000614 | BK5: 4.5e-05 | BL5: 4e-05 | BN5: 0.000395 | BO5: 0.000113 | BR5: 0.000377 | BS5: 62.15 | BT5: 60.35 | BU5: 57.49 | BV5: 37.85 | BZ5: 39.64 | CA5: 41.79 | CC5: 1.23 | CD5: 1.17 | CF5: 0.03 | CG5: 0.08 | CI5: 0.26 | CJ5: 0.22 | CM5: 0.72
A6: 2020_00054 | B6: 10 | C6: 3 | D6: 3 | G6: 3 | I6: 3 | J6: 3 | L6: 2 | M6: 2 | N6: 0.9 | O6: 0.9 | P6: 0.9 | Q6: 0.9 | R6: 0.9 | S6: 0.9 | T6: 0.005 | U6: 0.005 | V6: 0.005 | W6: 5 | X6: 5 | Y6: 5 | Z6: 100 | AA6: 100 | AB6: 100 | AC6: 0.099409 | AD6: 0.082467 | AE6: 0.03455 | AF6: 0.0825 | AG6: 0.088362 | AH6: 0.026452 | AI6: 96.95 | AJ6: 87.36 | AK6: 31.43 | AN6: 2 | AQ6: 98 | AR6: 0.000108 | AS6: 0.000108 | AT6: 0.000113 | AU6: 0.060754 | AV6: 0.049137 | AW6: 0.019394 | AX6: 0.060862 | AY6: 0.049245 | AZ6: 0.019507 | BA6: 0.038547 | BE6: 0.033222 | BF6: 0.015043 | BH6: 0.001062 | BI6: 0.000426 | BK6: 4e-05 | BL6: 3.7e-05 | BN6: 0.000232 | BO6: 7.6e-05 | BR6: 0 | BS6: 61.22 | BT6: 59.71 | BU6: 56.46 | BV6: 38.78 | BZ6: 40.29 | CA6: 43.54 | CC6: 1.29 | CD6: 1.23 | CF6: 0.05 | CG6: 0.11 | CI6: 0.28 | CJ6: 0.22 | CM6: 0
A7: 2020_00057 | B7: 10 | C7: 3 | D7: 3 | G7: 3 | I7: 3 | J7: 3 | L7: 2 | M7: 2 | N7: 0.9 | O7: 0.9 | P7: 0.9 | Q7: 0.9 | R7: 0.9 | S7: 0.9 | T7: 0.005 | U7: 0.005 | V7: 0.005 | W7: 5 | X7: 5 | Y7: 5 | Z7: 100 | AA7: 100 | AB7: 100 | AC7: 0.061311 | AD7: 0.040927 | AE7: 0.017687 | AF7: 0.057189 | AG7: 0.035206 | AH7: 0.013808 | AI7: 58.47 | AJ7: 42.03 | AK7: 15.57 | AN7: 0 | AQ7: 100 | AR7: 0.000104 | AS7: 0.000105 | AT7: 0.000109 | AU7: 0.037943 | AV7: 0.024556 | AW7: 0.009596 | AX7: 0.038048 | AY7: 0.02466 | AZ7: 0.009705 | BA7: 0.023263 | BE7: 0.016267 | BF7: 0.007981 | BH7: 0.000507 | BI7: 0.000197 | BK7: 4.3e-05 | BL7: 3.7e-05 | BN7: 0.000104 | BO7: 3.3e-05 | BR7: 0 | BS7: 62.06 | BT7: 60.25 | BU7: 54.87 | BV7: 37.94 | BZ7: 39.75 | CA7: 45.13 | CC7: 1.24 | CD7: 1.12 | CF7: 0.1 | CG7: 0.21 | CI7: 0.25 | CJ7: 0.18 | CM7: 0
A8: 2020_00081 | B8: 10 | C8: 3 | D8: 3 | G8: 3 | I8: 3 | J8: 3 | L8: 2 | M8: 2 | N8: 0.9 | O8: 0.9 | P8: 0.9 | Q8: 0.9 | R8: 0.9 | S8: 0.9 | T8: 0.005 | U8: 0.005 | V8: 0.005 | W8: 5 | X8: 5 | Y8: 5 | Z8: 100 | AA8: 100 | AB8: 100 | AC8: 0.136741 | AD8: 0.1824 | AE8: 0.081042 | AF8: 0.120417 | AG8: 0.180219 | AH8: 0.068021 | AI8: 133.54 | AJ8: 192.26 | AK8: 71.48 | AN8: 28 | AQ8: 72 | AR8: 0.000101 | AS8: 0.000102 | AT8: 0.00011 | AU8: 0.08391 | AV8: 0.108887 | AW8: 0.046288 | AX8: 0.084011 | AY8: 0.108989 | AZ8: 0.046397 | BA8: 0.05273 | BE8: 0.073411 | BF8: 0.033544 | BH8: 0.002276 | BI8: 0.000993 | BK8: 3.9e-05 | BL8: 3.9e-05 | BN8: 0.000501 | BO8: 0.000197 | BR8: 0.0011 | BS8: 61.44 | BT8: 59.75 | BU8: 57.25 | BV8: 38.56 | BZ8: 40.25 | CA8: 41.39 | CC8: 1.25 | CD8: 1.22 | CF8: 0.02 | CG8: 0.05 | CI8: 0.27 | CJ8: 0.24 | CM8: 1.36
A9: 2020_00095 | B9: 10 | C9: 3 | D9: 3 | G9: 3 | I9: 3 | J9: 3 | L9: 2 | M9: 2 | N9: 0.9 | O9: 0.9 | P9: 0.9 | Q9: 0.9 | R9: 0.9 | S9: 0.9 | T9: 0.005 | U9: 0.005 | V9: 0.005 | W9: 5 | X9: 5 | Y9: 5 | Z9: 100 | AA9: 100 | AB9: 100 | AC9: 0.113846 | AD9: 0.082677 | AE9: 0.038629 | AF9: 0.093769 | AG9: 0.075033 | AH9: 0.032881 | AI9: 121.46 | AJ9: 92.83 | AK9: 36.58 | AN9: 4 | AQ9: 96 | AR9: 0.000107 | AS9: 0.000111 | AT9: 0.000118 | AU9: 0.069615 | AV9: 0.049166 | AW9: 0.021784 | AX9: 0.069722 | AY9: 0.049277 | AZ9: 0.021902 | BA9: 0.044124 | BE9: 0.0334 | BF9: 0.016701 | BH9: 0.001125 | BI9: 0.00051 | BK9: 4.2e-05 | BL9: 4.1e-05 | BN9: 0.000238 | BO9: 9.2e-05 | BR9: 2.6e-05 | BS9: 61.24 | BT9: 59.6 | BU9: 56.7 | BV9: 38.76 | BZ9: 40.4 | CA9: 43.23 | CC9: 1.36 | CD9: 1.32 | CF9: 0.05 | CG9: 0.11 | CI9: 0.29 | CJ9: 0.24 | CM9: 0.07
A10: 2020_00153 | B10: 10 | C10: 3 | D10: 3 | G10: 3 | I10: 3 | J10: 3 | L10: 2 | M10: 2 | N10: 0.9 | O10: 0.9 | P10: 0.9 | Q10: 0.9 | R10: 0.9 | S10: 0.9 | T10: 0.005 | U10: 0.005 | V10: 0.005 | W10: 5 | X10: 5 | Y10: 5 | Z10: 100 | AA10: 100 | AB10: 100 | AC10: 0.14536 | AD10: 0.104244 | AE10: 0.064772 | AF10: 0.132572 | AG10: 0.090145 | AH10: 0.060614 | AI10: 138.84 | AJ10: 106.93 | AK10: 57.23 | AN10: 17 | AQ10: 83 | AR10: 0.000111 | AS10: 0.000109 | AT10: 0.000112 | AU10: 0.089073 | AV10: 0.062349 | AW10: 0.036798 | AX10: 0.089184 | AY10: 0.062458 | AZ10: 0.03691 | BA10: 0.056175 | BE10: 0.041786 | BF10: 0.027076 | BH10: 0.001333 | BI10: 0.000801 | BK10: 3.9e-05 | BL10: 3.9e-05 | BN10: 0.000293 | BO10: 0.000159 | BR10: 0.000786 | BS10: 61.35 | BT10: 59.91 | BU10: 56.98 | BV10: 38.65 | BZ10: 40.09 | CA10: 41.8 | CC10: 1.28 | CD10: 1.24 | CF10: 0.04 | CG10: 0.06 | CI10: 0.28 | CJ10: 0.24 | CM10: 1.21
A11: 2020_00155 | B11: 10 | C11: 3 | D11: 3 | G11: 3 | I11: 3 | J11: 3 | L11: 2 | M11: 2 | N11: 0.9 | O11: 0.9 | P11: 0.9 | Q11: 0.9 | R11: 0.9 | S11: 0.9 | T11: 0.005 | U11: 0.005 | V11: 0.005 | W11: 5 | X11: 5 | Y11: 5 | Z11: 100 | AA11: 100 | AB11: 100 | AC11: 0.094072 | AD11: 0.086262 | AE11: 0.037007 | AF11: 0.082548 | AG11: 0.091642 | AH11: 0.033527 | AI11: 84.05 | AJ11: 80.01 | AK11: 29.88 | AN11: 2 | AQ11: 98 | AR11: 9.9e-05 | AS11: 0.000104 | AT11: 0.000111 | AU11: 0.058196 | AV11: 0.052235 | AW11: 0.021166 | AX11: 0.058296 | AY11: 0.052339 | AZ11: 0.021277 | BA11: 0.035776 | BE11: 0.033922 | BF11: 0.015647 | BH11: 0.000989 | BI11: 0.000405 | BK11: 4.4e-05 | BL11: 3.9e-05 | BN11: 0.000216 | BO11: 7.5e-05 | BR11: 8.3e-05 | BS11: 61.97 | BT11: 60.67 | BU11: 57.5 | BV11: 38.03 | BZ11: 39.32 | CA11: 42.28 | CC11: 1.15 | CD11: 1.09 | CF11: 0.05 | CG11: 0.11 | CI11: 0.25 | CJ11: 0.2 | CM11: 0.23
A12: 2020_00159 | B12: 10 | C12: 3 | D12: 3 | G12: 3 | I12: 3 | J12: 3 | L12: 2 | M12: 2 | N12: 0.9 | O12: 0.9 | P12: 0.9 | Q12: 0.9 | R12: 0.9 | S12: 0.9 | T12: 0.005 | U12: 0.005 | V12: 0.005 | W12: 5 | X12: 5 | Y12: 5 | Z12: 100 | AA12: 100 | AB12: 100 | AC12: 0.097996 | AD12: 0.096262 | AE12: 0.039343 | AF12: 0.08065 | AG12: 0.099149 | AH12: 0.036724 | AI12: 105.07 | AJ12: 110.96 | AK12: 37.94 | AN12: 4 | AQ12: 96 | AR12: 0.000107 | AS12: 0.000106 | AT12: 0.00012 | AU12: 0.059847 | AV12: 0.057095 | AW12: 0.022183 | AX12: 0.059955 | AY12: 0.057201 | AZ12: 0.022303 | BA12: 0.038042 | BE12: 0.039061 | BF12: 0.017031 | BH12: 0.001306 | BI12: 0.000519 | BK12: 3.9e-05 | BL12: 3.7e-05 | BN12: 0.000287 | BO12: 9.9e-05 | BR12: 9e-06 | BS12: 61.18 | BT12: 59.42 | BU12: 56.69 | BV12: 38.82 | BZ12: 40.58 | CA12: 43.29 | CC12: 1.36 | CD12: 1.32 | CF12: 0.04 | CG12: 0.1 | CI12: 0.3 | CJ12: 0.25 | CM12: 0.02
A13: 2020_00175 | B13: 10 | C13: 3 | D13: 3 | G13: 3 | I13: 3 | J13: 3 | L13: 2 | M13: 2 | N13: 0.9 | O13: 0.9 | P13: 0.9 | Q13: 0.9 | R13: 0.9 | S13: 0.9 | T13: 0.005 | U13: 0.005 | V13: 0.005 | W13: 5 | X13: 5 | Y13: 5 | Z13: 100 | AA13: 100 | AB13: 100 | AC13: 0.071197 | AD13: 0.060642 | AE13: 0.027808 | AF13: 0.052337 | AG13: 0.053005 | AH13: 0.020924 | AI13: 82.26 | AJ13: 72.25 | AK13: 29.42 | AN13: 0 | AQ13: 100 | AR13: 0.000121 | AS13: 0.00012 | AT13: 0.000126 | AU13: 0.043218 | AV13: 0.035679 | AW13: 0.015204 | AX13: 0.043338 | AY13: 0.035799 | AZ13: 0.015329 | BA13: 0.027859 | BE13: 0.024844 | BF13: 0.012479 | BH13: 0.000919 | BI13: 0.00039 | BK13: 4.3e-05 | BL13: 3.7e-05 | BN13: 0.000198 | BO13: 7.2e-05 | BR13: 0 | BS13: 60.87 | BT13: 59.03 | BU13: 55.13 | BV13: 39.13 | BZ13: 40.97 | CA13: 44.87 | CC13: 1.52 | CD13: 1.4 | CF13: 0.07 | CG13: 0.13 | CI13: 0.33 | CJ13: 0.26 | CM13: 0
... A102: paquita_00100 | B102: 10 | C102: 3 | D102: 3 | G102: 3 | I102: 3 | J102: 3 | L102: 2 | M102: 2 | N102: 0.9 | O102: 0.9 | P102: 0.9 | Q102: 0.9 | R102: 0.9 | S102: 0.9 | T102: 0.005 | U102: 0.005 | V102: 0.005 | W102: 5 | X102: 5 | Y102: 5 | Z102: 100 | AA102: 100 | AB102: 100 | AC102: 0.011658 | AD102: 0.006129 | AE102: 0.003079 | AF102: 0.01344 | AG102: 0.007124 | AH102: 0.002562 | AI102: 15.12 | AJ102: 7.99 | AK102: 2.88 | AN102: 0 | AQ102: 100 | AR102: 0.000112 | AS102: 0.000117 | AT102: 0.000118 | AU102: 0.006857 | AV102: 0.003444 | AW102: 0.001101 | AX102: 0.006969 | AY102: 0.003561 | AZ102: 0.001219 | BA102: 0.004689 | BE102: 0.002569 | BF102: 0.00186 | BH102: 8.6e-05 | BI102: 2.7e-05 | BK102: 2.6e-05 | BL102: 9e-06 | BN102: 1.9e-05 | BO102: 5e-06 | BR102: 0 | BS102: 59.78 | BT102: 58.09 | BU102: 39.58 | BV102: 40.22 | BZ102: 41.91 | CA102: 60.41 | CC102: 1.4 | CD102: 0.87 | CF102: 0.43 | CG102: 0.28 | CI102: 0.31 | CJ102: 0.15 | CM102: 0

Sheet Run_2
A1: puzzle_size | B1: nAnts_alg0 | C1: nAnts_alg3 | D1: nAnts_alg4 | E1: threads_alg0 | F1: threads_alg3 | G1: threads_alg4 | H1: numcolonies_alg0 | I1: numcolonies_alg3 | J1: numcolonies_alg4 | K1: numacs_alg0 | L1: numacs_alg3 | M1: numacs_alg4 | N1: q0_alg0 | O1: q0_alg3 | P1: q0_alg4 | Q1: rho_alg0 | R1: rho_alg3 | S1: rho_alg4 | T1: bve_alg0 | U1: bve_alg3 | V1: bve_alg4 | W1: timeout_alg0 | X1: timeout_alg3 | Y1: timeout_alg4 | Z1: success_rate_alg0 | AA1: success_rate_alg3 | AB1: success_rate_alg4 | AC1: time_mean_alg0 | AD1: time_mean_alg3 | AE1: time_mean_alg4 | AF1: time_std_alg0 | AG1: time_std_alg3 | AH1: time_std_alg4 | AI1: iter_mean_alg0 | AJ1: iter_mean_alg3 | AK1: iter_mean_alg4 | AL1: with_comm_alg0 | AM1: with_comm_alg3 | AN1: with_comm_alg4 | AO1: without_comm_alg0 | AP1: without_comm_alg3 | AQ1: without_comm_alg4 | AR1: cp_initial_mean_alg0 | AS1: cp_initial_mean_alg3 | AT1: cp_initial_mean_alg4 | AU1: cp_ant_mean_alg0 | AV1: cp_ant_mean_alg3 | AW1: cp_ant_mean_alg4 | AX1: cp_total_mean_alg0 | AY1: cp_total_mean_alg3 | AZ1: cp_total_mean_alg4 | BA1: acs_time_mean_alg0 | BB1: acs_time_mean_alg3 | BC1: acs_time_mean_alg4 | BD1: dcm_aco_time_mean_alg0 | BE1: dcm_aco_time_mean_alg3 | BF1: dcm_aco_time_mean_alg4 | BG1: coop_game_mean_alg0 | BH1: coop_game_mean_alg3 | BI1: coop_game_mean_alg4 | BJ1: pheromone_fusion_mean_alg0 | BK1: pheromone_fusion_mean_alg3 | BL1: pheromone_fusion_mean_alg4 | BM1: public_path_mean_alg0 | BN1: public_path_mean_alg3 | BO1: public_path_mean_alg4 | BP1: communication_time_mean_alg0 | BQ1: communication_time_mean_alg3 | BR1: communication_time_mean_alg4 | BS1: cp_percentage_alg0 | BT1: cp_percentage_alg3 | BU1: cp_percentage_alg4 | BV1: acs_time_percentage_alg0 | BW1: acs_time_percentage_alg3 | BX1: acs_time_percentage_alg4 | BY1: dcm_aco_time_percentage_alg0 | BZ1: dcm_aco_time_percentage_alg3 | CA1: dcm_aco_time_percentage_alg4 | CB1: coop_game_percentage_alg0 | CC1: coop_game_percentage_alg3 | CD1: coop_game_percentage_alg4 | CE1: pheromone_fusion_percentage_alg0 | CF1: pheromone_fusion_percentage_alg3 | CG1: pheromone_fusion_percentage_alg4 | CH1: public_path_percentage_alg0 | CI1: public_path_percentage_alg3 | CJ1: public_path_percentage_alg4 | CK1: communication_time_percentage_alg0 | CL1: communication_time_percentage_alg3 | CM1: communication_time_percentage_alg4
A2: 2020_00004 | B2: 10 | C2: 3 | D2: 3 | G2: 3 | I2: 3 | J2: 3 | L2: 2 | M2: 2 | N2: 0.9 | O2: 0.9 | P2: 0.9 | Q2: 0.9 | R2: 0.9 | S2: 0.9 | T2: 0.005 | U2: 0.005 | V2: 0.005 | W2: 5 | X2: 5 | Y2: 5 | Z2: 100 | AA2: 100 | AB2: 100 | AC2: 0.077262 | AD2: 0.041735 | AE2: 0.018297 | AF2: 0.24416 | AG2: 0.036612 | AH2: 0.015035 | AI2: 89.93 | AJ2: 49.72 | AK2: 17.91 | AN2: 0 | AQ2: 100 | AR2: 8.3e-05 | AS2: 8.4e-05 | AT2: 9.3e-05 | AU2: 0.048313 | AV2: 0.025019 | AW2: 0.009963 | AX2: 0.048395 | AY2: 0.025103 | AZ2: 0.010056 | BA2: 0.028867 | BE2: 0.016632 | BF2: 0.008241 | BH2: 0.000508 | BI2: 0.000201 | BK2: 3.6e-05 | BL2: 3.3e-05 | BN2: 0.000104 | BO2: 3.4e-05 | BR2: 0 | BS2: 62.64 | BT2: 60.15 | BU2: 54.96 | BV2: 37.36 | BZ2: 39.85 | CA2: 45.04 | CC2: 1.22 | CD2: 1.1 | CF2: 0.09 | CG2: 0.18 | CI2: 0.25 | CJ2: 0.19 | CM2: 0
A3: 2020_00021 | B3: 10 | C3: 3 | D3: 3 | G3: 3 | I3: 3 | J3: 3 | L3: 2 | M3: 2 | N3: 0.9 | O3: 0.9 | P3: 0.9 | Q3: 0.9 | R3: 0.9 | S3: 0.9 | T3: 0.005 | U3: 0.005 | V3: 0.005 | W3: 5 | X3: 5 | Y3: 5 | Z3: 100 | AA3: 100 | AB3: 100 | AC3: 0.083768 | AD3: 0.055693 | AE3: 0.023588 | AF3: 0.069754 | AG3: 0.052754 | AH3: 0.021889 | AI3: 97.26 | AJ3: 67.55 | AK3: 22.84 | AN3: 0 | AQ3: 100 | AR3: 8.2e-05 | AS3: 8.5e-05 | AT3: 9.6e-05 | AU3: 0.051271 | AV3: 0.033141 | AW3: 0.012977 | AX3: 0.051353 | AY3: 0.033227 | AZ3: 0.013073 | BA3: 0.032415 | BE3: 0.022466 | BF3: 0.010515 | BH3: 0.000707 | BI3: 0.000278 | BK3: 4.1e-05 | BL3: 3.4e-05 | BN3: 0.00014 | BO3: 4.8e-05 | BR3: 0 | BS3: 61.3 | BT3: 59.66 | BU3: 55.42 | BV3: 38.7 | BZ3: 40.34 | CA3: 44.58 | CC3: 1.27 | CD3: 1.18 | CF3: 0.07 | CG3: 0.14 | CI3: 0.25 | CJ3: 0.2 | CM3: 0
A4: 2020_00041 | B4: 10 | C4: 3 | D4: 3 | G4: 3 | I4: 3 | J4: 3 | L4: 2 | M4: 2 | N4: 0.9 | O4: 0.9 | P4: 0.9 | Q4: 0.9 | R4: 0.9 | S4: 0.9 | T4: 0.005 | U4: 0.005 | V4: 0.005 | W4: 5 | X4: 5 | Y4: 5 | Z4: 100 | AA4: 100 | AB4: 100 | AC4: 0.090829 | AD4: 0.066545 | AE4: 0.019215 | AF4: 0.078071 | AG4: 0.068558 | AH4: 0.025964 | AI4: 103.46 | AJ4: 82.62 | AK4: 19.15 | AN4: 2 | AQ4: 98 | AR4: 8.7e-05 | AS4: 8.8e-05 | AT4: 9.7e-05 | AU4: 0.055927 | AV4: 0.039858 | AW4: 0.010489 | AX4: 0.056015 | AY4: 0.039946 | AZ4: 0.010586 | BA4: 0.034814 | BE4: 0.0266 | BF4: 0.008563 | BH4: 0.000837 | BI4: 0.000214 | BK4: 3.6e-05 | BL4: 3.3e-05 | BN4: 0.000174 | BO4: 3.9e-05 | BR4: 6.6e-05 | BS4: 61.67 | BT4: 60.03 | BU4: 55.09 | BV4: 38.33 | BZ4: 39.97 | CA4: 44.57 | CC4: 1.26 | CD4: 1.12 | CF4: 0.05 | CG4: 0.17 | CI4: 0.26 | CJ4: 0.2 | CM4: 0.34
A5: 2020_00049 | B5: 10 | C5: 3 | D5: 3 | G5: 3 | I5: 3 | J5: 3 | L5: 2 | M5: 2 | N5: 0.9 | O5: 0.9 | P5: 0.9 | Q5: 0.9 | R5: 0.9 | S5: 0.9 | T5: 0.005 | U5: 0.005 | V5: 0.005 | W5: 5 | X5: 5 | Y5: 5 | Z5: 100 | AA5: 100 | AB5: 100 | AC5: 0.111314 | AD5: 0.113554 | AE5: 0.041386 | AF5: 0.092957 | AG5: 0.107417 | AH5: 0.03516 | AI5: 118.17 | AJ5: 133.76 | AK5: 40.17 | AN5: 7 | AQ5: 93 | AR5: 8.6e-05 | AS5: 8.4e-05 | AT5: 9.5e-05 | AU5: 0.068725 | AV5: 0.06835 | AW5: 0.023571 | AX5: 0.068811 | AY5: 0.068433 | AZ5: 0.023665 | BA5: 0.042504 | BE5: 0.045121 | BF5: 0.017562 | BH5: 0.001357 | BI5: 0.000464 | BK5: 3.7e-05 | BL5: 3.2e-05 | BN5: 0.00029 | BO5: 8.6e-05 | BR5: 0.000159 | BS5: 61.82 | BT5: 60.27 | BU5: 57.18 | BV5: 38.18 | BZ5: 39.73 | CA5: 42.44 | CC5: 1.19 | CD5: 1.12 | CF5: 0.03 | CG5: 0.08 | CI5: 0.26 | CJ5: 0.21 | CM5: 0.38
A6: 2020_00054 | B6: 10 | C6: 3 | D6: 3 | G6: 3 | I6: 3 | J6: 3 | L6: 2 | M6: 2 | N6: 0.9 | O6: 0.9 | P6: 0.9 | Q6: 0.9 | R6: 0.9 | S6: 0.9 | T6: 0.005 | U6: 0.005 | V6: 0.005 | W6: 5 | X6: 5 | Y6: 5 | Z6: 100 | AA6: 100 | AB6: 100 | AC6: 0.090459 | AD6: 0.061564 | AE6: 0.030871 | AF6: 0.074445 | AG6: 0.044115 | AH6: 0.024561 | AI6: 102.52 | AJ6: 76 | AK6: 31.63 | AN6: 3 | AQ6: 97 | AR6: 9.1e-05 | AS6: 9.1e-05 | AT6: 9.8e-05 | AU6: 0.055122 | AV6: 0.036536 | AW6: 0.01716 | AX6: 0.055213 | AY6: 0.036627 | AZ6: 0.017259 | BA6: 0.035246 | BE6: 0.024937 | BF6: 0.0135 | BH6: 0.000779 | BI6: 0.000365 | BK6: 3.6e-05 | BL6: 3.2e-05 | BN6: 0.000168 | BO6: 6.7e-05 | BR6: 0.000112 | BS6: 61.04 | BT6: 59.49 | BU6: 55.91 | BV6: 38.96 | BZ6: 40.51 | CA6: 43.73 | CC6: 1.27 | CD6: 1.18 | CF6: 0.06 | CG6: 0.1 | CI6: 0.27 | CJ6: 0.22 | CM6: 0.36
A7: 2020_00057 | B7: 10 | C7: 3 | D7: 3 | G7: 3 | I7: 3 | J7: 3 | L7: 2 | M7: 2 | N7: 0.9 | O7: 0.9 | P7: 0.9 | Q7: 0.9 | R7: 0.9 | S7: 0.9 | T7: 0.005 | U7: 0.005 | V7: 0.005 | W7: 5 | X7: 5 | Y7: 5 | Z7: 100 | AA7: 100 | AB7: 100 | AC7: 0.043797 | AD7: 0.038555 | AE7: 0.015893 | AF7: 0.033904 | AG7: 0.037224 | AH7: 0.012445 | AI7: 48.9 | AJ7: 45.5 | AK7: 15.57 | AN7: 0 | AQ7: 100 | AR7: 8.5e-05 | AS7: 8.8e-05 | AT7: 9.5e-05 | AU7: 0.026898 | AV7: 0.023062 | AW7: 0.008539 | AX7: 0.026983 | AY7: 0.02315 | AZ7: 0.008634 | BA7: 0.016814 | BE7: 0.015405 | BF7: 0.007259 | BH7: 0.000477 | BI7: 0.000171 | BK7: 3.6e-05 | BL7: 3.7e-05 | BN7: 9.8e-05 | BO7: 2.8e-05 | BR7: 0 | BS7: 61.61 | BT7: 60.04 | BU7: 54.33 | BV7: 38.39 | BZ7: 39.95 | CA7: 45.67 | CC7: 1.24 | CD7: 1.08 | CF7: 0.09 | CG7: 0.23 | CI7: 0.26 | CJ7: 0.18 | CM7: 0
A8: 2020_00081 | B8: 10 | C8: 3 | D8: 3 | G8: 3 | I8: 3 | J8: 3 | L8: 2 | M8: 2 | N8: 0.9 | O8: 0.9 | P8: 0.9 | Q8: 0.9 | R8: 0.9 | S8: 0.9 | T8: 0.005 | U8: 0.005 | V8: 0.005 | W8: 5 | X8: 5 | Y8: 5 | Z8: 100 | AA8: 100 | AB8: 100 | AC8: 0.121112 | AD8: 0.149524 | AE8: 0.05938 | AF8: 0.093005 | AG8: 0.135724 | AH8: 0.049979 | AI8: 134.87 | AJ8: 179.67 | AK8: 59.74 | AN8: 18 | AQ8: 82 | AR8: 8.9e-05 | AS8: 8.9e-05 | AT8: 9.7e-05 | AU8: 0.074005 | AV8: 0.089304 | AW8: 0.033693 | AX8: 0.074094 | AY8: 0.089392 | AZ8: 0.033791 | BA8: 0.047018 | BE8: 0.060132 | BF8: 0.025111 | BH8: 0.001853 | BI8: 0.000701 | BK8: 3.4e-05 | BL8: 3.3e-05 | BN8: 0.000404 | BO8: 0.000137 | BR8: 0.000478 | BS8: 61.18 | BT8: 59.78 | BU8: 56.91 | BV8: 38.82 | BZ8: 40.22 | CA8: 42.29 | CC8: 1.24 | CD8: 1.18 | CF8: 0.02 | CG8: 0.06 | CI8: 0.27 | CJ8: 0.23 | CM8: 0.8
A9: 2020_00095 | B9: 10 | C9: 3 | D9: 3 | G9: 3 | I9: 3 | J9: 3 | L9: 2 | M9: 2 | N9: 0.9 | O9: 0.9 | P9: 0.9 | Q9: 0.9 | R9: 0.9 | S9: 0.9 | T9: 0.005 | U9: 0.005 | V9: 0.005 | W9: 5 | X9: 5 | Y9: 5 | Z9: 100 | AA9: 100 | AB9: 100 | AC9: 0.084796 | AD9: 0.066231 | AE9: 0.031278 | AF9: 0.079831 | AG9: 0.069912 | AH9: 0.030018 | AI9: 103.85 | AJ9: 85.85 | AK9: 33.98 | AN9: 5 | AQ9: 95 | AR9: 9.1e-05 | AS9: 9.5e-05 | AT9: 0.000102 | AU9: 0.051649 | AV9: 0.03924 | AW9: 0.017352 | AX9: 0.05174 | AY9: 0.039335 | AZ9: 0.017454 | BA9: 0.033056 | BE9: 0.026896 | BF9: 0.013664 | BH9: 0.000899 | BI9: 0.000391 | BK9: 3.8e-05 | BL9: 3.5e-05 | BN9: 0.00019 | BO9: 7e-05 | BR9: 0.00016 | BS9: 61.02 | BT9: 59.39 | BU9: 55.8 | BV9: 38.98 | BZ9: 40.61 | CA9: 43.69 | CC9: 1.36 | CD9: 1.25 | CF9: 0.06 | CG9: 0.11 | CI9: 0.29 | CJ9: 0.22 | CM9: 0.51
A10: 2020_00153 | B10: 10 | C10: 3 | D10: 3 | G10: 3 | I10: 3 | J10: 3 | L10: 2 | M10: 2 | N10: 0.9 | O10: 0.9 | P10: 0.9 | Q10: 0.9 | R10: 0.9 | S10: 0.9 | T10: 0.005 | U10: 0.005 | V10: 0.005 | W10: 5 | X10: 5 | Y10: 5 | Z10: 100 | AA10: 100 | AB10: 100 | AC10: 0.13037 | AD10: 0.095535 | AE10: 0.037194 | AF10: 0.117823 | AG10: 0.086111 | AH10: 0.034235 | AI10: 146.39 | AJ10: 114.47 | AK10: 37.61 | AN10: 6 | AQ10: 94 | AR10: 9.1e-05 | AS10: 9.3e-05 | AT10: 0.0001 | AU10: 0.079704 | AV10: 0.056907 | AW10: 0.020877 | AX10: 0.079796 | AY10: 0.057 | AZ10: 0.020977 | BA10: 0.050574 | BE10: 0.038536 | BF10: 0.01604 | BH10: 0.001196 | BI10: 0.000439 | BK10: 3.6e-05 | BL10: 3.1e-05 | BN10: 0.000265 | BO10: 8.4e-05 | BR10: 0.000176 | BS10: 61.21 | BT10: 59.66 | BU10: 56.4 | BV10: 38.79 | BZ10: 40.34 | CA10: 43.13 | CC10: 1.25 | CD10: 1.18 | CF10: 0.04 | CG10: 0.08 | CI10: 0.28 | CJ10: 0.23 | CM10: 0.47
A11: 2020_00155 | B11: 10 | C11: 3 | D11: 3 | G11: 3 | I11: 3 | J11: 3 | L11: 2 | M11: 2 | N11: 0.9 | O11: 0.9 | P11: 0.9 | Q11: 0.9 | R11: 0.9 | S11: 0.9 | T11: 0.005 | U11: 0.005 | V11: 0.005 | W11: 5 | X11: 5 | Y11: 5 | Z11: 100 | AA11: 100 | AB11: 100 | AC11: 0.073761 | AD11: 0.08223 | AE11: 0.035876 | AF11: 0.0654 | AG11: 0.078584 | AH11: 0.037484 | AI11: 75.91 | AJ11: 91.78 | AK11: 32.22 | AN11: 5 | AQ11: 95 | AR11: 8.7e-05 | AS11: 8.6e-05 | AT11: 9.7e-05 | AU11: 0.045383 | AV11: 0.04958 | AW11: 0.020435 | AX11: 0.04547 | AY11: 0.049666 | AZ11: 0.020532 | BA11: 0.028291 | BE11: 0.032564 | BF11: 0.015269 | BH11: 0.000922 | BI11: 0.000387 | BK11: 3.6e-05 | BL11: 3.7e-05 | BN11: 0.000199 | BO11: 7.3e-05 | BR11: 7.5e-05 | BS11: 61.64 | BT11: 60.4 | BU11: 57.23 | BV11: 38.36 | BZ11: 39.6 | CA11: 42.56 | CC11: 1.12 | CD11: 1.08 | CF11: 0.04 | CG11: 0.1 | CI11: 0.24 | CJ11: 0.2 | CM11: 0.21
A12: 2020_00159 | B12: 10 | C12: 3 | D12: 3 | G12: 3 | I12: 3 | J12: 3 | L12: 2 | M12: 2 | N12: 0.9 | O12: 0.9 | P12: 0.9 | Q12: 0.9 | R12: 0.9 | S12: 0.9 | T12: 0.005 | U12: 0.005 | V12: 0.005 | W12: 5 | X12: 5 | Y12: 5 | Z12: 100 | AA12: 100 | AB12: 100 | AC12: 0.094899 | AD12: 0.074768 | AE12: 0.03628 | AF12: 0.078767 | AG12: 0.091127 | AH12: 0.034139 | AI12: 116.72 | AJ12: 98.59 | AK12: 39.2 | AN12: 9 | AQ12: 91 | AR12: 9.5e-05 | AS12: 9.5e-05 | AT12: 0.000103 | AU12: 0.057758 | AV12: 0.044131 | AW12: 0.020275 | AX12: 0.057853 | AY12: 0.044225 | AZ12: 0.020377 | BA12: 0.037046 | BE12: 0.030543 | BF12: 0.015765 | BH12: 0.000999 | BI12: 0.000464 | BK12: 3.3e-05 | BL12: 3.3e-05 | BN12: 0.000217 | BO12: 9.1e-05 | BR12: 0.000137 | BS12: 60.96 | BT12: 59.15 | BU12: 56.17 | BV12: 39.04 | BZ12: 40.85 | CA12: 43.45 | CC12: 1.34 | CD12: 1.28 | CF12: 0.04 | CG12: 0.09 | CI12: 0.29 | CJ12: 0.25 | CM12: 0.38
A13: 2020_00175 | B13: 10 | C13: 3 | D13: 3 | G13: 3 | I13: 3 | J13: 3 | L13: 2 | M13: 2 | N13: 0.9 | O13: 0.9 | P13: 0.9 | Q13: 0.9 | R13: 0.9 | S13: 0.9 | T13: 0.005 | U13: 0.005 | V13: 0.005 | W13: 5 | X13: 5 | Y13: 5 | Z13: 100 | AA13: 100 | AB13: 100 | AC13: 0.058491 | AD13: 0.048092 | AE13: 0.025285 | AF13: 0.046525 | AG13: 0.039326 | AH13: 0.018414 | AI13: 76.8 | AJ13: 69.41 | AK13: 30.08 | AN13: 0 | AQ13: 100 | AR13: 0.000102 | AS13: 0.0001 | AT13: 0.00011 | AU13: 0.035372 | AV13: 0.028134 | AW13: 0.013786 | AX13: 0.035474 | AY13: 0.028234 | AZ13: 0.013895 | BA13: 0.023017 | BE13: 0.019859 | BF13: 0.011389 | BH13: 0.000723 | BI13: 0.000346 | BK13: 3.3e-05 | BL13: 3.4e-05 | BN13: 0.000152 | BO13: 6.3e-05 | BR13: 0 | BS13: 60.65 | BT13: 58.71 | BU13: 54.96 | BV13: 39.35 | BZ13: 41.29 | CA13: 45.04 | CC13: 1.5 | CD13: 1.37 | CF13: 0.07 | CG13: 0.13 | CI13: 0.32 | CJ13: 0.25 | CM13: 0
... A102: paquita_00100 | B102: 10 | C102: 3 | D102: 3 | G102: 3 | I102: 3 | J102: 3 | L102: 2 | M102: 2 | N102: 0.9 | O102: 0.9 | P102: 0.9 | Q102: 0.9 | R102: 0.9 | S102: 0.9 | T102: 0.005 | U102: 0.005 | V102: 0.005 | W102: 5 | X102: 5 | Y102: 5 | Z102: 100 | AA102: 100 | AB102: 100 | AC102: 0.009404 | AD102: 0.004699 | AE102: 0.002677 | AF102: 0.01087 | AG102: 0.005439 | AH102: 0.002014 | AI102: 12.41 | AJ102: 6.12 | AK102: 2.41 | AN102: 0 | AQ102: 100 | AR102: 0.000111 | AS102: 0.000116 | AT102: 0.000119 | AU102: 0.00552 | AV102: 0.002618 | AW102: 0.00087 | AX102: 0.005631 | AY102: 0.002735 | AZ102: 0.000989 | BA102: 0.003773 | BE102: 0.001965 | BF102: 0.001687 | BH102: 6.5e-05 | BI102: 2.1e-05 | BK102: 2.3e-05 | BL102: 8e-06 | BN102: 1.4e-05 | BO102: 4e-06 | BR102: 0 | BS102: 59.88 | BT102: 58.19 | BU102: 36.96 | BV102: 40.12 | BZ102: 41.81 | CA102: 63.02 | CC102: 1.39 | CD102: 0.77 | CF102: 0.49 | CG102: 0.32 | CI102: 0.3 | CJ102: 0.15 | CM102: 0

Sheet Run_3
A1: puzzle_size | B1: nAnts_alg0 | C1: nAnts_alg3 | D1: nAnts_alg4 | E1: threads_alg0 | F1: threads_alg3 | G1: threads_alg4 | H1: numcolonies_alg0 | I1: numcolonies_alg3 | J1: numcolonies_alg4 | K1: numacs_alg0 | L1: numacs_alg3 | M1: numacs_alg4 | N1: q0_alg0 | O1: q0_alg3 | P1: q0_alg4 | Q1: rho_alg0 | R1: rho_alg3 | S1: rho_alg4 | T1: bve_alg0 | U1: bve_alg3 | V1: bve_alg4 | W1: timeout_alg0 | X1: timeout_alg3 | Y1: timeout_alg4 | Z1: success_rate_alg0 | AA1: success_rate_alg3 | AB1: success_rate_alg4 | AC1: time_mean_alg0 | AD1: time_mean_alg3 | AE1: time_mean_alg4 | AF1: time_std_alg0 | AG1: time_std_alg3 | AH1: time_std_alg4 | AI1: iter_mean_alg0 | AJ1: iter_mean_alg3 | AK1: iter_mean_alg4 | AL1: with_comm_alg0 | AM1: with_comm_alg3 | AN1: with_comm_alg4 | AO1: without_comm_alg0 | AP1: without_comm_alg3 | AQ1: without_comm_alg4 | AR1: cp_initial_mean_alg0 | AS1: cp_initial_mean_alg3 | AT1: cp_initial_mean_alg4 | AU1: cp_ant_mean_alg0 | AV1: cp_ant_mean_alg3 | AW1: cp_ant_mean_alg4 | AX1: cp_total_mean_alg0 | AY1: cp_total_mean_alg3 | AZ1: cp_total_mean_alg4 | BA1: acs_time_mean_alg0 | BB1: acs_time_mean_alg3 | BC1: acs_time_mean_alg4 | BD1: dcm_aco_time_mean_alg0 | BE1: dcm_aco_time_mean_alg3 | BF1: dcm_aco_time_mean_alg4 | BG1: coop_game_mean_alg0 | BH1: coop_game_mean_alg3 | BI1: coop_game_mean_alg4 | BJ1: pheromone_fusion_mean_alg0 | BK1: pheromone_fusion_mean_alg3 | BL1: pheromone_fusion_mean_alg4 | BM1: public_path_mean_alg0 | BN1: public_path_mean_alg3 | BO1: public_path_mean_alg4 | BP1: communication_time_mean_alg0 | BQ1: communication_time_mean_alg3 | BR1: communication_time_mean_alg4 | BS1: cp_percentage_alg0 | BT1: cp_percentage_alg3 | BU1: cp_percentage_alg4 | BV1: acs_time_percentage_alg0 | BW1: acs_time_percentage_alg3 | BX1: acs_time_percentage_alg4 | BY1: dcm_aco_time_percentage_alg0 | BZ1: dcm_aco_time_percentage_alg3 | CA1: dcm_aco_time_percentage_alg4 | CB1: coop_game_percentage_alg0 | CC1: coop_game_percentage_alg3 | CD1: coop_game_percentage_alg4 | CE1: pheromone_fusion_percentage_alg0 | CF1: pheromone_fusion_percentage_alg3 | CG1: pheromone_fusion_percentage_alg4 | CH1: public_path_percentage_alg0 | CI1: public_path_percentage_alg3 | CJ1: public_path_percentage_alg4 | CK1: communication_time_percentage_alg0 | CL1: communication_time_percentage_alg3 | CM1: communication_time_percentage_alg4
A2: 2020_00004 | B2: 10 | C2: 3 | D2: 3 | G2: 3 | I2: 3 | J2: 3 | L2: 2 | M2: 2 | N2: 0.9 | O2: 0.9 | P2: 0.9 | Q2: 0.9 | R2: 0.9 | S2: 0.9 | T2: 0.005 | U2: 0.005 | V2: 0.005 | W2: 5 | X2: 5 | Y2: 5 | Z2: 100 | AA2: 100 | AB2: 100 | AC2: 0.128959 | AD2: 0.041482 | AE2: 0.017839 | AF2: 0.500681 | AG2: 0.039757 | AH2: 0.014735 | AI2: 152.78 | AJ2: 49.19 | AK2: 17.48 | AN2: 0 | AQ2: 100 | AR2: 8.3e-05 | AS2: 8.6e-05 | AT2: 9.1e-05 | AU2: 0.072093 | AV2: 0.024861 | AW2: 0.009713 | AX2: 0.072176 | AY2: 0.024948 | AZ2: 0.009804 | BA2: 0.056783 | BE2: 0.016535 | BF2: 0.008034 | BH2: 0.000505 | BI2: 0.000193 | BK2: 3.7e-05 | BL2: 3.6e-05 | BN2: 0.000109 | BO2: 3.3e-05 | BR2: 0 | BS2: 55.97 | BT2: 60.14 | BU2: 54.96 | BV2: 44.03 | BZ2: 39.86 | CA2: 45.04 | CC2: 1.22 | CD2: 1.08 | CF2: 0.09 | CG2: 0.2 | CI2: 0.26 | CJ2: 0.18 | CM2: 0
A3: 2020_00021 | B3: 10 | C3: 3 | D3: 3 | G3: 3 | I3: 3 | J3: 3 | L3: 2 | M3: 2 | N3: 0.9 | O3: 0.9 | P3: 0.9 | Q3: 0.9 | R3: 0.9 | S3: 0.9 | T3: 0.005 | U3: 0.005 | V3: 0.005 | W3: 5 | X3: 5 | Y3: 5 | Z3: 100 | AA3: 100 | AB3: 100 | AC3: 0.066476 | AD3: 0.058728 | AE3: 0.023356 | AF3: 0.051063 | AG3: 0.049239 | AH3: 0.023516 | AI3: 76.49 | AJ3: 71.28 | AK3: 23.89 | AN3: 2 | AQ3: 98 | AR3: 8.4e-05 | AS3: 8.7e-05 | AT3: 9.3e-05 | AU3: 0.040662 | AV3: 0.034993 | AW3: 0.01287 | AX3: 0.040746 | AY3: 0.03508 | AZ3: 0.012963 | BA3: 0.025729 | BE3: 0.023648 | BF3: 0.010357 | BH3: 0.000744 | BI3: 0.000273 | BK3: 3.5e-05 | BL3: 3.4e-05 | BN3: 0.000149 | BO3: 4.4e-05 | BR3: 3.6e-05 | BS3: 61.3 | BT3: 59.73 | BU3: 55.5 | BV3: 38.7 | BZ3: 40.27 | CA3: 44.34 | CC3: 1.27 | CD3: 1.17 | CF3: 0.06 | CG3: 0.15 | CI3: 0.25 | CJ3: 0.19 | CM3: 0.16
A4: 2020_00041 | B4: 10 | C4: 3 | D4: 3 | G4: 3 | I4: 3 | J4: 3 | L4: 2 | M4: 2 | N4: 0.9 | O4: 0.9 | P4: 0.9 | Q4: 0.9 | R4: 0.9 | S4: 0.9 | T4: 0.005 | U4: 0.005 | V4: 0.005 | W4: 5 | X4: 5 | Y4: 5 | Z4: 100 | AA4: 100 | AB4: 100 | AC4: 0.100831 | AD4: 0.05609 | AE4: 0.021377 | AF4: 0.072557 | AG4: 0.05757 | AH4: 0.029409 | AI4: 114.32 | AJ4: 69.32 | AK4: 21.65 | AN4: 4 | AQ4: 96 | AR4: 8.7e-05 | AS4: 8.7e-05 | AT4: 9.8e-05 | AU4: 0.062025 | AV4: 0.033636 | AW4: 0.011741 | AX4: 0.062113 | AY4: 0.033723 | AZ4: 0.011839 | BA4: 0.038718 | BE4: 0.022368 | BF4: 0.009478 | BH4: 0.000704 | BI4: 0.000245 | BK4: 3.3e-05 | BL4: 3.1e-05 | BN4: 0.000146 | BO4: 4.4e-05 | BR4: 6e-05 | BS4: 61.6 | BT4: 60.12 | BU4: 55.38 | BV4: 38.4 | BZ4: 39.88 | CA4: 44.34 | CC4: 1.26 | CD4: 1.14 | CF4: 0.06 | CG4: 0.14 | CI4: 0.26 | CJ4: 0.21 | CM4: 0.28
A5: 2020_00049 | B5: 10 | C5: 3 | D5: 3 | G5: 3 | I5: 3 | J5: 3 | L5: 2 | M5: 2 | N5: 0.9 | O5: 0.9 | P5: 0.9 | Q5: 0.9 | R5: 0.9 | S5: 0.9 | T5: 0.005 | U5: 0.005 | V5: 0.005 | W5: 5 | X5: 5 | Y5: 5 | Z5: 100 | AA5: 100 | AB5: 100 | AC5: 0.103932 | AD5: 0.121832 | AE5: 0.043024 | AF5: 0.0986 | AG5: 0.106486 | AH5: 0.042395 | AI5: 110.52 | AJ5: 143.8 | AK5: 41.87 | AN5: 9 | AQ5: 91 | AR5: 8.5e-05 | AS5: 8.3e-05 | AT5: 9.2e-05 | AU5: 0.064165 | AV5: 0.073338 | AW5: 0.024446 | AX5: 0.06425 | AY5: 0.073422 | AZ5: 0.024538 | BA5: 0.039682 | BE5: 0.048411 | BF5: 0.018158 | BH5: 0.00146 | BI5: 0.000486 | BK5: 3.8e-05 | BL5: 3.6e-05 | BN5: 0.000309 | BO5: 9e-05 | BR5: 0.000328 | BS5: 61.82 | BT5: 60.26 | BU5: 57.03 | BV5: 38.18 | BZ5: 39.74 | CA5: 42.2 | CC5: 1.2 | CD5: 1.13 | CF5: 0.03 | CG5: 0.08 | CI5: 0.25 | CJ5: 0.21 | CM5: 0.76
A6: 2020_00054 | B6: 10 | C6: 3 | D6: 3 | G6: 3 | I6: 3 | J6: 3 | L6: 2 | M6: 2 | N6: 0.9 | O6: 0.9 | P6: 0.9 | Q6: 0.9 | R6: 0.9 | S6: 0.9 | T6: 0.005 | U6: 0.005 | V6: 0.005 | W6: 5 | X6: 5 | Y6: 5 | Z6: 100 | AA6: 100 | AB6: 100 | AC6: 0.082644 | AD6: 0.051701 | AE6: 0.032038 | AF6: 0.058445 | AG6: 0.047104 | AH6: 0.02932 | AI6: 93.9 | AJ6: 64.15 | AK6: 33.12 | AN6: 4 | AQ6: 96 | AR6: 9e-05 | AS6: 9.1e-05 | AT6: 9.8e-05 | AU6: 0.050373 | AV6: 0.030649 | AW6: 0.017793 | AX6: 0.050463 | AY6: 0.030739 | AZ6: 0.017891 | BA6: 0.032181 | BE6: 0.020962 | BF6: 0.013953 | BH6: 0.00065 | BI6: 0.000379 | BK6: 3.5e-05 | BL6: 3.5e-05 | BN6: 0.000138 | BO6: 7e-05 | BR6: 0.000193 | BS6: 61.06 | BT6: 59.46 | BU6: 55.84 | BV6: 38.94 | BZ6: 40.54 | CA6: 43.55 | CC6: 1.26 | CD6: 1.18 | CF6: 0.07 | CG6: 0.11 | CI6: 0.27 | CJ6: 0.22 | CM6: 0.6
A7: 2020_00057 | B7: 10 | C7: 3 | D7: 3 | G7: 3 | I7: 3 | J7: 3 | L7: 2 | M7: 2 | N7: 0.9 | O7: 0.9 | P7: 0.9 | Q7: 0.9 | R7: 0.9 | S7: 0.9 | T7: 0.005 | U7: 0.005 | V7: 0.005 | W7: 5 | X7: 5 | Y7: 5 | Z7: 100 | AA7: 100 | AB7: 100 | AC7: 0.043626 | AD7: 0.03538 | AE7: 0.017029 | AF7: 0.037853 | AG7: 0.031964 | AH7: 0.013482 | AI7: 49.13 | AJ7: 42.06 | AK7: 16.76 | AN7: 0 | AQ7: 100 | AR7: 8.6e-05 | AS7: 8.4e-05 | AT7: 9.6e-05 | AU7: 0.026777 | AV7: 0.021201 | AW7: 0.009227 | AX7: 0.026864 | AY7: 0.021285 | AZ7: 0.009323 | BA7: 0.016762 | BE7: 0.014095 | BF7: 0.007707 | BH7: 0.000433 | BI7: 0.000186 | BK7: 3.5e-05 | BL7: 3.2e-05 | BN7: 8.8e-05 | BO7: 3.2e-05 | BR7: 0 | BS7: 61.58 | BT7: 60.16 | BU7: 54.75 | BV7: 38.42 | BZ7: 39.84 | CA7: 45.25 | CC7: 1.22 | CD7: 1.09 | CF7: 0.1 | CG7: 0.19 | CI7: 0.25 | CJ7: 0.19 | CM7: 0
A8: 2020_00081 | B8: 10 | C8: 3 | D8: 3 | G8: 3 | I8: 3 | J8: 3 | L8: 2 | M8: 2 | N8: 0.9 | O8: 0.9 | P8: 0.9 | Q8: 0.9 | R8: 0.9 | S8: 0.9 | T8: 0.005 | U8: 0.005 | V8: 0.005 | W8: 5 | X8: 5 | Y8: 5 | Z8: 100 | AA8: 100 | AB8: 100 | AC8: 0.107375 | AD8: 0.136101 | AE8: 0.058873 | AF8: 0.090706 | AG8: 0.118915 | AH8: 0.051402 | AI8: 119.43 | AJ8: 161.45 | AK8: 59.69 | AN8: 21 | AQ8: 79 | AR8: 8.9e-05 | AS8: 8.9e-05 | AT8: 9.6e-05 | AU8: 0.065718 | AV8: 0.08125 | AW8: 0.033477 | AX8: 0.065808 | AY8: 0.081339 | AZ8: 0.033573 | BA8: 0.041568 | BE8: 0.054761 | BF8: 0.024981 | BH8: 0.001678 | BI8: 0.000697 | BK8: 3.4e-05 | BL8: 3.3e-05 | BN8: 0.000364 | BO8: 0.000137 | BR8: 0.00032 | BS8: 61.29 | BT8: 59.76 | BU8: 57.03 | BV8: 38.71 | BZ8: 40.24 | CA8: 42.43 | CC8: 1.23 | CD8: 1.18 | CF8: 0.03 | CG8: 0.06 | CI8: 0.27 | CJ8: 0.23 | CM8: 0.54
A9: 2020_00095 | B9: 10 | C9: 3 | D9: 3 | G9: 3 | I9: 3 | J9: 3 | L9: 2 | M9: 2 | N9: 0.9 | O9: 0.9 | P9: 0.9 | Q9: 0.9 | R9: 0.9 | S9: 0.9 | T9: 0.005 | U9: 0.005 | V9: 0.005 | W9: 5 | X9: 5 | Y9: 5 | Z9: 100 | AA9: 100 | AB9: 100 | AC9: 0.103149 | AD9: 0.088257 | AE9: 0.032554 | AF9: 0.089493 | AG9: 0.081885 | AH9: 0.035357 | AI9: 125.89 | AJ9: 114.4 | AK9: 35.57 | AN9: 8 | AQ9: 92 | AR9: 9.3e-05 | AS9: 9.4e-05 | AT9: 0.000102 | AU9: 0.062891 | AV9: 0.052353 | AW9: 0.018084 | AX9: 0.062984 | AY9: 0.052447 | AZ9: 0.018187 | BA9: 0.040164 | BE9: 0.035809 | BF9: 0.014219 | BH9: 0.001189 | BI9: 0.000413 | BK9: 3.7e-05 | BL9: 3.3e-05 | BN9: 0.000254 | BO9: 7.8e-05 | BR9: 0.000149 | BS9: 61.06 | BT9: 59.43 | BU9: 55.87 | BV9: 38.94 | BZ9: 40.57 | CA9: 43.68 | CC9: 1.35 | CD9: 1.27 | CF9: 0.04 | CG9: 0.1 | CI9: 0.29 | CJ9: 0.24 | CM9: 0.46
A10: 2020_00153 | B10: 10 | C10: 3 | D10: 3 | G10: 3 | I10: 3 | J10: 3 | L10: 2 | M10: 2 | N10: 0.9 | O10: 0.9 | P10: 0.9 | Q10: 0.9 | R10: 0.9 | S10: 0.9 | T10: 0.005 | U10: 0.005 | V10: 0.005 | W10: 5 | X10: 5 | Y10: 5 | Z10: 100 | AA10: 100 | AB10: 100 | AC10: 0.102687 | AD10: 0.092861 | AE10: 0.041184 | AF10: 0.092239 | AG10: 0.082782 | AH10: 0.036159 | AI10: 116.68 | AJ10: 111.9 | AK10: 42.04 | AN10: 6 | AQ10: 94 | AR10: 9.1e-05 | AS10: 9.3e-05 | AT10: 0.000101 | AU10: 0.062645 | AV10: 0.055312 | AW10: 0.023268 | AX10: 0.062736 | AY10: 0.055406 | AZ10: 0.023369 | BA10: 0.039951 | BE10: 0.037455 | BF10: 0.01776 | BH10: 0.001155 | BI10: 0.000485 | BK10: 3.5e-05 | BL10: 3.3e-05 | BN10: 0.000249 | BO10: 9.3e-05 | BR10: 5.5e-05 | BS10: 61.09 | BT10: 59.67 | BU10: 56.74 | BV10: 38.91 | BZ10: 40.33 | CA10: 43.12 | CC10: 1.24 | CD10: 1.18 | CF10: 0.04 | CG10: 0.08 | CI10: 0.27 | CJ10: 0.23 | CM10: 0.13
A11: 2020_00155 | B11: 10 | C11: 3 | D11: 3 | G11: 3 | I11: 3 | J11: 3 | L11: 2 | M11: 2 | N11: 0.9 | O11: 0.9 | P11: 0.9 | Q11: 0.9 | R11: 0.9 | S11: 0.9 | T11: 0.005 | U11: 0.005 | V11: 0.005 | W11: 5 | X11: 5 | Y11: 5 | Z11: 100 | AA11: 100 | AB11: 100 | AC11: 0.081311 | AD11: 0.080444 | AE11: 0.037288 | AF11: 0.067532 | AG11: 0.080272 | AH11: 0.035513 | AI11: 83.12 | AJ11: 88.74 | AK11: 33.4 | AN11: 5 | AQ11: 95 | AR11: 8.7e-05 | AS11: 8.9e-05 | AT11: 9.9e-05 | AU11: 0.049999 | AV11: 0.048512 | AW11: 0.021143 | AX11: 0.050085 | AY11: 0.048601 | AZ11: 0.021242 | BA11: 0.031226 | BE11: 0.031843 | BF11: 0.015919 | BH11: 0.000905 | BI11: 0.000396 | BK11: 3.7e-05 | BL11: 3.5e-05 | BN11: 0.000198 | BO11: 7.3e-05 | BR11: 0.000127 | BS11: 61.6 | BT11: 60.42 | BU11: 56.97 | BV11: 38.4 | BZ11: 39.58 | CA11: 42.69 | CC11: 1.13 | CD11: 1.06 | CF11: 0.05 | CG11: 0.09 | CI11: 0.25 | CJ11: 0.2 | CM11: 0.34
A12: 2020_00159 | B12: 10 | C12: 3 | D12: 3 | G12: 3 | I12: 3 | J12: 3 | L12: 2 | M12: 2 | N12: 0.9 | O12: 0.9 | P12: 0.9 | Q12: 0.9 | R12: 0.9 | S12: 0.9 | T12: 0.005 | U12: 0.005 | V12: 0.005 | W12: 5 | X12: 5 | Y12: 5 | Z12: 100 | AA12: 100 | AB12: 100 | AC12: 0.079912 | AD12: 0.093267 | AE12: 0.036643 | AF12: 0.066873 | AG12: 0.092109 | AH12: 0.026274 | AI12: 97.21 | AJ12: 121.57 | AK12: 39.59 | AN12: 6 | AQ12: 94 | AR12: 9.4e-05 | AS12: 9.7e-05 | AT12: 0.000105 | AU12: 0.048625 | AV12: 0.055254 | AW12: 0.020305 | AX12: 0.048718 | AY12: 0.05535 | AZ12: 0.02041 | BA12: 0.031194 | BE12: 0.037917 | BF12: 0.015927 | BH12: 0.001245 | BI12: 0.00046 | BK12: 3.4e-05 | BL12: 3.2e-05 | BN12: 0.000272 | BO12: 8.7e-05 | BR12: 0.000305 | BS12: 60.96 | BT12: 59.35 | BU12: 55.7 | BV12: 39.03 | BZ12: 40.65 | CA12: 43.47 | CC12: 1.34 | CD12: 1.26 | CF12: 0.04 | CG12: 0.09 | CI12: 0.29 | CJ12: 0.24 | CM12: 0.83
A13: 2020_00175 | B13: 10 | C13: 3 | D13: 3 | G13: 3 | I13: 3 | J13: 3 | L13: 2 | M13: 2 | N13: 0.9 | O13: 0.9 | P13: 0.9 | Q13: 0.9 | R13: 0.9 | S13: 0.9 | T13: 0.005 | U13: 0.005 | V13: 0.005 | W13: 5 | X13: 5 | Y13: 5 | Z13: 100 | AA13: 100 | AB13: 100 | AC13: 0.050248 | AD13: 0.05475 | AE13: 0.027711 | AF13: 0.0413 | AG13: 0.052242 | AH13: 0.023962 | AI13: 65.11 | AJ13: 78.66 | AK13: 32.05 | AN13: 4 | AQ13: 96 | AR13: 0.000105 | AS13: 0.000101 | AT13: 0.000112 | AU13: 0.030345 | AV13: 0.032025 | AW13: 0.015061 | AX13: 0.03045 | AY13: 0.032126 | AZ13: 0.015173 | BA13: 0.019798 | BE13: 0.022624 | BF13: 0.012386 | BH13: 0.000807 | BI13: 0.000382 | BK13: 3.6e-05 | BL13: 3.4e-05 | BN13: 0.000172 | BO13: 7.1e-05 | BR13: 0.000152 | BS13: 60.6 | BT13: 58.68 | BU13: 54.75 | BV13: 39.4 | BZ13: 41.32 | CA13: 44.7 | CC13: 1.47 | CD13: 1.38 | CF13: 0.07 | CG13: 0.12 | CI13: 0.31 | CJ13: 0.26 | CM13: 0.55
... A102: paquita_00100 | B102: 10 | C102: 3 | D102: 3 | G102: 3 | I102: 3 | J102: 3 | L102: 2 | M102: 2 | N102: 0.9 | O102: 0.9 | P102: 0.9 | Q102: 0.9 | R102: 0.9 | S102: 0.9 | T102: 0.005 | U102: 0.005 | V102: 0.005 | W102: 5 | X102: 5 | Y102: 5 | Z102: 100 | AA102: 100 | AB102: 100 | AC102: 0.012998 | AD102: 0.005795 | AE102: 0.002863 | AF102: 0.014849 | AG102: 0.006787 | AH102: 0.002421 | AI102: 15.72 | AJ102: 7.62 | AK102: 2.61 | AN102: 0 | AQ102: 100 | AR102: 0.000118 | AS102: 0.000115 | AT102: 0.000119 | AU102: 0.007697 | AV102: 0.003242 | AW102: 0.001013 | AX102: 0.007815 | AY102: 0.003357 | AZ102: 0.001131 | BA102: 0.005183 | BE102: 0.002437 | BF102: 0.001732 | BH102: 8e-05 | BI102: 2.5e-05 | BK102: 2.8e-05 | BL102: 1e-05 | BN102: 1.8e-05 | BO102: 5e-06 | BR102: 0 | BS102: 60.12 | BT102: 57.93 | BU102: 39.52 | BV102: 39.88 | BZ102: 42.06 | CA102: 60.49 | CC102: 1.38 | CD102: 0.87 | CF102: 0.48 | CG102: 0.33 | CI102: 0.31 | CJ102: 0.17 | CM102: 0

Sheet Run_4
A1: puzzle_size | B1: nAnts_alg0 | C1: nAnts_alg3 | D1: nAnts_alg4 | E1: threads_alg0 | F1: threads_alg3 | G1: threads_alg4 | H1: numcolonies_alg0 | I1: numcolonies_alg3 | J1: numcolonies_alg4 | K1: numacs_alg0 | L1: numacs_alg3 | M1: numacs_alg4 | N1: q0_alg0 | O1: q0_alg3 | P1: q0_alg4 | Q1: rho_alg0 | R1: rho_alg3 | S1: rho_alg4 | T1: bve_alg0 | U1: bve_alg3 | V1: bve_alg4 | W1: timeout_alg0 | X1: timeout_alg3 | Y1: timeout_alg4 | Z1: success_rate_alg0 | AA1: success_rate_alg3 | AB1: success_rate_alg4 | AC1: time_mean_alg0 | AD1: time_mean_alg3 | AE1: time_mean_alg4 | AF1: time_std_alg0 | AG1: time_std_alg3 | AH1: time_std_alg4 | AI1: iter_mean_alg0 | AJ1: iter_mean_alg3 | AK1: iter_mean_alg4 | AL1: with_comm_alg0 | AM1: with_comm_alg3 | AN1: with_comm_alg4 | AO1: without_comm_alg0 | AP1: without_comm_alg3 | AQ1: without_comm_alg4 | AR1: cp_initial_mean_alg0 | AS1: cp_initial_mean_alg3 | AT1: cp_initial_mean_alg4 | AU1: cp_ant_mean_alg0 | AV1: cp_ant_mean_alg3 | AW1: cp_ant_mean_alg4 | AX1: cp_total_mean_alg0 | AY1: cp_total_mean_alg3 | AZ1: cp_total_mean_alg4 | BA1: acs_time_mean_alg0 | BB1: acs_time_mean_alg3 | BC1: acs_time_mean_alg4 | BD1: dcm_aco_time_mean_alg0 | BE1: dcm_aco_time_mean_alg3 | BF1: dcm_aco_time_mean_alg4 | BG1: coop_game_mean_alg0 | BH1: coop_game_mean_alg3 | BI1: coop_game_mean_alg4 | BJ1: pheromone_fusion_mean_alg0 | BK1: pheromone_fusion_mean_alg3 | BL1: pheromone_fusion_mean_alg4 | BM1: public_path_mean_alg0 | BN1: public_path_mean_alg3 | BO1: public_path_mean_alg4 | BP1: communication_time_mean_alg0 | BQ1: communication_time_mean_alg3 | BR1: communication_time_mean_alg4 | BS1: cp_percentage_alg0 | BT1: cp_percentage_alg3 | BU1: cp_percentage_alg4 | BV1: acs_time_percentage_alg0 | BW1: acs_time_percentage_alg3 | BX1: acs_time_percentage_alg4 | BY1: dcm_aco_time_percentage_alg0 | BZ1: dcm_aco_time_percentage_alg3 | CA1: dcm_aco_time_percentage_alg4 | CB1: coop_game_percentage_alg0 | CC1: coop_game_percentage_alg3 | CD1: coop_game_percentage_alg4 | CE1: pheromone_fusion_percentage_alg0 | CF1: pheromone_fusion_percentage_alg3 | CG1: pheromone_fusion_percentage_alg4 | CH1: public_path_percentage_alg0 | CI1: public_path_percentage_alg3 | CJ1: public_path_percentage_alg4 | CK1: communication_time_percentage_alg0 | CL1: communication_time_percentage_alg3 | CM1: communication_time_percentage_alg4
A2: 2020_00004 | B2: 10 | C2: 3 | D2: 3 | G2: 3 | I2: 3 | J2: 3 | L2: 2 | M2: 2 | N2: 0.9 | O2: 0.9 | P2: 0.9 | Q2: 0.9 | R2: 0.9 | S2: 0.9 | T2: 0.005 | U2: 0.005 | V2: 0.005 | W2: 5 | X2: 5 | Y2: 5 | Z2: 100 | AA2: 100 | AB2: 100 | AC2: 0.064795 | AD2: 0.040829 | AE2: 0.020312 | AF2: 0.061278 | AG2: 0.03535 | AH2: 0.017725 | AI2: 72.86 | AJ2: 48.3 | AK2: 18.97 | AN2: 1 | AQ2: 99 | AR2: 8.3e-05 | AS2: 8.6e-05 | AT2: 9.6e-05 | AU2: 0.039694 | AV2: 0.024488 | AW2: 0.011061 | AX2: 0.039777 | AY2: 0.024575 | AZ2: 0.011157 | BA2: 0.025018 | BE2: 0.016254 | BF2: 0.009138 | BH2: 0.000496 | BI2: 0.00023 | BK2: 3.7e-05 | BL2: 3.5e-05 | BN2: 0.000101 | BO2: 3.9e-05 | BR2: 1.7e-05 | BS2: 61.39 | BT2: 60.19 | BU2: 54.93 | BV2: 38.61 | BZ2: 39.81 | CA2: 44.99 | CC2: 1.22 | CD2: 1.13 | CF2: 0.09 | CG2: 0.17 | CI2: 0.25 | CJ2: 0.19 | CM2: 0.09
A3: 2020_00021 | B3: 10 | C3: 3 | D3: 3 | G3: 3 | I3: 3 | J3: 3 | L3: 2 | M3: 2 | N3: 0.9 | O3: 0.9 | P3: 0.9 | Q3: 0.9 | R3: 0.9 | S3: 0.9 | T3: 0.005 | U3: 0.005 | V3: 0.005 | W3: 5 | X3: 5 | Y3: 5 | Z3: 100 | AA3: 100 | AB3: 100 | AC3: 0.091127 | AD3: 0.055063 | AE3: 0.020652 | AF3: 0.073509 | AG3: 0.050077 | AH3: 0.018831 | AI3: 106.11 | AJ3: 68.96 | AK3: 21.03 | AN3: 0 | AQ3: 100 | AR3: 8.1e-05 | AS3: 8.3e-05 | AT3: 9.3e-05 | AU3: 0.055705 | AV3: 0.032779 | AW3: 0.011312 | AX3: 0.055786 | AY3: 0.032861 | AZ3: 0.011405 | BA3: 0.035342 | BE3: 0.022202 | BF3: 0.009247 | BH3: 0.000695 | BI3: 0.000237 | BK3: 3.8e-05 | BL3: 3.6e-05 | BN3: 0.000133 | BO3: 3.8e-05 | BR3: 0 | BS3: 61.22 | BT3: 59.68 | BU3: 55.23 | BV3: 38.78 | BZ3: 40.32 | CA3: 44.77 | CC3: 1.26 | CD3: 1.15 | CF3: 0.07 | CG3: 0.17 | CI3: 0.24 | CJ3: 0.18 | CM3: 0
A4: 2020_00041 | B4: 10 | C4: 3 | D4: 3 | G4: 3 | I4: 3 | J4: 3 | L4: 2 | M4: 2 | N4: 0.9 | O4: 0.9 | P4: 0.9 | Q4: 0.9 | R4: 0.9 | S4: 0.9 | T4: 0.005 | U4: 0.005 | V4: 0.005 | W4: 5 | X4: 5 | Y4: 5 | Z4: 100 | AA4: 100 | AB4: 100 | AC4: 0.090281 | AD4: 0.051368 | AE4: 0.018854 | AF4: 0.088284 | AG4: 0.063957 | AH4: 0.029316 | AI4: 102.34 | AJ4: 62.63 | AK4: 18.84 | AN4: 2 | AQ4: 98 | AR4: 8.7e-05 | AS4: 8.8e-05 | AT4: 9.6e-05 | AU4: 0.055559 | AV4: 0.030787 | AW4: 0.010351 | AX4: 0.055645 | AY4: 0.030875 | AZ4: 0.010447 | BA4: 0.034636 | BE4: 0.020492 | BF4: 0.00839 | BH4: 0.000645 | BI4: 0.000215 | BK4: 3.6e-05 | BL4: 3.4e-05 | BN4: 0.000132 | BO4: 3.8e-05 | BR4: 1.6e-05 | BS4: 61.64 | BT4: 60.11 | BU4: 55.41 | BV4: 38.36 | BZ4: 39.89 | CA4: 44.5 | CC4: 1.26 | CD4: 1.14 | CF4: 0.07 | CG4: 0.18 | CI4: 0.26 | CJ4: 0.2 | CM4: 0.09
A5: 2020_00049 | B5: 10 | C5: 3 | D5: 3 | G5: 3 | I5: 3 | J5: 3 | L5: 2 | M5: 2 | N5: 0.9 | O5: 0.9 | P5: 0.9 | Q5: 0.9 | R5: 0.9 | S5: 0.9 | T5: 0.005 | U5: 0.005 | V5: 0.005 | W5: 5 | X5: 5 | Y5: 5 | Z5: 100 | AA5: 100 | AB5: 100 | AC5: 0.101823 | AD5: 0.122737 | AE5: 0.039762 | AF5: 0.104764 | AG5: 0.128576 | AH5: 0.03561 | AI5: 110.17 | AJ5: 145.63 | AK5: 39.07 | AN5: 5 | AQ5: 95 | AR5: 8.4e-05 | AS5: 8.4e-05 | AT5: 9.1e-05 | AU5: 0.062871 | AV5: 0.073774 | AW5: 0.022694 | AX5: 0.062955 | AY5: 0.073858 | AZ5: 0.022786 | BA5: 0.038868 | BE5: 0.048879 | BF5: 0.016891 | BH5: 0.001465 | BI5: 0.00045 | BK5: 3.6e-05 | BL5: 3.5e-05 | BN5: 0.000313 | BO5: 8.2e-05 | BR5: 8.4e-05 | BS5: 61.83 | BT5: 60.18 | BU5: 57.31 | BV5: 38.17 | BZ5: 39.82 | CA5: 42.48 | CC5: 1.19 | CD5: 1.13 | CF5: 0.03 | CG5: 0.09 | CI5: 0.25 | CJ5: 0.21 | CM5: 0.21
A6: 2020_00054 | B6: 10 | C6: 3 | D6: 3 | G6: 3 | I6: 3 | J6: 3 | L6: 2 | M6: 2 | N6: 0.9 | O6: 0.9 | P6: 0.9 | Q6: 0.9 | R6: 0.9 | S6: 0.9 | T6: 0.005 | U6: 0.005 | V6: 0.005 | W6: 5 | X6: 5 | Y6: 5 | Z6: 100 | AA6: 100 | AB6: 100 | AC6: 0.082713 | AD6: 0.072706 | AE6: 0.030589 | AF6: 0.059798 | AG6: 0.063793 | AH6: 0.024079 | AI6: 96.33 | AJ6: 91.01 | AK6: 31.49 | AN6: 3 | AQ6: 97 | AR6: 8.9e-05 | AS6: 8.9e-05 | AT6: 9.8e-05 | AU6: 0.050377 | AV6: 0.043123 | AW6: 0.017073 | AX6: 0.050465 | AY6: 0.043211 | AZ6: 0.017171 | BA6: 0.032248 | BE6: 0.029494 | BF6: 0.013399 | BH6: 0.000925 | BI6: 0.000361 | BK6: 3.6e-05 | BL6: 3.2e-05 | BN6: 0.000194 | BO6: 6.6e-05 | BR6: 2e-05 | BS6: 61.01 | BT6: 59.43 | BU6: 56.13 | BV6: 38.99 | BZ6: 40.57 | CA6: 43.8 | CC6: 1.27 | CD6: 1.18 | CF6: 0.05 | CG6: 0.11 | CI6: 0.27 | CJ6: 0.21 | CM6: 0.07
A7: 2020_00057 | B7: 10 | C7: 3 | D7: 3 | G7: 3 | I7: 3 | J7: 3 | L7: 2 | M7: 2 | N7: 0.9 | O7: 0.9 | P7: 0.9 | Q7: 0.9 | R7: 0.9 | S7: 0.9 | T7: 0.005 | U7: 0.005 | V7: 0.005 | W7: 5 | X7: 5 | Y7: 5 | Z7: 100 | AA7: 100 | AB7: 100 | AC7: 0.046357 | AD7: 0.033961 | AE7: 0.015123 | AF7: 0.039568 | AG7: 0.029275 | AH7: 0.013549 | AI7: 52.08 | AJ7: 40.61 | AK7: 14.06 | AN7: 0 | AQ7: 100 | AR7: 8.7e-05 | AS7: 8.8e-05 | AT7: 9.8e-05 | AU7: 0.028445 | AV7: 0.020314 | AW7: 0.008099 | AX7: 0.028532 | AY7: 0.020402 | AZ7: 0.008196 | BA7: 0.017825 | BE7: 0.013559 | BF7: 0.006927 | BH7: 0.000416 | BI7: 0.000164 | BK7: 3.7e-05 | BL7: 3.3e-05 | BN7: 8.4e-05 | BO7: 2.7e-05 | BR7: 0 | BS7: 61.55 | BT7: 60.08 | BU7: 54.2 | BV7: 38.45 | BZ7: 39.93 | CA7: 45.8 | CC7: 1.22 | CD7: 1.09 | CF7: 0.11 | CG7: 0.22 | CI7: 0.25 | CJ7: 0.18 | CM7: 0
A8: 2020_00081 | B8: 10 | C8: 3 | D8: 3 | G8: 3 | I8: 3 | J8: 3 | L8: 2 | M8: 2 | N8: 0.9 | O8: 0.9 | P8: 0.9 | Q8: 0.9 | R8: 0.9 | S8: 0.9 | T8: 0.005 | U8: 0.005 | V8: 0.005 | W8: 5 | X8: 5 | Y8: 5 | Z8: 100 | AA8: 100 | AB8: 100 | AC8: 0.132149 | AD8: 0.144594 | AE8: 0.071659 | AF8: 0.127769 | AG8: 0.179279 | AH8: 0.064203 | AI8: 148.28 | AJ8: 176.78 | AK8: 70.41 | AN8: 22 | AQ8: 78 | AR8: 8.8e-05 | AS8: 8.8e-05 | AT8: 9.8e-05 | AU8: 0.080784 | AV8: 0.086245 | AW8: 0.040936 | AX8: 0.080872 | AY8: 0.086334 | AZ8: 0.041035 | BA8: 0.051277 | BE8: 0.058261 | BF8: 0.030205 | BH8: 0.001776 | BI8: 0.000856 | BK8: 3.5e-05 | BL8: 3.2e-05 | BN8: 0.000384 | BO8: 0.00017 | BR8: 0.000419 | BS8: 61.2 | BT8: 59.71 | BU8: 57.26 | BV8: 38.8 | BZ8: 40.29 | CA8: 42.15 | CC8: 1.23 | CD8: 1.19 | CF8: 0.02 | CG8: 0.04 | CI8: 0.27 | CJ8: 0.24 | CM8: 0.59
A9: 2020_00095 | B9: 10 | C9: 3 | D9: 3 | G9: 3 | I9: 3 | J9: 3 | L9: 2 | M9: 2 | N9: 0.9 | O9: 0.9 | P9: 0.9 | Q9: 0.9 | R9: 0.9 | S9: 0.9 | T9: 0.005 | U9: 0.005 | V9: 0.005 | W9: 5 | X9: 5 | Y9: 5 | Z9: 100 | AA9: 100 | AB9: 100 | AC9: 0.087373 | AD9: 0.056939 | AE9: 0.028825 | AF9: 0.084871 | AG9: 0.041136 | AH9: 0.025433 | AI9: 105.31 | AJ9: 75.06 | AK9: 31.12 | AN9: 5 | AQ9: 95 | AR9: 9.3e-05 | AS9: 9.2e-05 | AT9: 0.000102 | AU9: 0.053281 | AV9: 0.033747 | AW9: 0.015886 | AX9: 0.053374 | AY9: 0.03384 | AZ9: 0.015989 | BA9: 0.033999 | BE9: 0.0231 | BF9: 0.012684 | BH9: 0.000757 | BI9: 0.00036 | BK9: 3.6e-05 | BL9: 3.4e-05 | BN9: 0.000158 | BO9: 6.3e-05 | BR9: 0.000152 | BS9: 61.09 | BT9: 59.43 | BU9: 55.47 | BV9: 38.91 | BZ9: 40.57 | CA9: 44 | CC9: 1.33 | CD9: 1.25 | CF9: 0.06 | CG9: 0.12 | CI9: 0.28 | CJ9: 0.22 | CM9: 0.53
A10: 2020_00153 | B10: 10 | C10: 3 | D10: 3 | G10: 3 | I10: 3 | J10: 3 | L10: 2 | M10: 2 | N10: 0.9 | O10: 0.9 | P10: 0.9 | Q10: 0.9 | R10: 0.9 | S10: 0.9 | T10: 0.005 | U10: 0.005 | V10: 0.005 | W10: 5 | X10: 5 | Y10: 5 | Z10: 100 | AA10: 100 | AB10: 100 | AC10: 0.119033 | AD10: 0.110039 | AE10: 0.045956 | AF10: 0.126406 | AG10: 0.10922 | AH10: 0.037736 | AI10: 134.24 | AJ10: 135.36 | AK10: 46.61 | AN10: 9 | AQ10: 91 | AR10: 9.1e-05 | AS10: 9.1e-05 | AT10: 0.000101 | AU10: 0.072449 | AV10: 0.065447 | AW10: 0.026003 | AX10: 0.072539 | AY10: 0.065537 | AZ10: 0.026104 | BA10: 0.046494 | BE10: 0.044502 | BF10: 0.019614 | BH10: 0.001363 | BI10: 0.000549 | BK10: 3.3e-05 | BL10: 3.1e-05 | BN10: 0.000294 | BO10: 0.000106 | BR10: 0.000238 | BS10: 60.94 | BT10: 59.56 | BU10: 56.8 | BV10: 39.06 | BZ10: 40.44 | CA10: 42.68 | CC10: 1.24 | CD10: 1.19 | CF10: 0.03 | CG10: 0.07 | CI10: 0.27 | CJ10: 0.23 | CM10: 0.52
A11: 2020_00155 | B11: 10 | C11: 3 | D11: 3 | G11: 3 | I11: 3 | J11: 3 | L11: 2 | M11: 2 | N11: 0.9 | O11: 0.9 | P11: 0.9 | Q11: 0.9 | R11: 0.9 | S11: 0.9 | T11: 0.005 | U11: 0.005 | V11: 0.005 | W11: 5 | X11: 5 | Y11: 5 | Z11: 100 | AA11: 100 | AB11: 100 | AC11: 0.108943 | AD11: 0.082694 | AE11: 0.042261 | AF11: 0.090559 | AG11: 0.070007 | AH11: 0.038533 | AI11: 110.58 | AJ11: 90.73 | AK11: 38.84 | AN11: 8 | AQ11: 92 | AR11: 8.7e-05 | AS11: 8.7e-05 | AT11: 9.6e-05 | AU11: 0.067026 | AV11: 0.049901 | AW11: 0.024211 | AX11: 0.067114 | AY11: 0.049987 | AZ11: 0.024307 | BA11: 0.041829 | BE11: 0.032707 | BF11: 0.017857 | BH11: 0.000932 | BI11: 0.000454 | BK11: 3.6e-05 | BL11: 3.3e-05 | BN11: 0.000201 | BO11: 8.6e-05 | BR11: 9.6e-05 | BS11: 61.6 | BT11: 60.45 | BU11: 57.52 | BV11: 38.4 | BZ11: 39.55 | CA11: 42.25 | CC11: 1.13 | CD11: 1.08 | CF11: 0.04 | CG11: 0.08 | CI11: 0.24 | CJ11: 0.2 | CM11: 0.23
A12: 2020_00159 | B12: 10 | C12: 3 | D12: 3 | G12: 3 | I12: 3 | J12: 3 | L12: 2 | M12: 2 | N12: 0.9 | O12: 0.9 | P12: 0.9 | Q12: 0.9 | R12: 0.9 | S12: 0.9 | T12: 0.005 | U12: 0.005 | V12: 0.005 | W12: 5 | X12: 5 | Y12: 5 | Z12: 100 | AA12: 100 | AB12: 100 | AC12: 0.087514 | AD12: 0.085873 | AE12: 0.043628 | AF12: 0.075613 | AG12: 0.092297 | AH12: 0.042918 | AI12: 106.14 | AJ12: 113.91 | AK12: 47.66 | AN12: 13 | AQ12: 87 | AR12: 9.6e-05 | AS12: 9.4e-05 | AT12: 0.000103 | AU12: 0.053248 | AV12: 0.050831 | AW12: 0.024438 | AX12: 0.053345 | AY12: 0.050925 | AZ12: 0.02454 | BA12: 0.034169 | BE12: 0.034948 | BF12: 0.018806 | BH12: 0.001146 | BI12: 0.000556 | BK12: 3.6e-05 | BL12: 3.3e-05 | BN12: 0.000247 | BO12: 0.000108 | BR12: 0.000282 | BS12: 60.96 | BT12: 59.3 | BU12: 56.25 | BV12: 39.04 | BZ12: 40.7 | CA12: 43.11 | CC12: 1.33 | CD12: 1.27 | CF12: 0.04 | CG12: 0.07 | CI12: 0.29 | CJ12: 0.25 | CM12: 0.65
A13: 2020_00175 | B13: 10 | C13: 3 | D13: 3 | G13: 3 | I13: 3 | J13: 3 | L13: 2 | M13: 2 | N13: 0.9 | O13: 0.9 | P13: 0.9 | Q13: 0.9 | R13: 0.9 | S13: 0.9 | T13: 0.005 | U13: 0.005 | V13: 0.005 | W13: 5 | X13: 5 | Y13: 5 | Z13: 100 | AA13: 100 | AB13: 100 | AC13: 0.064941 | AD13: 0.052456 | AE13: 0.026065 | AF13: 0.056322 | AG13: 0.048565 | AH13: 0.023992 | AI13: 86.92 | AJ13: 74.6 | AK13: 31.06 | AN13: 4 | AQ13: 96 | AR13: 0.0001 | AS13: 0.0001 | AT13: 0.00011 | AU13: 0.039251 | AV13: 0.030683 | AW13: 0.014202 | AX13: 0.039351 | AY13: 0.030783 | AZ13: 0.014312 | BA13: 0.02559 | BE13: 0.021673 | BF13: 0.011695 | BH13: 0.000773 | BI13: 0.000358 | BK13: 3.3e-05 | BL13: 3.2e-05 | BN13: 0.000168 | BO13: 6.7e-05 | BR13: 5.8e-05 | BS13: 60.59 | BT13: 58.68 | BU13: 54.91 | BV13: 39.4 | BZ13: 41.32 | CA13: 44.87 | CC13: 1.47 | CD13: 1.38 | CF13: 0.06 | CG13: 0.12 | CI13: 0.32 | CJ13: 0.26 | CM13: 0.22
... A102: paquita_00100 | B102: 10 | C102: 3 | D102: 3 | G102: 3 | I102: 3 | J102: 3 | L102: 2 | M102: 2 | N102: 0.9 | O102: 0.9 | P102: 0.9 | Q102: 0.9 | R102: 0.9 | S102: 0.9 | T102: 0.005 | U102: 0.005 | V102: 0.005 | W102: 5 | X102: 5 | Y102: 5 | Z102: 100 | AA102: 100 | AB102: 100 | AC102: 0.006529 | AD102: 0.006365 | AE102: 0.002764 | AF102: 0.008365 | AG102: 0.007238 | AH102: 0.00188 | AI102: 8.35 | AJ102: 8.2 | AK102: 2.42 | AN102: 0 | AQ102: 100 | AR102: 0.000114 | AS102: 0.000116 | AT102: 0.000122 | AU102: 0.003817 | AV102: 0.003584 | AW102: 0.000939 | AX102: 0.003931 | AY102: 0.0037 | AZ102: 0.00106 | BA102: 0.002598 | BE102: 0.002666 | BF102: 0.001703 | BH102: 9e-05 | BI102: 2.2e-05 | BK102: 2.7e-05 | BL102: 1.1e-05 | BN102: 1.9e-05 | BO102: 4e-06 | BR102: 0 | BS102: 60.21 | BT102: 58.12 | BU102: 38.36 | BV102: 39.79 | BZ102: 41.88 | CA102: 61.62 | CC102: 1.41 | CD102: 0.8 | CF102: 0.42 | CG102: 0.39 | CI102: 0.3 | CJ102: 0.16 | CM102: 0

Sheet Run_5
A1: puzzle_size | B1: nAnts_alg0 | C1: nAnts_alg3 | D1: nAnts_alg4 | E1: threads_alg0 | F1: threads_alg3 | G1: threads_alg4 | H1: numcolonies_alg0 | I1: numcolonies_alg3 | J1: numcolonies_alg4 | K1: numacs_alg0 | L1: numacs_alg3 | M1: numacs_alg4 | N1: q0_alg0 | O1: q0_alg3 | P1: q0_alg4 | Q1: rho_alg0 | R1: rho_alg3 | S1: rho_alg4 | T1: bve_alg0 | U1: bve_alg3 | V1: bve_alg4 | W1: timeout_alg0 | X1: timeout_alg3 | Y1: timeout_alg4 | Z1: success_rate_alg0 | AA1: success_rate_alg3 | AB1: success_rate_alg4 | AC1: time_mean_alg0 | AD1: time_mean_alg3 | AE1: time_mean_alg4 | AF1: time_std_alg0 | AG1: time_std_alg3 | AH1: time_std_alg4 | AI1: iter_mean_alg0 | AJ1: iter_mean_alg3 | AK1: iter_mean_alg4 | AL1: with_comm_alg0 | AM1: with_comm_alg3 | AN1: with_comm_alg4 | AO1: without_comm_alg0 | AP1: without_comm_alg3 | AQ1: without_comm_alg4 | AR1: cp_initial_mean_alg0 | AS1: cp_initial_mean_alg3 | AT1: cp_initial_mean_alg4 | AU1: cp_ant_mean_alg0 | AV1: cp_ant_mean_alg3 | AW1: cp_ant_mean_alg4 | AX1: cp_total_mean_alg0 | AY1: cp_total_mean_alg3 | AZ1: cp_total_mean_alg4 | BA1: acs_time_mean_alg0 | BB1: acs_time_mean_alg3 | BC1: acs_time_mean_alg4 | BD1: dcm_aco_time_mean_alg0 | BE1: dcm_aco_time_mean_alg3 | BF1: dcm_aco_time_mean_alg4 | BG1: coop_game_mean_alg0 | BH1: coop_game_mean_alg3 | BI1: coop_game_mean_alg4 | BJ1: pheromone_fusion_mean_alg0 | BK1: pheromone_fusion_mean_alg3 | BL1: pheromone_fusion_mean_alg4 | BM1: public_path_mean_alg0 | BN1: public_path_mean_alg3 | BO1: public_path_mean_alg4 | BP1: communication_time_mean_alg0 | BQ1: communication_time_mean_alg3 | BR1: communication_time_mean_alg4 | BS1: cp_percentage_alg0 | BT1: cp_percentage_alg3 | BU1: cp_percentage_alg4 | BV1: acs_time_percentage_alg0 | BW1: acs_time_percentage_alg3 | BX1: acs_time_percentage_alg4 | BY1: dcm_aco_time_percentage_alg0 | BZ1: dcm_aco_time_percentage_alg3 | CA1: dcm_aco_time_percentage_alg4 | CB1: coop_game_percentage_alg0 | CC1: coop_game_percentage_alg3 | CD1: coop_game_percentage_alg4 | CE1: pheromone_fusion_percentage_alg0 | CF1: pheromone_fusion_percentage_alg3 | CG1: pheromone_fusion_percentage_alg4 | CH1: public_path_percentage_alg0 | CI1: public_path_percentage_alg3 | CJ1: public_path_percentage_alg4 | CK1: communication_time_percentage_alg0 | CL1: communication_time_percentage_alg3 | CM1: communication_time_percentage_alg4
A2: 2020_00004 | B2: 10 | C2: 3 | D2: 3 | G2: 3 | I2: 3 | J2: 3 | L2: 2 | M2: 2 | N2: 0.9 | O2: 0.9 | P2: 0.9 | Q2: 0.9 | R2: 0.9 | S2: 0.9 | T2: 0.005 | U2: 0.005 | V2: 0.005 | W2: 5 | X2: 5 | Y2: 5 | Z2: 99 | AA2: 100 | AB2: 100 | AC2: 0.074497 | AD2: 0.041458 | AE2: 0.017514 | AF2: 0.081101 | AG2: 0.035695 | AH2: 0.014872 | AI2: 83.57 | AJ2: 47.3 | AK2: 17.23 | AN2: 0 | AQ2: 100 | AR2: 8.1e-05 | AS2: 8.5e-05 | AT2: 9.1e-05 | AU2: 0.045655 | AV2: 0.024881 | AW2: 0.009535 | AX2: 0.045736 | AY2: 0.024966 | AZ2: 0.009626 | BA2: 0.028761 | BE2: 0.016492 | BF2: 0.007888 | BH2: 0.000514 | BI2: 0.000191 | BK2: 3.9e-05 | BL2: 3.1e-05 | BN2: 0.000106 | BO2: 3.2e-05 | BR2: 0 | BS2: 61.39 | BT2: 60.22 | BU2: 54.96 | BV2: 38.61 | BZ2: 39.78 | CA2: 45.04 | CC2: 1.24 | CD2: 1.09 | CF2: 0.09 | CG2: 0.18 | CI2: 0.26 | CJ2: 0.18 | CM2: 0
A3: 2020_00021 | B3: 10 | C3: 3 | D3: 3 | G3: 3 | I3: 3 | J3: 3 | L3: 2 | M3: 2 | N3: 0.9 | O3: 0.9 | P3: 0.9 | Q3: 0.9 | R3: 0.9 | S3: 0.9 | T3: 0.005 | U3: 0.005 | V3: 0.005 | W3: 5 | X3: 5 | Y3: 5 | Z3: 100 | AA3: 100 | AB3: 100 | AC3: 0.073748 | AD3: 0.05264 | AE3: 0.024477 | AF3: 0.059155 | AG3: 0.047688 | AH3: 0.0202 | AI3: 83.98 | AJ3: 64.72 | AK3: 24 | AN3: 2 | AQ3: 98 | AR3: 8.1e-05 | AS3: 8.1e-05 | AT3: 9.9e-05 | AU3: 0.045163 | AV3: 0.031421 | AW3: 0.013466 | AX3: 0.045243 | AY3: 0.031502 | AZ3: 0.013565 | BA3: 0.028505 | BE3: 0.021138 | BF3: 0.010812 | BH3: 0.000666 | BI3: 0.000287 | BK3: 3.5e-05 | BL3: 4e-05 | BN3: 0.00013 | BO3: 4.4e-05 | BR3: 0.0001 | BS3: 61.35 | BT3: 59.84 | BU3: 55.42 | BV3: 38.65 | BZ3: 40.16 | CA3: 44.17 | CC3: 1.27 | CD3: 1.17 | CF3: 0.07 | CG3: 0.16 | CI3: 0.25 | CJ3: 0.18 | CM3: 0.41
A4: 2020_00041 | B4: 10 | C4: 3 | D4: 3 | G4: 3 | I4: 3 | J4: 3 | L4: 2 | M4: 2 | N4: 0.9 | O4: 0.9 | P4: 0.9 | Q4: 0.9 | R4: 0.9 | S4: 0.9 | T4: 0.005 | U4: 0.005 | V4: 0.005 | W4: 5 | X4: 5 | Y4: 5 | Z4: 100 | AA4: 100 | AB4: 100 | AC4: 0.087769 | AD4: 0.049675 | AE4: 0.019155 | AF4: 0.09615 | AG4: 0.057813 | AH4: 0.024559 | AI4: 99.23 | AJ4: 60.71 | AK4: 19.29 | AN4: 1 | AQ4: 99 | AR4: 8.9e-05 | AS4: 8.7e-05 | AT4: 9.8e-05 | AU4: 0.054008 | AV4: 0.029819 | AW4: 0.010474 | AX4: 0.054097 | AY4: 0.029906 | AZ4: 0.010572 | BA4: 0.033672 | BE4: 0.019769 | BF4: 0.008509 | BH4: 0.000627 | BI4: 0.000216 | BK4: 3.7e-05 | BL4: 3.1e-05 | BN4: 0.000127 | BO4: 3.6e-05 | BR4: 7.3e-05 | BS4: 61.64 | BT4: 60.2 | BU4: 55.19 | BV4: 38.36 | BZ4: 39.8 | CA4: 44.42 | CC4: 1.26 | CD4: 1.13 | CF4: 0.07 | CG4: 0.16 | CI4: 0.25 | CJ4: 0.19 | CM4: 0.38
