Workbook

Sheet Run_1
A1: puzzle_size | B1: nAnts_alg0 | C1: nAnts_alg3 | D1: nAnts_alg4 | E1: threads_alg0 | F1: threads_alg3 | G1: threads_alg4 | H1: numcolonies_alg0 | I1: numcolonies_alg3 | J1: numcolonies_alg4 | K1: numacs_alg0 | L1: numacs_alg3 | M1: numacs_alg4 | N1: q0_alg0 | O1: q0_alg3 | P1: q0_alg4 | Q1: rho_alg0 | R1: rho_alg3 | S1: rho_alg4 | T1: bve_alg0 | U1: bve_alg3 | V1: bve_alg4 | W1: timeout_alg0 | X1: timeout_alg3 | Y1: timeout_alg4 | Z1: success_rate_alg0 | AA1: success_rate_alg3 | AB1: success_rate_alg4 | AC1: time_mean_alg0 | AD1: time_mean_alg3 | AE1: time_mean_alg4 | AF1: time_std_alg0 | AG1: time_std_alg3 | AH1: time_std_alg4 | AI1: iter_mean_alg0 | AJ1: iter_mean_alg3 | AK1: iter_mean_alg4 | AL1: with_comm_alg0 | AM1: with_comm_alg3 | AN1: with_comm_alg4 | AO1: without_comm_alg0 | AP1: without_comm_alg3 | AQ1: without_comm_alg4 | AR1: cp_initial_mean_alg0 | AS1: cp_initial_mean_alg3 | AT1: cp_initial_mean_alg4 | AU1: cp_ant_mean_alg0 | AV1: cp_ant_mean_alg3 | AW1: cp_ant_mean_alg4 | AX1: cp_total_mean_alg0 | AY1: cp_total_mean_alg3 | AZ1: cp_total_mean_alg4 | BA1: acs_time_mean_alg0 | BB1: acs_time_mean_alg3 | BC1: acs_time_mean_alg4 | BD1: dcm_aco_time_mean_alg0 | BE1: dcm_aco_time_mean_alg3 | BF1: dcm_aco_time_mean_alg4 | BG1: coop_game_mean_alg0 | BH1: coop_game_mean_alg3 | BI1: coop_game_mean_alg4 | BJ1: pheromone_fusion_mean_alg0 | BK1: pheromone_fusion_mean_alg3 | BL1: pheromone_fusion_mean_alg4 | BM1: public_path_mean_alg0 | BN1: public_path_mean_alg3 | BO1: public_path_mean_alg4 | BP1: communication_time_mean_alg0 | BQ1: communication_time_mean_alg3 | BR1: communication_time_mean_alg4 | BS1: cp_percentage_alg0 | BT1: cp_percentage_alg3 | BU1: cp_percentage_alg4 | BV1: acs_time_percentage_alg0 | BW1: acs_time_percentage_alg3 | BX1: acs_time_percentage_alg4 | BY1: dcm_aco_time_percentage_alg0 | BZ1: dcm_aco_time_percentage_alg3 | CA1: dcm_aco_time_percentage_alg4 | CB1: coop_game_percentage_alg0 | CC1: coop_game_percentage_alg3 | CD1: coop_game_percentage_alg4 | CE1: pheromone_fusion_percentage_alg0 | CF1: pheromone_fusion_percentage_alg3 | CG1: pheromone_fusion_percentage_alg4 | CH1: public_path_percentage_alg0 | CI1: public_path_percentage_alg3 | CJ1: public_path_percentage_alg4 | CK1: communication_time_percentage_alg0 | CL1: communication_time_percentage_alg3 | CM1: communication_time_percentage_alg4
A2: 2020_00004 | B2: 21 | C2: 7 | D2: 7 | G2: 3 | I2: 3 | J2: 3 | L2: 2 | M2: 2 | N2: 0.9 | O2: 0.9 | P2: 0.9 | Q2: 0.9 | R2: 0.9 | S2: 0.9 | T2: 0.005 | U2: 0.005 | V2: 0.005 | W2: 5 | X2: 5 | Y2: 5 | Z2: 100 | AA2: 100 | AB2: 100 | AC2: 0.115279 | AD2: 0.050333 | AE2: 0.024743 | AF2: 0.093308 | AG2: 0.04395 | AH2: 0.021891 | AI2: 54.67 | AJ2: 25.95 | AK2: 10.72 | AN2: 0 | AQ2: 100 | AR2: 9.3e-05 | AS2: 8.6e-05 | AT2: 9.2e-05 | AU2: 0.070387 | AV2: 0.03064 | AW2: 0.013469 | AX2: 0.070479 | AY2: 0.030726 | AZ2: 0.013561 | BA2: 0.044799 | BE2: 0.019607 | BF2: 0.011182 | BH2: 0.000271 | BI2: 0.000114 | BK2: 3.1e-05 | BL2: 3e-05 | BN2: 6.2e-05 | BO2: 2.1e-05 | BR2: 0 | BS2: 61.14 | BT2: 61.05 | BU2: 54.81 | BV2: 38.86 | BZ2: 38.95 | CA2: 45.19 | CC2: 0.54 | CD2: 0.46 | CF2: 0.06 | CG2: 0.12 | CI2: 0.12 | CJ2: 0.08 | CM2: 0
A3: 2020_00021 | B3: 21 | C3: 7 | D3: 7 | G3: 3 | I3: 3 | J3: 3 | L3: 2 | M3: 2 | N3: 0.9 | O3: 0.9 | P3: 0.9 | Q3: 0.9 | R3: 0.9 | S3: 0.9 | T3: 0.005 | U3: 0.005 | V3: 0.005 | W3: 5 | X3: 5 | Y3: 5 | Z3: 100 | AA3: 100 | AB3: 100 | AC3: 0.133174 | AD3: 0.061654 | AE3: 0.022349 | AF3: 0.099147 | AG3: 0.055004 | AH3: 0.019131 | AI3: 74.53 | AJ3: 33.39 | AK3: 9.83 | AN3: 0 | AQ3: 100 | AR3: 8.3e-05 | AS3: 8.4e-05 | AT3: 9.2e-05 | AU3: 0.080888 | AV3: 0.03727 | AW3: 0.012 | AX3: 0.080971 | AY3: 0.037354 | AZ3: 0.012091 | BA3: 0.052203 | BE3: 0.024301 | BF3: 0.010257 | BH3: 0.00035 | BI3: 0.000106 | BK3: 3e-05 | BL3: 3.2e-05 | BN3: 7.3e-05 | BO3: 1.8e-05 | BR3: 0 | BS3: 60.8 | BT3: 60.59 | BU3: 54.1 | BV3: 39.2 | BZ3: 39.41 | CA3: 45.89 | CC3: 0.57 | CD3: 0.47 | CF3: 0.05 | CG3: 0.14 | CI3: 0.12 | CJ3: 0.08 | CM3: 0
A4: 2020_00041 | B4: 21 | C4: 7 | D4: 7 | G4: 3 | I4: 3 | J4: 3 | L4: 2 | M4: 2 | N4: 0.9 | O4: 0.9 | P4: 0.9 | Q4: 0.9 | R4: 0.9 | S4: 0.9 | T4: 0.005 | U4: 0.005 | V4: 0.005 | W4: 5 | X4: 5 | Y4: 5 | Z4: 100 | AA4: 100 | AB4: 100 | AC4: 0.177689 | AD4: 0.067558 | AE4: 0.022053 | AF4: 0.151104 | AG4: 0.074707 | AH4: 0.027242 | AI4: 99.6 | AJ4: 36.83 | AK4: 9.9 | AN4: 0 | AQ4: 100 | AR4: 8.8e-05 | AS4: 8.8e-05 | AT4: 9.5e-05 | AU4: 0.108571 | AV4: 0.041152 | AW4: 0.012022 | AX4: 0.10866 | AY4: 0.04124 | AZ4: 0.012117 | BA4: 0.06903 | BE4: 0.026318 | BF4: 0.009935 | BH4: 0.000369 | BI4: 0.000104 | BK4: 2.8e-05 | BL4: 2.6e-05 | BN4: 8.2e-05 | BO4: 1.9e-05 | BR4: 0 | BS4: 61.15 | BT4: 61.04 | BU4: 54.95 | BV4: 38.85 | BZ4: 38.96 | CA4: 45.05 | CC4: 0.55 | CD4: 0.47 | CF4: 0.04 | CG4: 0.12 | CI4: 0.12 | CJ4: 0.09 | CM4: 0
A5: 2020_00049 | B5: 21 | C5: 7 | D5: 7 | G5: 3 | I5: 3 | J5: 3 | L5: 2 | M5: 2 | N5: 0.9 | O5: 0.9 | P5: 0.9 | Q5: 0.9 | R5: 0.9 | S5: 0.9 | T5: 0.005 | U5: 0.005 | V5: 0.005 | W5: 5 | X5: 5 | Y5: 5 | Z5: 100 | AA5: 100 | AB5: 100 | AC5: 0.167569 | AD5: 0.118923 | AE5: 0.044287 | AF5: 0.152688 | AG5: 0.116653 | AH5: 0.036972 | AI5: 87.62 | AJ5: 62.1 | AK5: 18.96 | AN5: 0 | AQ5: 100 | AR5: 8.4e-05 | AS5: 8.6e-05 | AT5: 9.4e-05 | AU5: 0.102837 | AV5: 0.072604 | AW5: 0.025202 | AX5: 0.102921 | AY5: 0.072689 | AZ5: 0.025296 | BA5: 0.064648 | BE5: 0.046233 | BF5: 0.018991 | BH5: 0.000616 | BI5: 0.000212 | BK5: 2.9e-05 | BL5: 3.2e-05 | BN5: 0.000138 | BO5: 4e-05 | BR5: 0 | BS5: 61.42 | BT5: 61.12 | BU5: 57.12 | BV5: 38.58 | BZ5: 38.88 | CA5: 42.88 | CC5: 0.52 | CD5: 0.48 | CF5: 0.02 | CG5: 0.07 | CI5: 0.12 | CJ5: 0.09 | CM5: 0
A6: 2020_00054 | B6: 21 | C6: 7 | D6: 7 | G6: 3 | I6: 3 | J6: 3 | L6: 2 | M6: 2 | N6: 0.9 | O6: 0.9 | P6: 0.9 | Q6: 0.9 | R6: 0.9 | S6: 0.9 | T6: 0.005 | U6: 0.005 | V6: 0.005 | W6: 5 | X6: 5 | Y6: 5 | Z6: 100 | AA6: 100 | AB6: 100 | AC6: 0.13477 | AD6: 0.076403 | AE6: 0.036782 | AF6: 0.122069 | AG6: 0.069442 | AH6: 0.027485 | AI6: 75.06 | AJ6: 41.58 | AK6: 16.63 | AN6: 0 | AQ6: 100 | AR6: 8.9e-05 | AS6: 9.2e-05 | AT6: 9.9e-05 | AU6: 0.081606 | AV6: 0.04604 | AW6: 0.020617 | AX6: 0.081695 | AY6: 0.046133 | AZ6: 0.020716 | BA6: 0.053075 | BE6: 0.03027 | BF6: 0.016066 | BH6: 0.000418 | BI6: 0.000186 | BK6: 3e-05 | BL6: 3.2e-05 | BN6: 9.6e-05 | BO6: 3.4e-05 | BR6: 0 | BS6: 60.62 | BT6: 60.38 | BU6: 56.32 | BV6: 39.38 | BZ6: 39.62 | CA6: 43.68 | CC6: 0.55 | CD6: 0.51 | CF6: 0.04 | CG6: 0.09 | CI6: 0.13 | CJ6: 0.09 | CM6: 0
A7: 2020_00057 | B7: 21 | C7: 7 | D7: 7 | G7: 3 | I7: 3 | J7: 3 | L7: 2 | M7: 2 | N7: 0.9 | O7: 0.9 | P7: 0.9 | Q7: 0.9 | R7: 0.9 | S7: 0.9 | T7: 0.005 | U7: 0.005 | V7: 0.005 | W7: 5 | X7: 5 | Y7: 5 | Z7: 100 | AA7: 100 | AB7: 100 | AC7: 0.07356 | AD7: 0.043114 | AE7: 0.017396 | AF7: 0.061772 | AG7: 0.038413 | AH7: 0.016002 | AI7: 40.62 | AJ7: 22.56 | AK7: 7.48 | AN7: 0 | AQ7: 100 | AR7: 8.6e-05 | AS7: 8.8e-05 | AT7: 9.3e-05 | AU7: 0.044853 | AV7: 0.026196 | AW7: 0.009167 | AX7: 0.044939 | AY7: 0.026285 | AZ7: 0.00926 | BA7: 0.028621 | BE7: 0.016829 | BF7: 0.008136 | BH7: 0.000229 | BI7: 7.6e-05 | BK7: 3e-05 | BL7: 2.8e-05 | BN7: 5.4e-05 | BO7: 1.4e-05 | BR7: 0 | BS7: 61.09 | BT7: 60.97 | BU7: 53.23 | BV7: 38.91 | BZ7: 39.03 | CA7: 46.77 | CC7: 0.53 | CD7: 0.44 | CF7: 0.07 | CG7: 0.16 | CI7: 0.13 | CJ7: 0.08 | CM7: 0
A8: 2020_00081 | B8: 21 | C8: 7 | D8: 7 | G8: 3 | I8: 3 | J8: 3 | L8: 2 | M8: 2 | N8: 0.9 | O8: 0.9 | P8: 0.9 | Q8: 0.9 | R8: 0.9 | S8: 0.9 | T8: 0.005 | U8: 0.005 | V8: 0.005 | W8: 5 | X8: 5 | Y8: 5 | Z8: 100 | AA8: 100 | AB8: 100 | AC8: 0.190845 | AD8: 0.165589 | AE8: 0.05538 | AF8: 0.214481 | AG8: 0.1632 | AH8: 0.043847 | AI8: 104.74 | AJ8: 83.31 | AK8: 23.55 | AN8: 1 | AQ8: 99 | AR8: 8.8e-05 | AS8: 9.5e-05 | AT8: 9.9e-05 | AU8: 0.115423 | AV8: 0.10015 | AW8: 0.031638 | AX8: 0.115511 | AY8: 0.100245 | AZ8: 0.031737 | BA8: 0.075333 | BE8: 0.065344 | BF8: 0.023529 | BH8: 0.000904 | BI8: 0.000283 | BK8: 3.2e-05 | BL8: 3.4e-05 | BN8: 0.000223 | BO8: 5.8e-05 | BR8: 0.000114 | BS8: 60.53 | BT8: 60.54 | BU8: 57.31 | BV8: 39.47 | BZ8: 39.46 | CA8: 42.49 | CC8: 0.55 | CD8: 0.51 | CF8: 0.02 | CG8: 0.06 | CI8: 0.13 | CJ8: 0.1 | CM8: 0.21
A9: 2020_00095 | B9: 21 | C9: 7 | D9: 7 | G9: 3 | I9: 3 | J9: 3 | L9: 2 | M9: 2 | N9: 0.9 | O9: 0.9 | P9: 0.9 | Q9: 0.9 | R9: 0.9 | S9: 0.9 | T9: 0.005 | U9: 0.005 | V9: 0.005 | W9: 5 | X9: 5 | Y9: 5 | Z9: 100 | AA9: 100 | AB9: 100 | AC9: 0.13525 | AD9: 0.067391 | AE9: 0.037671 | AF9: 0.100571 | AG9: 0.061283 | AH9: 0.038892 | AI9: 80.8 | AJ9: 38.68 | AK9: 18.21 | AN9: 1 | AQ9: 99 | AR9: 9.1e-05 | AS9: 9.4e-05 | AT9: 0.000102 | AU9: 0.081747 | AV9: 0.040608 | AW9: 0.021143 | AX9: 0.081839 | AY9: 0.040702 | AZ9: 0.021244 | BA9: 0.053411 | BE9: 0.026689 | BF9: 0.016426 | BH9: 0.000391 | BI9: 0.000203 | BK9: 2.9e-05 | BL9: 3e-05 | BN9: 8.9e-05 | BO9: 3.8e-05 | BR9: 0 | BS9: 60.51 | BT9: 60.4 | BU9: 56.4 | BV9: 39.49 | BZ9: 39.6 | CA9: 43.6 | CC9: 0.58 | CD9: 0.54 | CF9: 0.04 | CG9: 0.08 | CI9: 0.13 | CJ9: 0.1 | CM9: 0
A10: 2020_00153 | B10: 21 | C10: 7 | D10: 7 | G10: 3 | I10: 3 | J10: 3 | L10: 2 | M10: 2 | N10: 0.9 | O10: 0.9 | P10: 0.9 | Q10: 0.9 | R10: 0.9 | S10: 0.9 | T10: 0.005 | U10: 0.005 | V10: 0.005 | W10: 5 | X10: 5 | Y10: 5 | Z10: 100 | AA10: 100 | AB10: 100 | AC10: 0.149471 | AD10: 0.132412 | AE10: 0.055756 | AF10: 0.126318 | AG10: 0.107775 | AH10: 0.048288 | AI10: 82.33 | AJ10: 70.87 | AK10: 25.18 | AN10: 1 | AQ10: 99 | AR10: 9.1e-05 | AS10: 9.2e-05 | AT10: 0.0001 | AU10: 0.090462 | AV10: 0.080009 | AW10: 0.031812 | AX10: 0.090553 | AY10: 0.0801 | AZ10: 0.031913 | BA10: 0.058918 | BE10: 0.052311 | BF10: 0.023844 | BH10: 0.000715 | BI10: 0.000284 | BK10: 3e-05 | BL10: 3.1e-05 | BN10: 0.000163 | BO10: 5.6e-05 | BR10: 0 | BS10: 60.58 | BT10: 60.49 | BU10: 57.24 | BV10: 39.42 | BZ10: 39.51 | CA10: 42.76 | CC10: 0.54 | CD10: 0.51 | CF10: 0.02 | CG10: 0.06 | CI10: 0.12 | CJ10: 0.1 | CM10: 0
A11: 2020_00155 | B11: 21 | C11: 7 | D11: 7 | G11: 3 | I11: 3 | J11: 3 | L11: 2 | M11: 2 | N11: 0.9 | O11: 0.9 | P11: 0.9 | Q11: 0.9 | R11: 0.9 | S11: 0.9 | T11: 0.005 | U11: 0.005 | V11: 0.005 | W11: 5 | X11: 5 | Y11: 5 | Z11: 100 | AA11: 100 | AB11: 100 | AC11: 0.145202 | AD11: 0.111888 | AE11: 0.03752 | AF11: 0.153567 | AG11: 0.1111 | AH11: 0.029226 | AI11: 72.69 | AJ11: 52.51 | AK11: 15.2 | AN11: 0 | AQ11: 100 | AR11: 8.7e-05 | AS11: 9.1e-05 | AT11: 9.7e-05 | AU11: 0.088477 | AV11: 0.06842 | AW11: 0.021161 | AX11: 0.088564 | AY11: 0.06851 | AZ11: 0.021257 | BA11: 0.056638 | BE11: 0.043377 | BF11: 0.016262 | BH11: 0.000553 | BI11: 0.000168 | BK11: 3.3e-05 | BL11: 3.3e-05 | BN11: 0.000132 | BO11: 3.1e-05 | BR11: 0 | BS11: 60.99 | BT11: 61.23 | BU11: 56.66 | BV11: 39.01 | BZ11: 38.77 | CA11: 43.34 | CC11: 0.49 | CD11: 0.45 | CF11: 0.03 | CG11: 0.09 | CI11: 0.12 | CJ11: 0.08 | CM11: 0
A12: 2020_00159 | B12: 21 | C12: 7 | D12: 7 | G12: 3 | I12: 3 | J12: 3 | L12: 2 | M12: 2 | N12: 0.9 | O12: 0.9 | P12: 0.9 | Q12: 0.9 | R12: 0.9 | S12: 0.9 | T12: 0.005 | U12: 0.005 | V12: 0.005 | W12: 5 | X12: 5 | Y12: 5 | Z12: 100 | AA12: 100 | AB12: 100 | AC12: 0.117233 | AD12: 0.084151 | AE12: 0.037765 | AF12: 0.117016 | AG12: 0.076332 | AH12: 0.030079 | AI12: 68.81 | AJ12: 47.54 | AK12: 18.03 | AN12: 0 | AQ12: 100 | AR12: 9.6e-05 | AS12: 9.7e-05 | AT12: 0.000103 | AU12: 0.070671 | AV12: 0.05067 | AW12: 0.021093 | AX12: 0.070767 | AY12: 0.050767 | AZ12: 0.021196 | BA12: 0.046467 | BE12: 0.033383 | BF12: 0.016569 | BH12: 0.0005 | BI12: 0.000202 | BK12: 3.1e-05 | BL12: 3.2e-05 | BN12: 0.00012 | BO12: 3.8e-05 | BR12: 0 | BS12: 60.36 | BT12: 60.33 | BU12: 56.13 | BV12: 39.64 | BZ12: 39.67 | CA12: 43.87 | CC12: 0.59 | CD12: 0.53 | CF12: 0.04 | CG12: 0.09 | CI12: 0.14 | CJ12: 0.1 | CM12: 0
A13: 2020_00175 | B13: 21 | C13: 7 | D13: 7 | G13: 3 | I13: 3 | J13: 3 | L13: 2 | M13: 2 | N13: 0.9 | O13: 0.9 | P13: 0.9 | Q13: 0.9 | R13: 0.9 | S13: 0.9 | T13: 0.005 | U13: 0.005 | V13: 0.005 | W13: 5 | X13: 5 | Y13: 5 | Z13: 100 | AA13: 100 | AB13: 100 | AC13: 0.08329 | AD13: 0.061878 | AE13: 0.033463 | AF13: 0.073454 | AG13: 0.054677 | AH13: 0.024248 | AI13: 54.62 | AJ13: 39.21 | AK13: 17.02 | AN13: 0 | AQ13: 100 | AR13: 0.0001 | AS13: 0.000101 | AT13: 0.000113 | AU13: 0.049931 | AV13: 0.036896 | AW13: 0.018329 | AX13: 0.050031 | AY13: 0.036997 | AZ13: 0.018442 | BA13: 0.03326 | BE13: 0.024881 | BF13: 0.015021 | BH13: 0.000397 | BI13: 0.000197 | BK13: 3e-05 | BL13: 3.2e-05 | BN13: 9e-05 | BO13: 3.6e-05 | BR13: 0 | BS13: 60.07 | BT13: 59.79 | BU13: 55.11 | BV13: 39.93 | BZ13: 40.21 | CA13: 44.89 | CC13: 0.64 | CD13: 0.59 | CF13: 0.05 | CG13: 0.1 | CI13: 0.14 | CJ13: 0.11 | CM13: 0
... A101: 2020_00999 | B101: 21 | C101: 7 | D101: 7 | G101: 3 | I101: 3 | J101: 3 | L101: 2 | M101: 2 | N101: 0.9 | O101: 0.9 | P101: 0.9 | Q101: 0.9 | R101: 0.9 | S101: 0.9 | T101: 0.005 | U101: 0.005 | V101: 0.005 | W101: 5 | X101: 5 | Y101: 5 | Z101: 100 | AA101: 100 | AB101: 100 | AC101: 0.174938 | AD101: 0.138394 | AE101: 0.057382 | AF101: 0.148642 | AG101: 0.141986 | AH101: 0.055113 | AI101: 107.38 | AJ101: 82.94 | AK101: 27.6 | AN101: 2 | AQ101: 98 | AR101: 0.0001 | AS101: 9.9e-05 | AT101: 0.000111 | AU101: 0.104814 | AV101: 0.082562 | AW101: 0.031561 | AX101: 0.104914 | AY101: 0.082661 | AZ101: 0.031671 | BA101: 0.070024 | BE101: 0.055734 | BF101: 0.025519 | BH101: 0.000843 | BI101: 0.000322 | BK101: 3e-05 | BL101: 3.2e-05 | BN101: 0.000192 | BO101: 6.3e-05 | BR101: 0.000191 | BS101: 59.97 | BT101: 59.73 | BU101: 55.19 | BV101: 40.03 | BZ101: 40.27 | CA101: 44.47 | CC101: 0.61 | CD101: 0.56 | CF101: 0.02 | CG101: 0.06 | CI101: 0.14 | CJ101: 0.11 | CM101: 0.33

Sheet Run_2
A1: puzzle_size | B1: nAnts_alg0 | C1: nAnts_alg3 | D1: nAnts_alg4 | E1: threads_alg0 | F1: threads_alg3 | G1: threads_alg4 | H1: numcolonies_alg0 | I1: numcolonies_alg3 | J1: numcolonies_alg4 | K1: numacs_alg0 | L1: numacs_alg3 | M1: numacs_alg4 | N1: q0_alg0 | O1: q0_alg3 | P1: q0_alg4 | Q1: rho_alg0 | R1: rho_alg3 | S1: rho_alg4 | T1: bve_alg0 | U1: bve_alg3 | V1: bve_alg4 | W1: timeout_alg0 | X1: timeout_alg3 | Y1: timeout_alg4 | Z1: success_rate_alg0 | AA1: success_rate_alg3 | AB1: success_rate_alg4 | AC1: time_mean_alg0 | AD1: time_mean_alg3 | AE1: time_mean_alg4 | AF1: time_std_alg0 | AG1: time_std_alg3 | AH1: time_std_alg4 | AI1: iter_mean_alg0 | AJ1: iter_mean_alg3 | AK1: iter_mean_alg4 | AL1: with_comm_alg0 | AM1: with_comm_alg3 | AN1: with_comm_alg4 | AO1: without_comm_alg0 | AP1: without_comm_alg3 | AQ1: without_comm_alg4 | AR1: cp_initial_mean_alg0 | AS1: cp_initial_mean_alg3 | AT1: cp_initial_mean_alg4 | AU1: cp_ant_mean_alg0 | AV1: cp_ant_mean_alg3 | AW1: cp_ant_mean_alg4 | AX1: cp_total_mean_alg0 | AY1: cp_total_mean_alg3 | AZ1: cp_total_mean_alg4 | BA1: acs_time_mean_alg0 | BB1: acs_time_mean_alg3 | BC1: acs_time_mean_alg4 | BD1: dcm_aco_time_mean_alg0 | BE1: dcm_aco_time_mean_alg3 | BF1: dcm_aco_time_mean_alg4 | BG1: coop_game_mean_alg0 | BH1: coop_game_mean_alg3 | BI1: coop_game_mean_alg4 | BJ1: pheromone_fusion_mean_alg0 | BK1: pheromone_fusion_mean_alg3 | BL1: pheromone_fusion_mean_alg4 | BM1: public_path_mean_alg0 | BN1: public_path_mean_alg3 | BO1: public_path_mean_alg4 | BP1: communication_time_mean_alg0 | BQ1: communication_time_mean_alg3 | BR1: communication_time_mean_alg4 | BS1: cp_percentage_alg0 | BT1: cp_percentage_alg3 | BU1: cp_percentage_alg4 | BV1: acs_time_percentage_alg0 | BW1: acs_time_percentage_alg3 | BX1: acs_time_percentage_alg4 | BY1: dcm_aco_time_percentage_alg0 | BZ1: dcm_aco_time_percentage_alg3 | CA1: dcm_aco_time_percentage_alg4 | CB1: coop_game_percentage_alg0 | CC1: coop_game_percentage_alg3 | CD1: coop_game_percentage_alg4 | CE1: pheromone_fusion_percentage_alg0 | CF1: pheromone_fusion_percentage_alg3 | CG1: pheromone_fusion_percentage_alg4 | CH1: public_path_percentage_alg0 | CI1: public_path_percentage_alg3 | CJ1: public_path_percentage_alg4 | CK1: communication_time_percentage_alg0 | CL1: communication_time_percentage_alg3 | CM1: communication_time_percentage_alg4
A2: 2020_00004 | B2: 21 | C2: 7 | D2: 7 | G2: 3 | I2: 3 | J2: 3 | L2: 2 | M2: 2 | N2: 0.9 | O2: 0.9 | P2: 0.9 | Q2: 0.9 | R2: 0.9 | S2: 0.9 | T2: 0.005 | U2: 0.005 | V2: 0.005 | W2: 5 | X2: 5 | Y2: 5 | Z2: 100 | AA2: 100 | AB2: 100 | AC2: 0.085733 | AD2: 0.03901 | AE2: 0.022233 | AF2: 0.075256 | AG2: 0.03837 | AH2: 0.016925 | AI2: 45.93 | AJ2: 19.65 | AK2: 9.64 | AN2: 0 | AQ2: 100 | AR2: 8.3e-05 | AS2: 8.7e-05 | AT2: 9.4e-05 | AU2: 0.052287 | AV2: 0.023719 | AW2: 0.01203 | AX2: 0.052369 | AY2: 0.023807 | AZ2: 0.012124 | BA2: 0.033364 | BE2: 0.015203 | BF2: 0.01011 | BH2: 0.000207 | BI2: 0.000101 | BK2: 3e-05 | BL2: 2.9e-05 | BN2: 4.8e-05 | BO2: 1.7e-05 | BR2: 0 | BS2: 61.08 | BT2: 61.03 | BU2: 54.53 | BV2: 38.92 | BZ2: 38.97 | CA2: 45.47 | CC2: 0.53 | CD2: 0.45 | CF2: 0.08 | CG2: 0.13 | CI2: 0.12 | CJ2: 0.08 | CM2: 0
A3: 2020_00021 | B3: 21 | C3: 7 | D3: 7 | G3: 3 | I3: 3 | J3: 3 | L3: 2 | M3: 2 | N3: 0.9 | O3: 0.9 | P3: 0.9 | Q3: 0.9 | R3: 0.9 | S3: 0.9 | T3: 0.005 | U3: 0.005 | V3: 0.005 | W3: 5 | X3: 5 | Y3: 5 | Z3: 100 | AA3: 100 | AB3: 100 | AC3: 0.134724 | AD3: 0.06649 | AE3: 0.031161 | AF3: 0.106878 | AG3: 0.062113 | AH3: 0.028674 | AI3: 74.67 | AJ3: 35.89 | AK3: 13.72 | AN3: 0 | AQ3: 100 | AR3: 8.3e-05 | AS3: 8.4e-05 | AT3: 9.5e-05 | AU3: 0.081879 | AV3: 0.040266 | AW3: 0.017207 | AX3: 0.081962 | AY3: 0.040351 | AZ3: 0.017302 | BA3: 0.052763 | BE3: 0.026139 | BF3: 0.013859 | BH3: 0.000365 | BI3: 0.000155 | BK3: 2.9e-05 | BL3: 3.1e-05 | BN3: 7.8e-05 | BO3: 2.7e-05 | BR3: 0 | BS3: 60.84 | BT3: 60.69 | BU3: 55.52 | BV3: 39.16 | BZ3: 39.31 | CA3: 44.48 | CC3: 0.55 | CD3: 0.5 | CF3: 0.04 | CG3: 0.1 | CI3: 0.12 | CJ3: 0.09 | CM3: 0
A4: 2020_00041 | B4: 21 | C4: 7 | D4: 7 | G4: 3 | I4: 3 | J4: 3 | L4: 2 | M4: 2 | N4: 0.9 | O4: 0.9 | P4: 0.9 | Q4: 0.9 | R4: 0.9 | S4: 0.9 | T4: 0.005 | U4: 0.005 | V4: 0.005 | W4: 5 | X4: 5 | Y4: 5 | Z4: 100 | AA4: 100 | AB4: 100 | AC4: 0.130177 | AD4: 0.05913 | AE4: 0.026643 | AF4: 0.155426 | AG4: 0.078274 | AH4: 0.036262 | AI4: 71.28 | AJ4: 31.71 | AK4: 11.91 | AN4: 0 | AQ4: 100 | AR4: 8.6e-05 | AS4: 8.6e-05 | AT4: 9.8e-05 | AU4: 0.079529 | AV4: 0.036009 | AW4: 0.01479 | AX4: 0.079616 | AY4: 0.036095 | AZ4: 0.014888 | BA4: 0.050561 | BE4: 0.023036 | BF4: 0.011755 | BH4: 0.000322 | BI4: 0.00013 | BK4: 2.8e-05 | BL4: 2.6e-05 | BN4: 7.3e-05 | BO4: 2.4e-05 | BR4: 0 | BS4: 61.16 | BT4: 61.04 | BU4: 55.88 | BV4: 38.84 | BZ4: 38.96 | CA4: 44.12 | CC4: 0.55 | CD4: 0.49 | CF4: 0.05 | CG4: 0.1 | CI4: 0.12 | CJ4: 0.09 | CM4: 0
A5: 2020_00049 | B5: 21 | C5: 7 | D5: 7 | G5: 3 | I5: 3 | J5: 3 | L5: 2 | M5: 2 | N5: 0.9 | O5: 0.9 | P5: 0.9 | Q5: 0.9 | R5: 0.9 | S5: 0.9 | T5: 0.005 | U5: 0.005 | V5: 0.005 | W5: 5 | X5: 5 | Y5: 5 | Z5: 100 | AA5: 100 | AB5: 100 | AC5: 0.149299 | AD5: 0.099477 | AE5: 0.045962 | AF5: 0.140971 | AG5: 0.095196 | AH5: 0.038302 | AI5: 76.2 | AJ5: 50.7 | AK5: 19.79 | AN5: 0 | AQ5: 100 | AR5: 8.4e-05 | AS5: 8.4e-05 | AT5: 9.2e-05 | AU5: 0.091597 | AV5: 0.060856 | AW5: 0.02631 | AX5: 0.09168 | AY5: 0.06094 | AZ5: 0.026402 | BA5: 0.057618 | BE5: 0.038537 | BF5: 0.01956 | BH5: 0.000524 | BI5: 0.000224 | BK5: 2.9e-05 | BL5: 3.2e-05 | BN5: 0.000121 | BO5: 4.1e-05 | BR5: 0 | BS5: 61.41 | BT5: 61.26 | BU5: 57.44 | BV5: 38.59 | BZ5: 38.74 | CA5: 42.56 | CC5: 0.53 | CD5: 0.49 | CF5: 0.03 | CG5: 0.07 | CI5: 0.12 | CJ5: 0.09 | CM5: 0
A6: 2020_00054 | B6: 21 | C6: 7 | D6: 7 | G6: 3 | I6: 3 | J6: 3 | L6: 2 | M6: 2 | N6: 0.9 | O6: 0.9 | P6: 0.9 | Q6: 0.9 | R6: 0.9 | S6: 0.9 | T6: 0.005 | U6: 0.005 | V6: 0.005 | W6: 5 | X6: 5 | Y6: 5 | Z6: 100 | AA6: 100 | AB6: 100 | AC6: 0.124304 | AD6: 0.074582 | AE6: 0.038816 | AF6: 0.114443 | AG6: 0.071219 | AH6: 0.031875 | AI6: 68.24 | AJ6: 40.06 | AK6: 17.72 | AN6: 0 | AQ6: 100 | AR6: 9.1e-05 | AS6: 9.1e-05 | AT6: 9.7e-05 | AU6: 0.075099 | AV6: 0.044931 | AW6: 0.021786 | AX6: 0.07519 | AY6: 0.045022 | AZ6: 0.021883 | BA6: 0.049115 | BE6: 0.02956 | BF6: 0.016932 | BH6: 0.000412 | BI6: 0.000197 | BK6: 2.9e-05 | BL6: 3.2e-05 | BN6: 9.3e-05 | BO6: 3.7e-05 | BR6: 0 | BS6: 60.49 | BT6: 60.37 | BU6: 56.38 | BV6: 39.51 | BZ6: 39.63 | CA6: 43.62 | CC6: 0.55 | CD6: 0.51 | CF6: 0.04 | CG6: 0.08 | CI6: 0.12 | CJ6: 0.09 | CM6: 0
A7: 2020_00057 | B7: 21 | C7: 7 | D7: 7 | G7: 3 | I7: 3 | J7: 3 | L7: 2 | M7: 2 | N7: 0.9 | O7: 0.9 | P7: 0.9 | Q7: 0.9 | R7: 0.9 | S7: 0.9 | T7: 0.005 | U7: 0.005 | V7: 0.005 | W7: 5 | X7: 5 | Y7: 5 | Z7: 100 | AA7: 100 | AB7: 100 | AC7: 0.078666 | AD7: 0.040693 | AE7: 0.016887 | AF7: 0.062259 | AG7: 0.030562 | AH7: 0.013096 | AI7: 42.42 | AJ7: 20.99 | AK7: 6.87 | AN7: 0 | AQ7: 100 | AR7: 9e-05 | AS7: 8.7e-05 | AT7: 0.000102 | AU7: 0.047982 | AV7: 0.024729 | AW7: 0.008741 | AX7: 0.048073 | AY7: 0.024816 | AZ7: 0.008842 | BA7: 0.030593 | BE7: 0.015877 | BF7: 0.008044 | BH7: 0.000216 | BI7: 7.3e-05 | BK7: 2.9e-05 | BL7: 3.3e-05 | BN7: 5e-05 | BO7: 1.3e-05 | BR7: 0 | BS7: 61.11 | BT7: 60.98 | BU7: 52.36 | BV7: 38.89 | BZ7: 39.02 | CA7: 47.64 | CC7: 0.53 | CD7: 0.43 | CF7: 0.07 | CG7: 0.19 | CI7: 0.12 | CJ7: 0.08 | CM7: 0
A8: 2020_00081 | B8: 21 | C8: 7 | D8: 7 | G8: 3 | I8: 3 | J8: 3 | L8: 2 | M8: 2 | N8: 0.9 | O8: 0.9 | P8: 0.9 | Q8: 0.9 | R8: 0.9 | S8: 0.9 | T8: 0.005 | U8: 0.005 | V8: 0.005 | W8: 5 | X8: 5 | Y8: 5 | Z8: 100 | AA8: 100 | AB8: 100 | AC8: 0.162626 | AD8: 0.139319 | AE8: 0.062198 | AF8: 0.144476 | AG8: 0.123929 | AH8: 0.056056 | AI8: 87.08 | AJ8: 73.43 | AK8: 27.9 | AN8: 3 | AQ8: 97 | AR8: 9e-05 | AS8: 8.8e-05 | AT8: 9.6e-05 | AU8: 0.098709 | AV8: 0.084272 | AW8: 0.035704 | AX8: 0.098799 | AY8: 0.08436 | AZ8: 0.0358 | BA8: 0.063827 | BE8: 0.054959 | BF8: 0.026378 | BH8: 0.000743 | BI8: 0.000315 | BK8: 3e-05 | BL8: 3.2e-05 | BN8: 0.00017 | BO8: 6.2e-05 | BR8: 2e-05 | BS8: 60.75 | BT8: 60.55 | BU8: 57.56 | BV8: 39.25 | BZ8: 39.45 | CA8: 42.41 | CC8: 0.53 | CD8: 0.51 | CF8: 0.02 | CG8: 0.05 | CI8: 0.12 | CJ8: 0.1 | CM8: 0.03
A9: 2020_00095 | B9: 21 | C9: 7 | D9: 7 | G9: 3 | I9: 3 | J9: 3 | L9: 2 | M9: 2 | N9: 0.9 | O9: 0.9 | P9: 0.9 | Q9: 0.9 | R9: 0.9 | S9: 0.9 | T9: 0.005 | U9: 0.005 | V9: 0.005 | W9: 5 | X9: 5 | Y9: 5 | Z9: 100 | AA9: 100 | AB9: 100 | AC9: 0.124226 | AD9: 0.076712 | AE9: 0.039026 | AF9: 0.088899 | AG9: 0.074274 | AH9: 0.036071 | AI9: 73.12 | AJ9: 43.93 | AK9: 18.36 | AN9: 0 | AQ9: 100 | AR9: 9.2e-05 | AS9: 9.3e-05 | AT9: 0.000105 | AU9: 0.07502 | AV9: 0.046239 | AW9: 0.021916 | AX9: 0.075112 | AY9: 0.046332 | AZ9: 0.022021 | BA9: 0.049115 | BE9: 0.03038 | BF9: 0.017005 | BH9: 0.000445 | BI9: 0.000212 | BK9: 3e-05 | BL9: 3.3e-05 | BN9: 0.0001 | BO9: 3.9e-05 | BR9: 0 | BS9: 60.46 | BT9: 60.4 | BU9: 56.43 | BV9: 39.54 | BZ9: 39.6 | CA9: 43.57 | CC9: 0.58 | CD9: 0.54 | CF9: 0.04 | CG9: 0.08 | CI9: 0.13 | CJ9: 0.1 | CM9: 0
A10: 2020_00153 | B10: 21 | C10: 7 | D10: 7 | G10: 3 | I10: 3 | J10: 3 | L10: 2 | M10: 2 | N10: 0.9 | O10: 0.9 | P10: 0.9 | Q10: 0.9 | R10: 0.9 | S10: 0.9 | T10: 0.005 | U10: 0.005 | V10: 0.005 | W10: 5 | X10: 5 | Y10: 5 | Z10: 100 | AA10: 100 | AB10: 100 | AC10: 0.182896 | AD10: 0.126117 | AE10: 0.044725 | AF10: 0.170448 | AG10: 0.121877 | AH10: 0.032276 | AI10: 99.49 | AJ10: 67.26 | AK10: 20.07 | AN10: 0 | AQ10: 100 | AR10: 9.2e-05 | AS10: 9.3e-05 | AT10: 9.9e-05 | AU10: 0.110766 | AV10: 0.076154 | AW10: 0.025358 | AX10: 0.110858 | AY10: 0.076247 | AZ10: 0.025458 | BA10: 0.072038 | BE10: 0.04987 | BF10: 0.019268 | BH10: 0.000683 | BI10: 0.000226 | BK10: 2.8e-05 | BL10: 3.1e-05 | BN10: 0.000156 | BO10: 4.2e-05 | BR10: 0 | BS10: 60.61 | BT10: 60.46 | BU10: 56.92 | BV10: 39.39 | BZ10: 39.54 | CA10: 43.08 | CC10: 0.54 | CD10: 0.5 | CF10: 0.02 | CG10: 0.07 | CI10: 0.12 | CJ10: 0.09 | CM10: 0
A11: 2020_00155 | B11: 21 | C11: 7 | D11: 7 | G11: 3 | I11: 3 | J11: 3 | L11: 2 | M11: 2 | N11: 0.9 | O11: 0.9 | P11: 0.9 | Q11: 0.9 | R11: 0.9 | S11: 0.9 | T11: 0.005 | U11: 0.005 | V11: 0.005 | W11: 5 | X11: 5 | Y11: 5 | Z11: 100 | AA11: 100 | AB11: 100 | AC11: 0.16303 | AD11: 0.093459 | AE11: 0.039023 | AF11: 0.153 | AG11: 0.085238 | AH11: 0.039011 | AI11: 80.59 | AJ11: 45.05 | AK11: 15.29 | AN11: 0 | AQ11: 100 | AR11: 8.8e-05 | AS11: 8.7e-05 | AT11: 9.8e-05 | AU11: 0.099603 | AV11: 0.057168 | AW11: 0.02204 | AX11: 0.099691 | AY11: 0.057255 | AZ11: 0.022138 | BA11: 0.063339 | BE11: 0.036204 | BF11: 0.016885 | BH11: 0.00046 | BI11: 0.000175 | BK11: 3e-05 | BL11: 3.3e-05 | BN11: 0.000105 | BO11: 3.4e-05 | BR11: 0 | BS11: 61.15 | BT11: 61.26 | BU11: 56.73 | BV11: 38.85 | BZ11: 38.74 | CA11: 43.27 | CC11: 0.49 | CD11: 0.45 | CF11: 0.03 | CG11: 0.08 | CI11: 0.11 | CJ11: 0.09 | CM11: 0
A12: 2020_00159 | B12: 21 | C12: 7 | D12: 7 | G12: 3 | I12: 3 | J12: 3 | L12: 2 | M12: 2 | N12: 0.9 | O12: 0.9 | P12: 0.9 | Q12: 0.9 | R12: 0.9 | S12: 0.9 | T12: 0.005 | U12: 0.005 | V12: 0.005 | W12: 5 | X12: 5 | Y12: 5 | Z12: 100 | AA12: 100 | AB12: 100 | AC12: 0.129278 | AD12: 0.098696 | AE12: 0.038854 | AF12: 0.092568 | AG12: 0.076918 | AH12: 0.029845 | AI12: 75.96 | AJ12: 55.83 | AK12: 18.72 | AN12: 0 | AQ12: 100 | AR12: 9.4e-05 | AS12: 9.6e-05 | AT12: 0.000105 | AU12: 0.078028 | AV12: 0.059477 | AW12: 0.021745 | AX12: 0.078122 | AY12: 0.059573 | AZ12: 0.02185 | BA12: 0.051156 | BE12: 0.039123 | BF12: 0.017004 | BH12: 0.000583 | BI12: 0.000209 | BK12: 3e-05 | BL12: 3.1e-05 | BN12: 0.000138 | BO12: 3.9e-05 | BR12: 0 | BS12: 60.43 | BT12: 60.36 | BU12: 56.24 | BV12: 39.57 | BZ12: 39.64 | CA12: 43.76 | CC12: 0.59 | CD12: 0.54 | CF12: 0.03 | CG12: 0.08 | CI12: 0.14 | CJ12: 0.1 | CM12: 0
A13: 2020_00175 | B13: 21 | C13: 7 | D13: 7 | G13: 3 | I13: 3 | J13: 3 | L13: 2 | M13: 2 | N13: 0.9 | O13: 0.9 | P13: 0.9 | Q13: 0.9 | R13: 0.9 | S13: 0.9 | T13: 0.005 | U13: 0.005 | V13: 0.005 | W13: 5 | X13: 5 | Y13: 5 | Z13: 100 | AA13: 100 | AB13: 100 | AC13: 0.08107 | AD13: 0.069636 | AE13: 0.029864 | AF13: 0.078168 | AG13: 0.05834 | AH13: 0.021785 | AI13: 52.66 | AJ13: 43.33 | AK13: 15.76 | AN13: 0 | AQ13: 100 | AR13: 0.000102 | AS13: 0.000103 | AT13: 0.00011 | AU13: 0.048523 | AV13: 0.041555 | AW13: 0.016379 | AX13: 0.048625 | AY13: 0.041658 | AZ13: 0.016489 | BA13: 0.032445 | BE13: 0.027978 | BF13: 0.013375 | BH13: 0.000451 | BI13: 0.000173 | BK13: 3e-05 | BL13: 3.1e-05 | BN13: 0.000104 | BO13: 3.1e-05 | BR13: 0 | BS13: 59.98 | BT13: 59.82 | BU13: 55.22 | BV13: 40.02 | BZ13: 40.18 | CA13: 44.79 | CC13: 0.65 | CD13: 0.58 | CF13: 0.04 | CG13: 0.11 | CI13: 0.15 | CJ13: 0.1 | CM13: 0
... A101: 2020_00999 | B101: 21 | C101: 7 | D101: 7 | G101: 3 | I101: 3 | J101: 3 | L101: 2 | M101: 2 | N101: 0.9 | O101: 0.9 | P101: 0.9 | Q101: 0.9 | R101: 0.9 | S101: 0.9 | T101: 0.005 | U101: 0.005 | V101: 0.005 | W101: 5 | X101: 5 | Y101: 5 | Z101: 100 | AA101: 100 | AB101: 100 | AC101: 0.243393 | AD101: 0.128282 | AE101: 0.045448 | AF101: 0.272905 | AG101: 0.130441 | AH101: 0.052268 | AI101: 127.56 | AJ101: 67.01 | AK101: 22.67 | AN101: 2 | AQ101: 98 | AR101: 0.000116 | AS101: 0.000113 | AT101: 0.000109 | AU101: 0.147272 | AV101: 0.076855 | AW101: 0.025407 | AX101: 0.147388 | AY101: 0.076969 | AZ101: 0.025516 | BA101: 0.096005 | BE101: 0.051314 | BF101: 0.019932 | BH101: 0.000791 | BI101: 0.000272 | BK101: 3.4e-05 | BL101: 2.9e-05 | BN101: 0.000184 | BO101: 5.1e-05 | BR101: 0 | BS101: 60.56 | BT101: 60 | BU101: 56.14 | BV101: 39.44 | BZ101: 40 | CA101: 43.86 | CC101: 0.62 | CD101: 0.6 | CF101: 0.03 | CG101: 0.06 | CI101: 0.14 | CJ101: 0.11 | CM101: 0

Sheet Run_3
A1: puzzle_size | B1: nAnts_alg0 | C1: nAnts_alg3 | D1: nAnts_alg4 | E1: threads_alg0 | F1: threads_alg3 | G1: threads_alg4 | H1: numcolonies_alg0 | I1: numcolonies_alg3 | J1: numcolonies_alg4 | K1: numacs_alg0 | L1: numacs_alg3 | M1: numacs_alg4 | N1: q0_alg0 | O1: q0_alg3 | P1: q0_alg4 | Q1: rho_alg0 | R1: rho_alg3 | S1: rho_alg4 | T1: bve_alg0 | U1: bve_alg3 | V1: bve_alg4 | W1: timeout_alg0 | X1: timeout_alg3 | Y1: timeout_alg4 | Z1: success_rate_alg0 | AA1: success_rate_alg3 | AB1: success_rate_alg4 | AC1: time_mean_alg0 | AD1: time_mean_alg3 | AE1: time_mean_alg4 | AF1: time_std_alg0 | AG1: time_std_alg3 | AH1: time_std_alg4 | AI1: iter_mean_alg0 | AJ1: iter_mean_alg3 | AK1: iter_mean_alg4 | AL1: with_comm_alg0 | AM1: with_comm_alg3 | AN1: with_comm_alg4 | AO1: without_comm_alg0 | AP1: without_comm_alg3 | AQ1: without_comm_alg4 | AR1: cp_initial_mean_alg0 | AS1: cp_initial_mean_alg3 | AT1: cp_initial_mean_alg4 | AU1: cp_ant_mean_alg0 | AV1: cp_ant_mean_alg3 | AW1: cp_ant_mean_alg4 | AX1: cp_total_mean_alg0 | AY1: cp_total_mean_alg3 | AZ1: cp_total_mean_alg4 | BA1: acs_time_mean_alg0 | BB1: acs_time_mean_alg3 | BC1: acs_time_mean_alg4 | BD1: dcm_aco_time_mean_alg0 | BE1: dcm_aco_time_mean_alg3 | BF1: dcm_aco_time_mean_alg4 | BG1: coop_game_mean_alg0 | BH1: coop_game_mean_alg3 | BI1: coop_game_mean_alg4 | BJ1: pheromone_fusion_mean_alg0 | BK1: pheromone_fusion_mean_alg3 | BL1: pheromone_fusion_mean_alg4 | BM1: public_path_mean_alg0 | BN1: public_path_mean_alg3 | BO1: public_path_mean_alg4 | BP1: communication_time_mean_alg0 | BQ1: communication_time_mean_alg3 | BR1: communication_time_mean_alg4 | BS1: cp_percentage_alg0 | BT1: cp_percentage_alg3 | BU1: cp_percentage_alg4 | BV1: acs_time_percentage_alg0 | BW1: acs_time_percentage_alg3 | BX1: acs_time_percentage_alg4 | BY1: dcm_aco_time_percentage_alg0 | BZ1: dcm_aco_time_percentage_alg3 | CA1: dcm_aco_time_percentage_alg4 | CB1: coop_game_percentage_alg0 | CC1: coop_game_percentage_alg3 | CD1: coop_game_percentage_alg4 | CE1: pheromone_fusion_percentage_alg0 | CF1: pheromone_fusion_percentage_alg3 | CG1: pheromone_fusion_percentage_alg4 | CH1: public_path_percentage_alg0 | CI1: public_path_percentage_alg3 | CJ1: public_path_percentage_alg4 | CK1: communication_time_percentage_alg0 | CL1: communication_time_percentage_alg3 | CM1: communication_time_percentage_alg4
A2: 2020_00004 | B2: 21 | C2: 7 | D2: 7 | G2: 3 | I2: 3 | J2: 3 | L2: 2 | M2: 2 | N2: 0.9 | O2: 0.9 | P2: 0.9 | Q2: 0.9 | R2: 0.9 | S2: 0.9 | T2: 0.005 | U2: 0.005 | V2: 0.005 | W2: 5 | X2: 5 | Y2: 5 | Z2: 99 | AA2: 100 | AB2: 100 | AC2: 0.090745 | AD2: 0.04184 | AE2: 0.02029 | AF2: 0.086161 | AG2: 0.03336 | AH2: 0.015417 | AI2: 46.72 | AJ2: 21.15 | AK2: 8.7 | AN2: 0 | AQ2: 100 | AR2: 8.4e-05 | AS2: 8.5e-05 | AT2: 9.4e-05 | AU2: 0.055501 | AV2: 0.025509 | AW2: 0.010771 | AX2: 0.055586 | AY2: 0.025595 | AZ2: 0.010864 | BA2: 0.03516 | BE2: 0.016246 | BF2: 0.009426 | BH2: 0.000219 | BI2: 8.9e-05 | BK2: 3e-05 | BL2: 2.9e-05 | BN2: 4.9e-05 | BO2: 1.6e-05 | BR2: 0 | BS2: 61.25 | BT2: 61.17 | BU2: 53.54 | BV2: 38.75 | BZ2: 38.83 | CA2: 46.46 | CC2: 0.52 | CD2: 0.44 | CF2: 0.07 | CG2: 0.14 | CI2: 0.12 | CJ2: 0.08 | CM2: 0
A3: 2020_00021 | B3: 21 | C3: 7 | D3: 7 | G3: 3 | I3: 3 | J3: 3 | L3: 2 | M3: 2 | N3: 0.9 | O3: 0.9 | P3: 0.9 | Q3: 0.9 | R3: 0.9 | S3: 0.9 | T3: 0.005 | U3: 0.005 | V3: 0.005 | W3: 5 | X3: 5 | Y3: 5 | Z3: 100 | AA3: 100 | AB3: 100 | AC3: 0.150117 | AD3: 0.055553 | AE3: 0.02228 | AF3: 0.14091 | AG3: 0.053902 | AH3: 0.018159 | AI3: 82.6 | AJ3: 29.52 | AK3: 10 | AN3: 0 | AQ3: 100 | AR3: 8.2e-05 | AS3: 8.3e-05 | AT3: 9.3e-05 | AU3: 0.09124 | AV3: 0.033603 | AW3: 0.011992 | AX3: 0.091322 | AY3: 0.033686 | AZ3: 0.012085 | BA3: 0.058795 | BE3: 0.021867 | BF3: 0.010196 | BH3: 0.000302 | BI3: 0.000105 | BK3: 2.9e-05 | BL3: 3.2e-05 | BN3: 6.5e-05 | BO3: 1.8e-05 | BR3: 0 | BS3: 60.83 | BT3: 60.64 | BU3: 54.24 | BV3: 39.17 | BZ3: 39.36 | CA3: 45.76 | CC3: 0.54 | CD3: 0.47 | CF3: 0.05 | CG3: 0.15 | CI3: 0.12 | CJ3: 0.08 | CM3: 0
A4: 2020_00041 | B4: 21 | C4: 7 | D4: 7 | G4: 3 | I4: 3 | J4: 3 | L4: 2 | M4: 2 | N4: 0.9 | O4: 0.9 | P4: 0.9 | Q4: 0.9 | R4: 0.9 | S4: 0.9 | T4: 0.005 | U4: 0.005 | V4: 0.005 | W4: 5 | X4: 5 | Y4: 5 | Z4: 100 | AA4: 100 | AB4: 100 | AC4: 0.163641 | AD4: 0.065346 | AE4: 0.023016 | AF4: 0.170133 | AG4: 0.074126 | AH4: 0.023627 | AI4: 89.78 | AJ4: 34.76 | AK4: 10.18 | AN4: 0 | AQ4: 100 | AR4: 8.7e-05 | AS4: 9e-05 | AT4: 9.5e-05 | AU4: 0.0999 | AV4: 0.039848 | AW4: 0.012485 | AX4: 0.099987 | AY4: 0.039938 | AZ4: 0.01258 | BA4: 0.063654 | BE4: 0.025409 | BF4: 0.010435 | BH4: 0.000359 | BI4: 0.00011 | BK4: 2.9e-05 | BL4: 2.9e-05 | BN4: 8.1e-05 | BO4: 2e-05 | BR4: 0 | BS4: 61.1 | BT4: 61.12 | BU4: 54.66 | BV4: 38.9 | BZ4: 38.88 | CA4: 45.34 | CC4: 0.55 | CD4: 0.48 | CF4: 0.04 | CG4: 0.12 | CI4: 0.12 | CJ4: 0.09 | CM4: 0
A5: 2020_00049 | B5: 21 | C5: 7 | D5: 7 | G5: 3 | I5: 3 | J5: 3 | L5: 2 | M5: 2 | N5: 0.9 | O5: 0.9 | P5: 0.9 | Q5: 0.9 | R5: 0.9 | S5: 0.9 | T5: 0.005 | U5: 0.005 | V5: 0.005 | W5: 5 | X5: 5 | Y5: 5 | Z5: 100 | AA5: 100 | AB5: 100 | AC5: 0.144572 | AD5: 0.127649 | AE5: 0.049826 | AF5: 0.124292 | AG5: 0.117239 | AH5: 0.045774 | AI5: 75.05 | AJ5: 64.79 | AK5: 21.38 | AN5: 0 | AQ5: 100 | AR5: 8.3e-05 | AS5: 8.4e-05 | AT5: 9.2e-05 | AU5: 0.088726 | AV5: 0.078105 | AW5: 0.028555 | AX5: 0.088809 | AY5: 0.078189 | AZ5: 0.028647 | BA5: 0.055763 | BE5: 0.049459 | BF5: 0.021179 | BH5: 0.000663 | BI5: 0.000241 | BK5: 3.1e-05 | BL5: 3.4e-05 | BN5: 0.000153 | BO5: 4.8e-05 | BR5: 0 | BS5: 61.43 | BT5: 61.25 | BU5: 57.49 | BV5: 38.57 | BZ5: 38.75 | CA5: 42.51 | CC5: 0.52 | CD5: 0.48 | CF5: 0.02 | CG5: 0.07 | CI5: 0.12 | CJ5: 0.1 | CM5: 0
A6: 2020_00054 | B6: 21 | C6: 7 | D6: 7 | G6: 3 | I6: 3 | J6: 3 | L6: 2 | M6: 2 | N6: 0.9 | O6: 0.9 | P6: 0.9 | Q6: 0.9 | R6: 0.9 | S6: 0.9 | T6: 0.005 | U6: 0.005 | V6: 0.005 | W6: 5 | X6: 5 | Y6: 5 | Z6: 100 | AA6: 100 | AB6: 100 | AC6: 0.13007 | AD6: 0.068905 | AE6: 0.04144 | AF6: 0.100401 | AG6: 0.056688 | AH6: 0.026456 | AI6: 72.37 | AJ6: 37.4 | AK6: 18.25 | AN6: 0 | AQ6: 100 | AR6: 8.8e-05 | AS6: 9e-05 | AT6: 0.000101 | AU6: 0.078616 | AV6: 0.041553 | AW6: 0.023272 | AX6: 0.078703 | AY6: 0.041643 | AZ6: 0.023373 | BA6: 0.051366 | BE6: 0.027262 | BF6: 0.018067 | BH6: 0.000377 | BI6: 0.000212 | BK6: 3e-05 | BL6: 3.6e-05 | BN6: 8.6e-05 | BO6: 4e-05 | BR6: 0 | BS6: 60.51 | BT6: 60.44 | BU6: 56.4 | BV6: 39.49 | BZ6: 39.56 | CA6: 43.6 | CC6: 0.55 | CD6: 0.51 | CF6: 0.04 | CG6: 0.09 | CI6: 0.12 | CJ6: 0.1 | CM6: 0
A7: 2020_00057 | B7: 21 | C7: 7 | D7: 7 | G7: 3 | I7: 3 | J7: 3 | L7: 2 | M7: 2 | N7: 0.9 | O7: 0.9 | P7: 0.9 | Q7: 0.9 | R7: 0.9 | S7: 0.9 | T7: 0.005 | U7: 0.005 | V7: 0.005 | W7: 5 | X7: 5 | Y7: 5 | Z7: 100 | AA7: 100 | AB7: 100 | AC7: 0.073373 | AD7: 0.039153 | AE7: 0.01811 | AF7: 0.064843 | AG7: 0.030284 | AH7: 0.016665 | AI7: 40.35 | AJ7: 20.45 | AK7: 7.84 | AN7: 0 | AQ7: 100 | AR7: 8.6e-05 | AS7: 8.5e-05 | AT7: 9.4e-05 | AU7: 0.044625 | AV7: 0.023762 | AW7: 0.009518 | AX7: 0.044711 | AY7: 0.023848 | AZ7: 0.009612 | BA7: 0.028662 | BE7: 0.015306 | BF7: 0.008499 | BH7: 0.000212 | BI7: 7.9e-05 | BK7: 3e-05 | BL7: 3e-05 | BN7: 4.9e-05 | BO7: 1.5e-05 | BR7: 0 | BS7: 60.94 | BT7: 60.91 | BU7: 53.07 | BV7: 39.06 | BZ7: 39.09 | CA7: 46.93 | CC7: 0.54 | CD7: 0.44 | CF7: 0.08 | CG7: 0.16 | CI7: 0.13 | CJ7: 0.08 | CM7: 0
A8: 2020_00081 | B8: 21 | C8: 7 | D8: 7 | G8: 3 | I8: 3 | J8: 3 | L8: 2 | M8: 2 | N8: 0.9 | O8: 0.9 | P8: 0.9 | Q8: 0.9 | R8: 0.9 | S8: 0.9 | T8: 0.005 | U8: 0.005 | V8: 0.005 | W8: 5 | X8: 5 | Y8: 5 | Z8: 100 | AA8: 100 | AB8: 100 | AC8: 0.201476 | AD8: 0.159528 | AE8: 0.072364 | AF8: 0.178176 | AG8: 0.165342 | AH8: 0.059914 | AI8: 106.57 | AJ8: 83.58 | AK8: 31.4 | AN8: 3 | AQ8: 97 | AR8: 8.7e-05 | AS8: 8.9e-05 | AT8: 0.0001 | AU8: 0.122156 | AV8: 0.096256 | AW8: 0.041607 | AX8: 0.122243 | AY8: 0.096345 | AZ8: 0.041707 | BA8: 0.079232 | BE8: 0.063183 | BF8: 0.030592 | BH8: 0.000854 | BI8: 0.000371 | BK8: 2.9e-05 | BL8: 3.2e-05 | BN8: 0.000197 | BO8: 7.3e-05 | BR8: 6.5e-05 | BS8: 60.67 | BT8: 60.39 | BU8: 57.64 | BV8: 39.33 | BZ8: 39.61 | CA8: 42.28 | CC8: 0.54 | CD8: 0.51 | CF8: 0.02 | CG8: 0.04 | CI8: 0.12 | CJ8: 0.1 | CM8: 0.09
A9: 2020_00095 | B9: 21 | C9: 7 | D9: 7 | G9: 3 | I9: 3 | J9: 3 | L9: 2 | M9: 2 | N9: 0.9 | O9: 0.9 | P9: 0.9 | Q9: 0.9 | R9: 0.9 | S9: 0.9 | T9: 0.005 | U9: 0.005 | V9: 0.005 | W9: 5 | X9: 5 | Y9: 5 | Z9: 100 | AA9: 100 | AB9: 100 | AC9: 0.116321 | AD9: 0.07742 | AE9: 0.031566 | AF9: 0.099878 | AG9: 0.06892 | AH9: 0.028649 | AI9: 67.99 | AJ9: 42.96 | AK9: 14.87 | AN9: 0 | AQ9: 100 | AR9: 9.5e-05 | AS9: 9.5e-05 | AT9: 0.000103 | AU9: 0.070349 | AV9: 0.046528 | AW9: 0.017445 | AX9: 0.070444 | AY9: 0.046623 | AZ9: 0.017548 | BA9: 0.045878 | BE9: 0.030797 | BF9: 0.014018 | BH9: 0.00045 | BI9: 0.000166 | BK9: 3e-05 | BL9: 3.2e-05 | BN9: 0.000104 | BO9: 3.2e-05 | BR9: 0 | BS9: 60.56 | BT9: 60.22 | BU9: 55.59 | BV9: 39.44 | BZ9: 39.78 | CA9: 44.41 | CC9: 0.58 | CD9: 0.53 | CF9: 0.04 | CG9: 0.1 | CI9: 0.13 | CJ9: 0.1 | CM9: 0
A10: 2020_00153 | B10: 21 | C10: 7 | D10: 7 | G10: 3 | I10: 3 | J10: 3 | L10: 2 | M10: 2 | N10: 0.9 | O10: 0.9 | P10: 0.9 | Q10: 0.9 | R10: 0.9 | S10: 0.9 | T10: 0.005 | U10: 0.005 | V10: 0.005 | W10: 5 | X10: 5 | Y10: 5 | Z10: 100 | AA10: 100 | AB10: 100 | AC10: 0.162183 | AD10: 0.105418 | AE10: 0.048671 | AF10: 0.141537 | AG10: 0.095978 | AH10: 0.039211 | AI10: 86.94 | AJ10: 55.14 | AK10: 21.65 | AN10: 0 | AQ10: 100 | AR10: 9.3e-05 | AS10: 9.1e-05 | AT10: 0.0001 | AU10: 0.098116 | AV10: 0.063687 | AW10: 0.027618 | AX10: 0.098209 | AY10: 0.063778 | AZ10: 0.027718 | BA10: 0.063974 | BE10: 0.04164 | BF10: 0.020953 | BH10: 0.000568 | BI10: 0.000245 | BK10: 3.1e-05 | BL10: 3.2e-05 | BN10: 0.00013 | BO10: 4.6e-05 | BR10: 0 | BS10: 60.55 | BT10: 60.5 | BU10: 56.95 | BV10: 39.45 | BZ10: 39.5 | CA10: 43.05 | CC10: 0.54 | CD10: 0.5 | CF10: 0.03 | CG10: 0.06 | CI10: 0.12 | CJ10: 0.09 | CM10: 0
A11: 2020_00155 | B11: 21 | C11: 7 | D11: 7 | G11: 3 | I11: 3 | J11: 3 | L11: 2 | M11: 2 | N11: 0.9 | O11: 0.9 | P11: 0.9 | Q11: 0.9 | R11: 0.9 | S11: 0.9 | T11: 0.005 | U11: 0.005 | V11: 0.005 | W11: 5 | X11: 5 | Y11: 5 | Z11: 100 | AA11: 100 | AB11: 100 | AC11: 0.143327 | AD11: 0.096686 | AE11: 0.033388 | AF11: 0.125954 | AG11: 0.096871 | AH11: 0.030738 | AI11: 68.85 | AJ11: 46.57 | AK11: 13.42 | AN11: 0 | AQ11: 100 | AR11: 8.9e-05 | AS11: 8.6e-05 | AT11: 9.4e-05 | AU11: 0.087597 | AV11: 0.059092 | AW11: 0.018708 | AX11: 0.087686 | AY11: 0.059178 | AZ11: 0.018802 | BA11: 0.055641 | BE11: 0.037508 | BF11: 0.014587 | BH11: 0.000474 | BI11: 0.000145 | BK11: 3.2e-05 | BL11: 3.1e-05 | BN11: 0.000109 | BO11: 2.7e-05 | BR11: 0 | BS11: 61.18 | BT11: 61.21 | BU11: 56.31 | BV11: 38.82 | BZ11: 38.79 | CA11: 43.69 | CC11: 0.49 | CD11: 0.43 | CF11: 0.03 | CG11: 0.09 | CI11: 0.11 | CJ11: 0.08 | CM11: 0
A12: 2020_00159 | B12: 21 | C12: 7 | D12: 7 | G12: 3 | I12: 3 | J12: 3 | L12: 2 | M12: 2 | N12: 0.9 | O12: 0.9 | P12: 0.9 | Q12: 0.9 | R12: 0.9 | S12: 0.9 | T12: 0.005 | U12: 0.005 | V12: 0.005 | W12: 5 | X12: 5 | Y12: 5 | Z12: 100 | AA12: 100 | AB12: 100 | AC12: 0.12867 | AD12: 0.085395 | AE12: 0.038303 | AF12: 0.131138 | AG12: 0.069667 | AH12: 0.030602 | AI12: 75.19 | AJ12: 47.66 | AK12: 17.59 | AN12: 0 | AQ12: 100 | AR12: 9.6e-05 | AS12: 9.6e-05 | AT12: 0.000107 | AU12: 0.077708 | AV12: 0.051425 | AW12: 0.021328 | AX12: 0.077805 | AY12: 0.051522 | AZ12: 0.021435 | BA12: 0.050865 | BE12: 0.033873 | BF12: 0.016868 | BH12: 0.000499 | BI12: 0.000207 | BK12: 3.2e-05 | BL12: 3.4e-05 | BN12: 0.000116 | BO12: 3.9e-05 | BR12: 0 | BS12: 60.47 | BT12: 60.33 | BU12: 55.96 | BV12: 39.53 | BZ12: 39.67 | CA12: 44.04 | CC12: 0.58 | CD12: 0.54 | CF12: 0.04 | CG12: 0.09 | CI12: 0.14 | CJ12: 0.1 | CM12: 0
A13: 2020_00175 | B13: 21 | C13: 7 | D13: 7 | G13: 3 | I13: 3 | J13: 3 | L13: 2 | M13: 2 | N13: 0.9 | O13: 0.9 | P13: 0.9 | Q13: 0.9 | R13: 0.9 | S13: 0.9 | T13: 0.005 | U13: 0.005 | V13: 0.005 | W13: 5 | X13: 5 | Y13: 5 | Z13: 100 | AA13: 100 | AB13: 100 | AC13: 0.080936 | AD13: 0.063446 | AE13: 0.030568 | AF13: 0.071714 | AG13: 0.058395 | AH13: 0.027038 | AI13: 52.27 | AJ13: 40.21 | AK13: 16.1 | AN13: 0 | AQ13: 100 | AR13: 9.9e-05 | AS13: 0.0001 | AT13: 0.000107 | AU13: 0.048385 | AV13: 0.037778 | AW13: 0.016767 | AX13: 0.048484 | AY13: 0.037877 | AZ13: 0.016875 | BA13: 0.032451 | BE13: 0.025569 | BF13: 0.013693 | BH13: 0.000408 | BI13: 0.000178 | BK13: 3e-05 | BL13: 3.4e-05 | BN13: 9.1e-05 | BO13: 3.3e-05 | BR13: 0 | BS13: 59.9 | BT13: 59.7 | BU13: 55.2 | BV13: 40.09 | BZ13: 40.3 | CA13: 44.8 | CC13: 0.64 | CD13: 0.58 | CF13: 0.05 | CG13: 0.11 | CI13: 0.14 | CJ13: 0.11 | CM13: 0
... A101: 2020_00999 | B101: 21 | C101: 7 | D101: 7 | G101: 3 | I101: 3 | J101: 3 | L101: 2 | M101: 2 | N101: 0.9 | O101: 0.9 | P101: 0.9 | Q101: 0.9 | R101: 0.9 | S101: 0.9 | T101: 0.005 | U101: 0.005 | V101: 0.005 | W101: 5 | X101: 5 | Y101: 5 | Z101: 100 | AA101: 100 | AB101: 100 | AC101: 0.421363 | AD101: 0.25143 | AE101: 0.096901 | AF101: 0.301794 | AG101: 0.263833 | AH101: 0.096479 | AI101: 116.25 | AJ101: 68.24 | AK101: 24.94 | AN101: 2 | AQ101: 98 | AR101: 0.000216 | AS101: 0.000213 | AT101: 0.000209 | AU101: 0.255215 | AV101: 0.151098 | AW101: 0.054527 | AX101: 0.255431 | AY101: 0.151311 | AZ101: 0.054736 | BA101: 0.165932 | BE101: 0.100119 | BF101: 0.041971 | BH101: 0.001612 | BI101: 0.000588 | BK101: 6.6e-05 | BL101: 6.3e-05 | BN101: 0.00043 | BO101: 0.000118 | BR101: 0.000193 | BS101: 60.62 | BT101: 60.18 | BU101: 56.49 | BV101: 39.38 | BZ101: 39.82 | CA101: 43.31 | CC101: 0.64 | CD101: 0.61 | CF101: 0.03 | CG101: 0.07 | CI101: 0.17 | CJ101: 0.12 | CM101: 0.2

Sheet Run_4
A1: puzzle_size | B1: nAnts_alg0 | C1: nAnts_alg3 | D1: nAnts_alg4 | E1: threads_alg0 | F1: threads_alg3 | G1: threads_alg4 | H1: numcolonies_alg0 | I1: numcolonies_alg3 | J1: numcolonies_alg4 | K1: numacs_alg0 | L1: numacs_alg3 | M1: numacs_alg4 | N1: q0_alg0 | O1: q0_alg3 | P1: q0_alg4 | Q1: rho_alg0 | R1: rho_alg3 | S1: rho_alg4 | T1: bve_alg0 | U1: bve_alg3 | V1: bve_alg4 | W1: timeout_alg0 | X1: timeout_alg3 | Y1: timeout_alg4 | Z1: success_rate_alg0 | AA1: success_rate_alg3 | AB1: success_rate_alg4 | AC1: time_mean_alg0 | AD1: time_mean_alg3 | AE1: time_mean_alg4 | AF1: time_std_alg0 | AG1: time_std_alg3 | AH1: time_std_alg4 | AI1: iter_mean_alg0 | AJ1: iter_mean_alg3 | AK1: iter_mean_alg4 | AL1: with_comm_alg0 | AM1: with_comm_alg3 | AN1: with_comm_alg4 | AO1: without_comm_alg0 | AP1: without_comm_alg3 | AQ1: without_comm_alg4 | AR1: cp_initial_mean_alg0 | AS1: cp_initial_mean_alg3 | AT1: cp_initial_mean_alg4 | AU1: cp_ant_mean_alg0 | AV1: cp_ant_mean_alg3 | AW1: cp_ant_mean_alg4 | AX1: cp_total_mean_alg0 | AY1: cp_total_mean_alg3 | AZ1: cp_total_mean_alg4 | BA1: acs_time_mean_alg0 | BB1: acs_time_mean_alg3 | BC1: acs_time_mean_alg4 | BD1: dcm_aco_time_mean_alg0 | BE1: dcm_aco_time_mean_alg3 | BF1: dcm_aco_time_mean_alg4 | BG1: coop_game_mean_alg0 | BH1: coop_game_mean_alg3 | BI1: coop_game_mean_alg4 | BJ1: pheromone_fusion_mean_alg0 | BK1: pheromone_fusion_mean_alg3 | BL1: pheromone_fusion_mean_alg4 | BM1: public_path_mean_alg0 | BN1: public_path_mean_alg3 | BO1: public_path_mean_alg4 | BP1: communication_time_mean_alg0 | BQ1: communication_time_mean_alg3 | BR1: communication_time_mean_alg4 | BS1: cp_percentage_alg0 | BT1: cp_percentage_alg3 | BU1: cp_percentage_alg4 | BV1: acs_time_percentage_alg0 | BW1: acs_time_percentage_alg3 | BX1: acs_time_percentage_alg4 | BY1: dcm_aco_time_percentage_alg0 | BZ1: dcm_aco_time_percentage_alg3 | CA1: dcm_aco_time_percentage_alg4 | CB1: coop_game_percentage_alg0 | CC1: coop_game_percentage_alg3 | CD1: coop_game_percentage_alg4 | CE1: pheromone_fusion_percentage_alg0 | CF1: pheromone_fusion_percentage_alg3 | CG1: pheromone_fusion_percentage_alg4 | CH1: public_path_percentage_alg0 | CI1: public_path_percentage_alg3 | CJ1: public_path_percentage_alg4 | CK1: communication_time_percentage_alg0 | CL1: communication_time_percentage_alg3 | CM1: communication_time_percentage_alg4
A2: 2020_00004 | B2: 21 | C2: 7 | D2: 7 | G2: 3 | I2: 3 | J2: 3 | L2: 2 | M2: 2 | N2: 0.9 | O2: 0.9 | P2: 0.9 | Q2: 0.9 | R2: 0.9 | S2: 0.9 | T2: 0.005 | U2: 0.005 | V2: 0.005 | W2: 5 | X2: 5 | Y2: 5 | Z2: 100 | AA2: 100 | AB2: 100 | AC2: 0.246277 | AD2: 0.086518 | AE2: 0.047576 | AF2: 0.205952 | AG2: 0.075121 | AH2: 0.037197 | AI2: 59.75 | AJ2: 20.7 | AK2: 10.83 | AN2: 0 | AQ2: 100 | AR2: 0.000181 | AS2: 0.000181 | AT2: 0.000176 | AU2: 0.151627 | AV2: 0.052639 | AW2: 0.026013 | AX2: 0.151808 | AY2: 0.052819 | AZ2: 0.026189 | BA2: 0.094469 | BE2: 0.033699 | BF2: 0.021387 | BH2: 0.000486 | BI2: 0.000227 | BK2: 6.7e-05 | BL2: 6.5e-05 | BN2: 0.000124 | BO2: 4e-05 | BR2: 0 | BS2: 61.64 | BT2: 61.05 | BU2: 55.05 | BV2: 38.36 | BZ2: 38.95 | CA2: 44.95 | CC2: 0.56 | CD2: 0.48 | CF2: 0.08 | CG2: 0.14 | CI2: 0.14 | CJ2: 0.08 | CM2: 0
A3: 2020_00021 | B3: 21 | C3: 7 | D3: 7 | G3: 3 | I3: 3 | J3: 3 | L3: 2 | M3: 2 | N3: 0.9 | O3: 0.9 | P3: 0.9 | Q3: 0.9 | R3: 0.9 | S3: 0.9 | T3: 0.005 | U3: 0.005 | V3: 0.005 | W3: 5 | X3: 5 | Y3: 5 | Z3: 100 | AA3: 100 | AB3: 100 | AC3: 0.284553 | AD3: 0.126739 | AE3: 0.052285 | AF3: 0.265907 | AG3: 0.118411 | AH3: 0.049559 | AI3: 72.2 | AJ3: 31.42 | AK3: 12.32 | AN3: 0 | AQ3: 100 | AR3: 0.00018 | AS3: 0.000178 | AT3: 0.00017 | AU3: 0.174148 | AV3: 0.077035 | AW3: 0.028548 | AX3: 0.174328 | AY3: 0.077213 | AZ3: 0.028718 | BA3: 0.110225 | BE3: 0.049526 | BF3: 0.023567 | BH3: 0.000731 | BI3: 0.000266 | BK3: 6.9e-05 | BL3: 6.5e-05 | BN3: 0.000186 | BO3: 4.9e-05 | BR3: 0 | BS3: 61.26 | BT3: 60.92 | BU3: 54.93 | BV3: 38.74 | BZ3: 39.08 | CA3: 45.07 | CC3: 0.58 | CD3: 0.51 | CF3: 0.05 | CG3: 0.13 | CI3: 0.15 | CJ3: 0.09 | CM3: 0
A4: 2020_00041 | B4: 21 | C4: 7 | D4: 7 | G4: 3 | I4: 3 | J4: 3 | L4: 2 | M4: 2 | N4: 0.9 | O4: 0.9 | P4: 0.9 | Q4: 0.9 | R4: 0.9 | S4: 0.9 | T4: 0.005 | U4: 0.005 | V4: 0.005 | W4: 5 | X4: 5 | Y4: 5 | Z4: 100 | AA4: 100 | AB4: 100 | AC4: 0.353719 | AD4: 0.160694 | AE4: 0.043565 | AF4: 0.29934 | AG4: 0.182022 | AH4: 0.051622 | AI4: 87.6 | AJ4: 39.84 | AK4: 10.32 | AN4: 0 | AQ4: 100 | AR4: 0.000192 | AS4: 0.000186 | AT4: 0.000183 | AU4: 0.218146 | AV4: 0.098319 | AW4: 0.023811 | AX4: 0.218338 | AY4: 0.098504 | AZ4: 0.023994 | BA4: 0.135381 | BE4: 0.06219 | BF4: 0.019571 | BH4: 0.000927 | BI4: 0.000216 | BK4: 6.4e-05 | BL4: 5.3e-05 | BN4: 0.000236 | BO4: 4e-05 | BR4: 0 | BS4: 61.73 | BT4: 61.3 | BU4: 55.08 | BV4: 38.27 | BZ4: 38.7 | CA4: 44.92 | CC4: 0.58 | CD4: 0.5 | CF4: 0.04 | CG4: 0.12 | CI4: 0.15 | CJ4: 0.09 | CM4: 0
A5: 2020_00049 | B5: 21 | C5: 7 | D5: 7 | G5: 3 | I5: 3 | J5: 3 | L5: 2 | M5: 2 | N5: 0.9 | O5: 0.9 | P5: 0.9 | Q5: 0.9 | R5: 0.9 | S5: 0.9 | T5: 0.005 | U5: 0.005 | V5: 0.005 | W5: 5 | X5: 5 | Y5: 5 | Z5: 100 | AA5: 100 | AB5: 100 | AC5: 0.375144 | AD5: 0.249421 | AE5: 0.088494 | AF5: 0.347288 | AG5: 0.210853 | AH5: 0.071878 | AI5: 87.59 | AJ5: 58.09 | AK5: 19.88 | AN5: 0 | AQ5: 100 | AR5: 0.00018 | AS5: 0.000188 | AT5: 0.000176 | AU5: 0.232029 | AV5: 0.1534 | AW5: 0.051007 | AX5: 0.232209 | AY5: 0.153588 | AZ5: 0.051183 | BA5: 0.142935 | BE5: 0.095833 | BF5: 0.037311 | BH5: 0.001408 | BI5: 0.000449 | BK5: 7.2e-05 | BL5: 6.8e-05 | BN5: 0.000356 | BO5: 8.7e-05 | BR5: 0 | BS5: 61.9 | BT5: 61.58 | BU5: 57.84 | BV5: 38.1 | BZ5: 38.42 | CA5: 42.16 | CC5: 0.56 | CD5: 0.51 | CF5: 0.03 | CG5: 0.08 | CI5: 0.14 | CJ5: 0.1 | CM5: 0
A6: 2020_00054 | B6: 21 | C6: 7 | D6: 7 | G6: 3 | I6: 3 | J6: 3 | L6: 2 | M6: 2 | N6: 0.9 | O6: 0.9 | P6: 0.9 | Q6: 0.9 | R6: 0.9 | S6: 0.9 | T6: 0.005 | U6: 0.005 | V6: 0.005 | W6: 5 | X6: 5 | Y6: 5 | Z6: 100 | AA6: 100 | AB6: 100 | AC6: 0.305011 | AD6: 0.144859 | AE6: 0.070114 | AF6: 0.266188 | AG6: 0.118036 | AH6: 0.052336 | AI6: 76.2 | AJ6: 35.94 | AK6: 16.42 | AN6: 0 | AQ6: 100 | AR6: 0.0002 | AS6: 0.000196 | AT6: 0.000188 | AU6: 0.186695 | AV6: 0.087859 | AW6: 0.039233 | AX6: 0.186895 | AY6: 0.088056 | AZ6: 0.039422 | BA6: 0.118116 | BE6: 0.056803 | BF6: 0.030693 | BH6: 0.000838 | BI6: 0.000371 | BK6: 7.2e-05 | BL6: 6.4e-05 | BN6: 0.000224 | BO6: 7.1e-05 | BR6: 0 | BS6: 61.27 | BT6: 60.79 | BU6: 56.22 | BV6: 38.73 | BZ6: 39.21 | CA6: 43.78 | CC6: 0.58 | CD6: 0.53 | CF6: 0.05 | CG6: 0.09 | CI6: 0.15 | CJ6: 0.1 | CM6: 0
A7: 2020_00057 | B7: 21 | C7: 7 | D7: 7 | G7: 3 | I7: 3 | J7: 3 | L7: 2 | M7: 2 | N7: 0.9 | O7: 0.9 | P7: 0.9 | Q7: 0.9 | R7: 0.9 | S7: 0.9 | T7: 0.005 | U7: 0.005 | V7: 0.005 | W7: 5 | X7: 5 | Y7: 5 | Z7: 100 | AA7: 100 | AB7: 100 | AC7: 0.131188 | AD7: 0.091324 | AE7: 0.035048 | AF7: 0.109819 | AG7: 0.081932 | AH7: 0.03057 | AI7: 32.65 | AJ7: 22.21 | AK7: 8.19 | AN7: 0 | AQ7: 100 | AR7: 0.000183 | AS7: 0.000186 | AT7: 0.000178 | AU7: 0.08063 | AV7: 0.055741 | AW7: 0.018438 | AX7: 0.080813 | AY7: 0.055927 | AZ7: 0.018616 | BA7: 0.050375 | BE7: 0.035397 | BF7: 0.016432 | BH7: 0.000522 | BI7: 0.000161 | BK7: 6.7e-05 | BL7: 5.5e-05 | BN7: 0.000131 | BO7: 2.8e-05 | BR7: 0 | BS7: 61.6 | BT7: 61.24 | BU7: 53.12 | BV7: 38.4 | BZ7: 38.76 | CA7: 46.88 | CC7: 0.57 | CD7: 0.46 | CF7: 0.07 | CG7: 0.16 | CI7: 0.14 | CJ7: 0.08 | CM7: 0
A8: 2020_00081 | B8: 21 | C8: 7 | D8: 7 | G8: 3 | I8: 3 | J8: 3 | L8: 2 | M8: 2 | N8: 0.9 | O8: 0.9 | P8: 0.9 | Q8: 0.9 | R8: 0.9 | S8: 0.9 | T8: 0.005 | U8: 0.005 | V8: 0.005 | W8: 5 | X8: 5 | Y8: 5 | Z8: 100 | AA8: 100 | AB8: 100 | AC8: 0.458099 | AD8: 0.279979 | AE8: 0.115528 | AF8: 0.423667 | AG8: 0.270843 | AH8: 0.106161 | AI8: 109.85 | AJ8: 67.02 | AK8: 26.53 | AN8: 3 | AQ8: 97 | AR8: 0.000198 | AS8: 0.000194 | AT8: 0.000195 | AU8: 0.281712 | AV8: 0.170799 | AW8: 0.066461 | AX8: 0.28191 | AY8: 0.170993 | AZ8: 0.066657 | BA8: 0.176188 | BE8: 0.108986 | BF8: 0.048715 | BH8: 0.001607 | BI8: 0.00061 | BK8: 7.1e-05 | BL8: 6.8e-05 | BN8: 0.000428 | BO8: 0.00013 | BR8: 0.000156 | BS8: 61.54 | BT8: 61.07 | BU8: 57.7 | BV8: 38.46 | BZ8: 38.93 | CA8: 42.17 | CC8: 0.57 | CD8: 0.53 | CF8: 0.03 | CG8: 0.06 | CI8: 0.15 | CJ8: 0.11 | CM8: 0.14
A9: 2020_00095 | B9: 21 | C9: 7 | D9: 7 | G9: 3 | I9: 3 | J9: 3 | L9: 2 | M9: 2 | N9: 0.9 | O9: 0.9 | P9: 0.9 | Q9: 0.9 | R9: 0.9 | S9: 0.9 | T9: 0.005 | U9: 0.005 | V9: 0.005 | W9: 5 | X9: 5 | Y9: 5 | Z9: 100 | AA9: 100 | AB9: 100 | AC9: 0.332478 | AD9: 0.176355 | AE9: 0.067971 | AF9: 0.272502 | AG9: 0.201599 | AH9: 0.049617 | AI9: 88.16 | AJ9: 47.1 | AK9: 17.13 | AN9: 0 | AQ9: 100 | AR9: 0.000201 | AS9: 0.000199 | AT9: 0.000195 | AU9: 0.202762 | AV9: 0.106868 | AW9: 0.038151 | AX9: 0.202963 | AY9: 0.107067 | AZ9: 0.038346 | BA9: 0.129515 | BE9: 0.069287 | BF9: 0.029624 | BH9: 0.001081 | BI9: 0.000377 | BK9: 6.7e-05 | BL9: 6.5e-05 | BN9: 0.000289 | BO9: 6.9e-05 | BR9: 0 | BS9: 61.05 | BT9: 60.71 | BU9: 56.42 | BV9: 38.95 | BZ9: 39.29 | CA9: 43.58 | CC9: 0.61 | CD9: 0.55 | CF9: 0.04 | CG9: 0.1 | CI9: 0.16 | CJ9: 0.1 | CM9: 0
A10: 2020_00153 | B10: 21 | C10: 7 | D10: 7 | G10: 3 | I10: 3 | J10: 3 | L10: 2 | M10: 2 | N10: 0.9 | O10: 0.9 | P10: 0.9 | Q10: 0.9 | R10: 0.9 | S10: 0.9 | T10: 0.005 | U10: 0.005 | V10: 0.005 | W10: 5 | X10: 5 | Y10: 5 | Z10: 100 | AA10: 100 | AB10: 100 | AC10: 0.350388 | AD10: 0.21574 | AE10: 0.102154 | AF10: 0.294196 | AG10: 0.173897 | AH10: 0.081748 | AI10: 87.6 | AJ10: 52.15 | AK10: 23.96 | AN10: 1 | AQ10: 99 | AR10: 0.0002 | AS10: 0.000203 | AT10: 0.000194 | AU10: 0.214335 | AV10: 0.131591 | AW10: 0.058571 | AX10: 0.214535 | AY10: 0.131794 | AZ10: 0.058765 | BA10: 0.135853 | BE10: 0.083946 | BF10: 0.043298 | BH10: 0.001235 | BI10: 0.000547 | BK10: 7.2e-05 | BL10: 6.2e-05 | BN10: 0.000317 | BO10: 0.000108 | BR10: 9.2e-05 | BS10: 61.23 | BT10: 61.09 | BU10: 57.53 | BV10: 38.77 | BZ10: 38.91 | CA10: 42.38 | CC10: 0.57 | CD10: 0.54 | CF10: 0.03 | CG10: 0.06 | CI10: 0.15 | CJ10: 0.11 | CM10: 0.09
A11: 2020_00155 | B11: 21 | C11: 7 | D11: 7 | G11: 3 | I11: 3 | J11: 3 | L11: 2 | M11: 2 | N11: 0.9 | O11: 0.9 | P11: 0.9 | Q11: 0.9 | R11: 0.9 | S11: 0.9 | T11: 0.005 | U11: 0.005 | V11: 0.005 | W11: 5 | X11: 5 | Y11: 5 | Z11: 100 | AA11: 100 | AB11: 100 | AC11: 0.343582 | AD11: 0.170737 | AE11: 0.079815 | AF11: 0.305123 | AG11: 0.155874 | AH11: 0.064162 | AI11: 76.69 | AJ11: 36.7 | AK11: 15.98 | AN11: 0 | AQ11: 100 | AR11: 0.000187 | AS11: 0.000197 | AT11: 0.000189 | AU11: 0.211833 | AV11: 0.105462 | AW11: 0.045539 | AX11: 0.21202 | AY11: 0.10566 | AZ11: 0.045728 | BA11: 0.131561 | BE11: 0.065077 | BF11: 0.034087 | BH11: 0.000904 | BI11: 0.0004 | BK11: 7.1e-05 | BL11: 7e-05 | BN11: 0.000229 | BO11: 7.4e-05 | BR11: 0 | BS11: 61.71 | BT11: 61.88 | BU11: 57.29 | BV11: 38.29 | BZ11: 38.12 | CA11: 42.71 | CC11: 0.53 | CD11: 0.5 | CF11: 0.04 | CG11: 0.09 | CI11: 0.13 | CJ11: 0.09 | CM11: 0
A12: 2020_00159 | B12: 21 | C12: 7 | D12: 7 | G12: 3 | I12: 3 | J12: 3 | L12: 2 | M12: 2 | N12: 0.9 | O12: 0.9 | P12: 0.9 | Q12: 0.9 | R12: 0.9 | S12: 0.9 | T12: 0.005 | U12: 0.005 | V12: 0.005 | W12: 5 | X12: 5 | Y12: 5 | Z12: 100 | AA12: 100 | AB12: 100 | AC12: 0.338193 | AD12: 0.194337 | AE12: 0.096999 | AF12: 0.306084 | AG12: 0.19849 | AH12: 0.074093 | AI12: 88.43 | AJ12: 50.44 | AK12: 23.8 | AN12: 0 | AQ12: 100 | AR12: 0.000219 | AS12: 0.000213 | AT12: 0.000204 | AU12: 0.207368 | AV12: 0.118133 | AW12: 0.055509 | AX12: 0.207587 | AY12: 0.118346 | AZ12: 0.055712 | BA12: 0.130606 | BE12: 0.075991 | BF12: 0.041286 | BH12: 0.00119 | BI12: 0.000566 | BK12: 6.8e-05 | BL12: 6.9e-05 | BN12: 0.000312 | BO12: 0.000112 | BR12: 0 | BS12: 61.38 | BT12: 60.9 | BU12: 57.44 | BV12: 38.62 | BZ12: 39.1 | CA12: 42.56 | CC12: 0.61 | CD12: 0.58 | CF12: 0.03 | CG12: 0.07 | CI12: 0.16 | CJ12: 0.12 | CM12: 0
A13: 2020_00175 | B13: 21 | C13: 7 | D13: 7 | G13: 3 | I13: 3 | J13: 3 | L13: 2 | M13: 2 | N13: 0.9 | O13: 0.9 | P13: 0.9 | Q13: 0.9 | R13: 0.9 | S13: 0.9 | T13: 0.005 | U13: 0.005 | V13: 0.005 | W13: 5 | X13: 5 | Y13: 5 | Z13: 100 | AA13: 100 | AB13: 100 | AC13: 0.210122 | AD13: 0.119643 | AE13: 0.059473 | AF13: 0.192566 | AG13: 0.117259 | AH13: 0.050966 | AI13: 60.87 | AJ13: 34.33 | AK13: 15.83 | AN13: 0 | AQ13: 100 | AR13: 0.000228 | AS13: 0.000222 | AT13: 0.000211 | AU13: 0.127571 | AV13: 0.071959 | AW13: 0.032891 | AX13: 0.127799 | AY13: 0.072181 | AZ13: 0.033103 | BA13: 0.082323 | BE13: 0.047462 | BF13: 0.02637 | BH13: 0.000808 | BI13: 0.000364 | BK13: 6.8e-05 | BL13: 6.9e-05 | BN13: 0.00021 | BO13: 7.1e-05 | BR13: 0 | BS13: 60.82 | BT13: 60.33 | BU13: 55.66 | BV13: 39.18 | BZ13: 39.67 | CA13: 44.34 | CC13: 0.68 | CD13: 0.61 | CF13: 0.06 | CG13: 0.12 | CI13: 0.18 | CJ13: 0.12 | CM13: 0
... A101: 2020_00999 | B101: 21 | C101: 7 | D101: 7 | G101: 3 | I101: 3 | J101: 3 | L101: 2 | M101: 2 | N101: 0.9 | O101: 0.9 | P101: 0.9 | Q101: 0.9 | R101: 0.9 | S101: 0.9 | T101: 0.005 | U101: 0.005 | V101: 0.005 | W101: 5 | X101: 5 | Y101: 5 | Z101: 100 | AA101: 100 | AB101: 100 | AC101: 0.197484 | AD101: 0.126422 | AE101: 0.047915 | AF101: 0.221857 | AG101: 0.126893 | AH101: 0.041222 | AI101: 121.54 | AJ101: 76.42 | AK101: 25.16 | AN101: 0 | AQ101: 100 | AR101: 9.7e-05 | AS101: 9.9e-05 | AT101: 0.000106 | AU101: 0.117873 | AV101: 0.075411 | AW101: 0.026929 | AX101: 0.11797 | AY101: 0.07551 | AZ101: 0.027035 | BA101: 0.079513 | BE101: 0.050912 | BF101: 0.02088 | BH101: 0.000764 | BI101: 0.000269 | BK101: 2.9e-05 | BL101: 2.8e-05 | BN101: 0.00017 | BO101: 5.1e-05 | BR101: 0 | BS101: 59.74 | BT101: 59.73 | BU101: 56.42 | BV101: 40.26 | BZ101: 40.27 | CA101: 43.58 | CC101: 0.6 | CD101: 0.56 | CF101: 0.02 | CG101: 0.06 | CI101: 0.13 | CJ101: 0.11 | CM101: 0

Sheet Run_5
A1: puzzle_size | B1: nAnts_alg0 | C1: nAnts_alg3 | D1: nAnts_alg4 | E1: threads_alg0 | F1: threads_alg3 | G1: threads_alg4 | H1: numcolonies_alg0 | I1: numcolonies_alg3 | J1: numcolonies_alg4 | K1: numacs_alg0 | L1: numacs_alg3 | M1: numacs_alg4 | N1: q0_alg0 | O1: q0_alg3 | P1: q0_alg4 | Q1: rho_alg0 | R1: rho_alg3 | S1: rho_alg4 | T1: bve_alg0 | U1: bve_alg3 | V1: bve_alg4 | W1: timeout_alg0 | X1: timeout_alg3 | Y1: timeout_alg4 | Z1: success_rate_alg0 | AA1: success_rate_alg3 | AB1: success_rate_alg4 | AC1: time_mean_alg0 | AD1: time_mean_alg3 | AE1: time_mean_alg4 | AF1: time_std_alg0 | AG1: time_std_alg3 | AH1: time_std_alg4 | AI1: iter_mean_alg0 | AJ1: iter_mean_alg3 | AK1: iter_mean_alg4 | AL1: with_comm_alg0 | AM1: with_comm_alg3 | AN1: with_comm_alg4 | AO1: without_comm_alg0 | AP1: without_comm_alg3 | AQ1: without_comm_alg4 | AR1: cp_initial_mean_alg0 | AS1: cp_initial_mean_alg3 | AT1: cp_initial_mean_alg4 | AU1: cp_ant_mean_alg0 | AV1: cp_ant_mean_alg3 | AW1: cp_ant_mean_alg4 | AX1: cp_total_mean_alg0 | AY1: cp_total_mean_alg3 | AZ1: cp_total_mean_alg4 | BA1: acs_time_mean_alg0 | BB1: acs_time_mean_alg3 | BC1: acs_time_mean_alg4 | BD1: dcm_aco_time_mean_alg0 | BE1: dcm_aco_time_mean_alg3 | BF1: dcm_aco_time_mean_alg4 | BG1: coop_game_mean_alg0 | BH1: coop_game_mean_alg3 | BI1: coop_game_mean_alg4 | BJ1: pheromone_fusion_mean_alg0 | BK1: pheromone_fusion_mean_alg3 | BL1: pheromone_fusion_mean_alg4 | BM1: public_path_mean_alg0 | BN1: public_path_mean_alg3 | BO1: public_path_mean_alg4 | BP1: communication_time_mean_alg0 | BQ1: communication_time_mean_alg3 | BR1: communication_time_mean_alg4 | BS1: cp_percentage_alg0 | BT1: cp_percentage_alg3 | BU1: cp_percentage_alg4 | BV1: acs_time_percentage_alg0 | BW1: acs_time_percentage_alg3 | BX1: acs_time_percentage_alg4 | BY1: dcm_aco_time_percentage_alg0 | BZ1: dcm_aco_time_percentage_alg3 | CA1: dcm_aco_time_percentage_alg4 | CB1: coop_game_percentage_alg0 | CC1: coop_game_percentage_alg3 | CD1: coop_game_percentage_alg4 | CE1: pheromone_fusion_percentage_alg0 | CF1: pheromone_fusion_percentage_alg3 | CG1: pheromone_fusion_percentage_alg4 | CH1: public_path_percentage_alg0 | CI1: public_path_percentage_alg3 | CJ1: public_path_percentage_alg4 | CK1: communication_time_percentage_alg0 | CL1: communication_time_percentage_alg3 | CM1: communication_time_percentage_alg4
A2: 2020_00004 | B2: 21 | C2: 7 | D2: 7 | G2: 3 | I2: 3 | J2: 3 | L2: 2 | M2: 2 | N2: 0.9 | O2: 0.9 | P2: 0.9 | Q2: 0.9 | R2: 0.9 | S2: 0.9 | T2: 0.005 | U2: 0.005 | V2: 0.005 | W2: 5 | X2: 5 | Y2: 5 | Z2: 100 | AA2: 100 | AB2: 100 | AC2: 0.09234 | AD2: 0.039417 | AE2: 0.02339 | AF2: 0.072626 | AG2: 0.029553 | AH2: 0.017353 | AI2: 50 | AJ2: 20.74 | AK2: 10.7 | AN2: 0 | AQ2: 100 | AR2: 8.3e-05 | AS2: 8.3e-05 | AT2: 8.9e-05 | AU2: 0.056324 | AV2: 0.02401 | AW2: 0.01285 | AX2: 0.056407 | AY2: 0.024093 | AZ2: 0.012939 | BA2: 0.035933 | BE2: 0.015324 | BF2: 0.01045 | BH2: 0.000204 | BI2: 0.000107 | BK2: 2.8e-05 | BL2: 2.7e-05 | BN2: 4.5e-05 | BO2: 1.8e-05 | BR2: 0 | BS2: 61.09 | BT2: 61.12 | BU2: 55.32 | BV2: 38.91 | BZ2: 38.88 | CA2: 44.68 | CC2: 0.52 | CD2: 0.46 | CF2: 0.07 | CG2: 0.12 | CI2: 0.11 | CJ2: 0.08 | CM2: 0
A3: 2020_00021 | B3: 21 | C3: 7 | D3: 7 | G3: 3 | I3: 3 | J3: 3 | L3: 2 | M3: 2 | N3: 0.9 | O3: 0.9 | P3: 0.9 | Q3: 0.9 | R3: 0.9 | S3: 0.9 | T3: 0.005 | U3: 0.005 | V3: 0.005 | W3: 5 | X3: 5 | Y3: 5 | Z3: 100 | AA3: 100 | AB3: 100 | AC3: 0.104548 | AD3: 0.057628 | AE3: 0.0255 | AF3: 0.097387 | AG3: 0.052375 | AH3: 0.025748 | AI3: 57.21 | AJ3: 31.49 | AK3: 12.18 | AN3: 0 | AQ3: 100 | AR3: 8.6e-05 | AS3: 8.3e-05 | AT3: 8.7e-05 | AU3: 0.06346 | AV3: 0.034869 | AW3: 0.013895 | AX3: 0.063546 | AY3: 0.034952 | AZ3: 0.013983 | BA3: 0.041002 | BE3: 0.022676 | BF3: 0.011518 | BH3: 0.000313 | BI3: 0.00012 | BK3: 2.8e-05 | BL3: 2.9e-05 | BN3: 6.5e-05 | BO3: 2.1e-05 | BR3: 0 | BS3: 60.78 | BT3: 60.65 | BU3: 54.83 | BV3: 39.22 | BZ3: 39.35 | CA3: 45.17 | CC3: 0.54 | CD3: 0.47 | CF3: 0.05 | CG3: 0.11 | CI3: 0.11 | CJ3: 0.08 | CM3: 0
A4: 2020_00041 | B4: 21 | C4: 7 | D4: 7 | G4: 3 | I4: 3 | J4: 3 | L4: 2 | M4: 2 | N4: 0.9 | O4: 0.9 | P4: 0.9 | Q4: 0.9 | R4: 0.9 | S4: 0.9 | T4: 0.005 | U4: 0.005 | V4: 0.005 | W4: 5 | X4: 5 | Y4: 5 | Z4: 100 | AA4: 100 | AB4: 100 | AC4: 0.160181 | AD4: 0.060318 | AE4: 0.024345 | AF4: 0.14276 | AG4: 0.067696 | AH4: 0.033334 | AI4: 88.76 | AJ4: 32.97 | AK4: 11.47 | AN4: 0 | AQ4: 100 | AR4: 8.8e-05 | AS4: 8.7e-05 | AT4: 9.3e-05 | AU4: 0.097796 | AV4: 0.036718 | AW4: 0.013422 | AX4: 0.097884 | AY4: 0.036805 | AZ4: 0.013515 | BA4: 0.062298 | BE4: 0.023512 | BF4: 0.01083 | BH4: 0.000326 | BI4: 0.000116 | BK4: 2.7e-05 | BL4: 2.6e-05 | BN4: 7.1e-05 | BO4: 2.1e-05 | BR4: 0 | BS4: 61.11 | BT4: 61.02 | BU4: 55.51 | BV4: 38.89 | BZ4: 38.98 | CA4: 44.49 | CC4: 0.54 | CD4: 0.47 | CF4: 0.04 | CG4: 0.11 | CI4: 0.12 | CJ4: 0.09 | CM4: 0
